File: raw-data/Sp15_245L_sec-001_group-01_bendtest-aluminum.raw
"Test Type","Manual"
"Method Name:","C:\INSTRON\user\template\Sp15_245Lsect001_group-3_aluminum_bendtest.mtM"
"Name:","4FtPerMin"
"Operator ID:","Jaques"
"Company:","BSU"
"Lab name:",""
"Test date:","1/26/15"
"Temperature:",""
"Humidity:",""
"Note 1:",""
"Note 2:",""
"Note 3:",""
"Geometry:","Circular"
"Specimen",1
"Specimen name:",""
"Width:",6.350000,"mm"
"Thickness:",1.524000,"mm"
"Length:",12.000000,"mm"
"Diameter:",5.000000,"um"
"Inner diameter:",0.500000,"mm"
"Outer diameter:",1.000000,"mm"
"Wall thickness:",0.500000,"mm"
"Area:",19.634954,"um*um"
"Linear density:",1.000000,"den"
"Sled weight:",9.806650,"N"
"Loading span:",0.000000,"mm"
"Support span:",1.000000,"mm"
"Span ratio:","2"
"Fixture type:","3-point"
"Comment:",""
"Included"
"Time sec","Extension mm","Load N","Stress MPa","Cycle Count ","Total Cycle Count ","Repetitions Count ","Strain [Exten.] %","Tenacity gf/tex"
0,0,-3.631685,-184960.2,0,0,0,0,-3332.96
0.09,0,-3.631546,-184953.1,0,0,0,0,-3332.832
0.142,0,-3.631622,-184957,0,0,0,0,-3332.902
0.152,0,-3.606756,-183690.5,0,0,0,0,-3310.08
0.176,0,-3.633247,-185039.8,0,0,0,0,-3334.393
0.184,-0.000472222,-3.646026,-185690.6,0,0,0,-0.003935183,-3346.121
0.198,-0.000472222,-3.671391,-186982.4,0,0,0,-0.003935183,-3369.4
0.206,-0.000472222,-3.697896,-188332.3,0,0,0,-0.003935183,-3393.724
0.214,-0.000472222,-3.723133,-189617.6,0,0,0,-0.003935183,-3416.885
0.234,-0.000472222,-3.720407,-189478.8,0,0,0,-0.003935183,-3414.383
0.256,-0.000472222,-3.72352,-189637.3,0,0,0,-0.003935183,-3417.24
0.322,-0.0007083331,-3.740126,-190483,0,0,0,-0.005902776,-3432.48
0.334,-0.0007083331,-3.764239,-191711.1,0,0,0,-0.005902776,-3454.61
0.342,-0.0007083331,-3.792499,-193150.4,0,0,0,-0.005902776,-3480.546
0.348,-0.000944444,-3.815785,-194336.3,0,0,0,-0.007870367,-3501.916
0.356,-0.000944444,-3.844814,-195814.8,0,0,0,-0.007870367,-3528.557
0.364,-0.001180555,-3.867653,-196977.9,0,0,0,-0.009837959,-3549.517
0.37,-0.001416666,-3.885723,-197898.2,0,0,0,-0.01180555,-3566.101
0.378,-0.001416666,-3.916833,-199482.7,0,0,0,-0.01180555,-3594.652
0.384,-0.001652777,-3.946489,-200993,0,0,0,-0.01377314,-3621.869
0.388,-0.001652777,-3.96766,-202071.3,0,0,0,-0.01377314,-3641.299
0.392,-0.001888888,-3.988391,-203127.1,0,0,0,-0.01574073,-3660.324
0.396,-0.001888888,-4.010552,-204255.7,0,0,0,-0.01574073,-3680.662
0.4,-0.002124999,-4.035485,-205525.5,0,0,0,-0.01770833,-3703.544
0.404,-0.002124999,-4.061581,-206854.6,0,0,0,-0.01770833,-3727.494
0.408,-0.00236111,-4.087122,-208155.4,0,0,0,-0.01967592,-3750.934
0.412,-0.00236111,-4.111208,-209382.1,0,0,0,-0.01967592,-3773.039
0.416,-0.002597221,-4.134089,-210547.4,0,0,0,-0.02164351,-3794.038
0.42,-0.002597221,-4.157532,-211741.4,0,0,0,-0.02164351,-3815.553
0.424,-0.002833332,-4.182433,-213009.6,0,0,0,-0.0236111,-3838.406
0.428,-0.002833332,-4.207553,-214288.9,0,0,0,-0.0236111,-3861.459
0.432,-0.003069443,-4.232326,-215550.6,0,0,0,-0.02557869,-3884.194
0.436,-0.003069443,-4.257046,-216809.6,0,0,0,-0.02557869,-3906.881
0.44,-0.003305554,-4.281429,-218051.4,0,0,0,-0.02754628,-3929.258
0.444,-0.003305554,-4.305318,-219268,0,0,0,-0.02754628,-3951.182
0.448,-0.003541665,-4.328607,-220454.2,0,0,0,-0.02951388,-3972.556
0.452,-0.003541665,-4.350996,-221594.4,0,0,0,-0.02951388,-3993.103
0.456,-0.003777776,-4.372694,-222699.5,0,0,0,-0.03148147,-4013.016
0.46,-0.003777776,-4.393721,-223770.4,0,0,0,-0.03148147,-4032.313
0.464,-0.004013887,-4.414952,-224851.7,0,0,0,-0.03344906,-4051.799
0.468,-0.004013887,-4.436427,-225945.4,0,0,0,-0.03344906,-4071.507
0.472,-0.004249998,-4.458215,-227055,0,0,0,-0.03541665,-4091.502
0.476,-0.004249998,-4.480048,-228167,0,0,0,-0.03541665,-4111.54
0.48,-0.004486109,-4.501499,-229259.5,0,0,0,-0.03738425,-4131.226
0.484,-0.004486109,-4.522258,-230316.7,0,0,0,-0.03738425,-4150.278
0.492,-0.00472222,-4.560492,-232264,0,0,0,-0.03935184,-4185.367
0.5,-0.00472222,-4.59502,-234022.5,0,0,0,-0.03935184,-4217.055
0.508,-0.004958331,-4.627618,-235682.7,0,0,0,-0.04131943,-4246.972
0.516,-0.004958331,-4.65734,-237196.4,0,0,0,-0.04131943,-4274.249
0.522,-0.005194443,-4.675721,-238132.5,0,0,0,-0.04328702,-4291.118
0.532,-0.005194443,-4.700008,-239369.5,0,0,0,-0.04328702,-4313.407
0.542,-0.005430553,-4.721042,-240440.7,0,0,0,-0.04525461,-4332.71
0.554,-0.005666665,-4.742842,-241551,0,0,0,-0.0472222,-4352.717
0.568,-0.005666665,-4.765819,-242721.2,0,0,0,-0.0472222,-4373.805
0.586,-0.005902775,-4.781946,-243542.5,0,0,0,-0.04918979,-4388.605
0.602,-0.006138886,-4.7999,-244456.9,0,0,0,-0.05115739,-4405.083
0.618,-0.006374997,-4.818519,-245405.2,0,0,0,-0.05312498,-4422.17
0.638,-0.006374997,-4.839838,-246491,0,0,0,-0.05312498,-4441.735
0.65,-0.006611108,-4.856901,-247359.9,0,0,0,-0.05509257,-4457.395
0.666,-0.006611108,-4.880898,-248582.1,0,0,0,-0.05509257,-4479.417
0.688,-0.00684722,-4.89349,-249223.4,0,0,0,-0.05706016,-4490.974
0.708,-0.00708333,-4.906305,-249876,0,0,0,-0.05902775,-4502.734
0.72,-0.007319441,-4.924991,-250827.8,0,0,0,-0.06099534,-4519.884
0.732,-0.007319441,-4.951683,-252187.2,0,0,0,-0.06099534,-4544.38
0.744,-0.007319441,-4.976253,-253438.5,0,0,0,-0.06099534,-4566.929
0.756,-0.007555552,-4.99085,-254181.9,0,0,0,-0.06296293,-4580.326
0.78,-0.007791664,-5.011011,-255208.7,0,0,0,-0.06493053,-4598.828
0.798,-0.008027775,-5.02664,-256004.7,0,0,0,-0.06689812,-4613.171
0.824,-0.008263885,-5.048084,-257096.8,0,0,0,-0.06886571,-4632.852
0.844,-0.008263885,-5.070795,-258253.5,0,0,0,-0.06886571,-4653.694
0.866,-0.008499997,-5.092501,-259359,0,0,0,-0.0708333,-4673.615
0.882,-0.008736108,-5.108196,-260158.3,0,0,0,-0.0728009,-4688.02
0.908,-0.008736108,-5.130171,-261277.5,0,0,0,-0.0728009,-4708.187
0.916,-0.008972219,-5.14366,-261964.4,0,0,0,-0.07476849,-4720.566
0.928,-0.008972219,-5.16558,-263080.8,0,0,0,-0.07476849,-4740.683
0.938,-0.00920833,-5.183882,-264012.9,0,0,0,-0.07673608,-4757.48
0.952,-0.00920833,-5.207155,-265198.3,0,0,0,-0.07673608,-4778.839
0.976,-0.00944444,-5.226667,-266191.9,0,0,0,-0.07870367,-4796.745
0.988,-0.009680551,-5.239078,-266824.1,0,0,0,-0.08067126,-4808.135
0.998,-0.009916663,-5.260441,-267912.1,0,0,0,-0.08263886,-4827.741
1.006,-0.009916663,-5.281832,-269001.5,0,0,0,-0.08263886,-4847.373
1.018,-0.01015277,-5.309223,-270396.5,0,0,0,-0.08460645,-4872.51
1.03,-0.01015277,-5.333242,-271619.8,0,0,0,-0.08460645,-4894.554
1.042,-0.01038889,-5.349638,-272454.8,0,0,0,-0.08657404,-4909.602
1.056,-0.010625,-5.367896,-273384.7,0,0,0,-0.08854163,-4926.357
1.078,-0.01086111,-5.387615,-274389,0,0,0,-0.09050922,-4944.455
1.102,-0.01109722,-5.405007,-275274.8,0,0,0,-0.09247681,-4960.416
1.12,-0.01109722,-5.4,-275019.7,0,0,0,-0.09247681,-4955.82
1.124,-0.01109722,-5.370182,-273501.2,0,0,0,-0.09247681,-4928.456
1.128,-0.01133333,-5.330508,-271480.5,0,0,0,-0.09444441,-4892.044
1.132,-0.01133333,-5.284404,-269132.5,0,0,0,-0.09444441,-4849.733
1.136,-0.01133333,-5.235514,-266642.5,0,0,0,-0.09444441,-4804.864
1.14,-0.01133333,-5.186812,-264162.2,0,0,0,-0.09444441,-4760.168
1.144,-0.01133333,-5.140172,-261786.8,0,0,0,-0.09444441,-4717.365
1.148,-0.01133333,-5.097373,-259607.1,0,0,0,-0.09444441,-4678.087
1.152,-0.01156944,-5.059934,-257700.3,0,0,0,-0.096412,-4643.727
1.156,-0.01156944,-5.028722,-256110.7,0,0,0,-0.096412,-4615.083
1.16,-0.01156944,-5.002766,-254788.8,0,0,0,-0.096412,-4591.262
1.164,-0.01156944,-4.981115,-253686.1,0,0,0,-0.096412,-4571.391
1.172,-0.01180555,-4.952255,-252216.3,0,0,0,-0.09837959,-4544.905
1.196,-0.01204166,-4.947236,-251960.7,0,0,0,-0.1003472,-4540.299
1.218,-0.01204166,-4.968995,-253068.9,0,0,0,-0.1003472,-4560.269
1.228,-0.01227777,-4.984795,-253873.5,0,0,0,-0.1023148,-4574.769
1.268,-0.01274999,-5.002315,-254765.8,0,0,0,-0.10625,-4590.847
1.292,-0.01274999,-5.02395,-255867.7,0,0,0,-0.10625,-4610.703
1.3,-0.01298611,-5.038724,-256620.1,0,0,0,-0.1082175,-4624.262
1.312,-0.01298611,-5.062213,-257816.4,0,0,0,-0.1082175,-4645.818
1.336,-0.01322222,-5.078667,-258654.4,0,0,0,-0.1101851,-4660.919
1.348,-0.01345833,-5.090712,-259267.8,0,0,0,-0.1121527,-4671.974
1.362,-0.01369444,-5.109201,-260209.5,0,0,0,-0.1141203,-4688.941
1.386,-0.01393055,-5.132058,-261373.6,0,0,0,-0.1160879,-4709.918
1.41,-0.01416666,-5.152656,-262422.6,0,0,0,-0.1180555,-4728.822
1.432,-0.01416666,-5.174572,-263538.8,0,0,0,-0.1180555,-4748.936
1.442,-0.01440277,-5.189118,-264279.6,0,0,0,-0.1200231,-4762.285
1.486,-0.01463888,-5.20631,-265155.2,0,0,0,-0.1219907,-4778.063
1.516,-0.0151111,-5.197356,-264699.2,0,0,0,-0.1259259,-4769.845
1.544,-0.01534721,-5.177989,-263712.8,0,0,0,-0.1278935,-4752.071
1.568,-0.01534721,-5.156494,-262618.1,0,0,0,-0.1278935,-4732.345
1.596,-0.01581944,-5.166323,-263118.7,0,0,0,-0.1318286,-4741.365
1.642,-0.01605555,-5.169511,-263281,0,0,0,-0.1337962,-4744.291
1.668,-0.01629166,-5.187182,-264181,0,0,0,-0.1357638,-4760.508
1.694,-0.01652777,-5.199511,-264808.9,0,0,0,-0.1377314,-4771.823
1.71,-0.01676388,-5.213482,-265520.5,0,0,0,-0.139699,-4784.645
1.748,-0.0172361,-5.219444,-265824.1,0,0,0,-0.1436342,-4790.116
1.76,-0.0172361,-5.246222,-267187.9,0,0,0,-0.1436342,-4814.692
1.794,-0.01770833,-5.247708,-267263.6,0,0,0,-0.1475694,-4816.056
1.816,-0.01794444,-5.264719,-268130,0,0,0,-0.149537,-4831.668
1.85,-0.01818055,-5.283974,-269110.6,0,0,0,-0.1515046,-4849.339
1.864,-0.01841666,-5.304057,-270133.4,0,0,0,-0.1534722,-4867.77
1.886,-0.01865277,-5.321475,-271020.5,0,0,0,-0.1554397,-4883.755
1.928,-0.01888888,-5.337377,-271830.4,0,0,0,-0.1574073,-4898.349
1.952,-0.0193611,-5.339528,-271940,0,0,0,-0.1613425,-4900.323
1.964,-0.0193611,-5.314954,-270688.4,0,0,0,-0.1613425,-4877.771
1.972,-0.0193611,-5.281411,-268980,0,0,0,-0.1613425,-4846.986
1.976,-0.01959721,-5.260947,-267937.8,0,0,0,-0.1633101,-4828.206
1.98,-0.01959721,-5.238742,-266806.9,0,0,0,-0.1633101,-4807.827
1.984,-0.01959721,-5.214073,-265550.6,0,0,0,-0.1633101,-4785.187
1.988,-0.01959721,-5.188008,-264223.1,0,0,0,-0.1633101,-4761.266
1.992,-0.01959721,-5.161235,-262859.5,0,0,0,-0.1633101,-4736.695
1.996,-0.01959721,-5.135392,-261543.4,0,0,0,-0.1633101,-4712.979
2,-0.01983333,-5.112137,-260359,0,0,0,-0.1652777,-4691.636
2.006,-0.01983333,-5.083813,-258916.5,0,0,0,-0.1652777,-4665.642
2.018,-0.01983333,-5.060899,-257749.5,0,0,0,-0.1652777,-4644.613
2.046,-0.02030555,-5.062182,-257814.8,0,0,0,-0.1692129,-4645.791
2.066,-0.02030555,-5.082527,-258851,0,0,0,-0.1692129,-4664.462
2.094,-0.02077777,-5.093341,-259401.8,0,0,0,-0.1731481,-4674.386
2.116,-0.02101388,-5.118874,-260702.1,0,0,0,-0.1751157,-4697.819
2.128,-0.02101388,-5.140755,-261816.5,0,0,0,-0.1751157,-4717.9
2.14,-0.02124999,-5.160645,-262829.5,0,0,0,-0.1770833,-4736.154
2.164,-0.0214861,-5.171807,-263398,0,0,0,-0.1790509,-4746.398
2.186,-0.02172221,-5.185163,-264078.2,0,0,0,-0.1810184,-4758.655
2.204,-0.02172221,-5.20709,-265194.9,0,0,0,-0.1810184,-4778.779
2.212,-0.02195833,-5.220157,-265860.4,0,0,0,-0.1829861,-4790.771
2.234,-0.02219444,-5.232159,-266471.7,0,0,0,-0.1849536,-4801.785
2.256,-0.02243054,-5.249603,-267360.1,0,0,0,-0.1869212,-4817.794
2.294,-0.02266666,-5.265198,-268154.3,0,0,0,-0.1888888,-4832.107
2.31,-0.02290277,-5.288661,-269349.3,0,0,0,-0.1908564,-4853.64
2.324,-0.02313888,-5.309671,-270419.3,0,0,0,-0.192824,-4872.922
2.348,-0.02337499,-5.327854,-271345.4,0,0,0,-0.1947916,-4889.609
2.358,-0.02337499,-5.303019,-270080.5,0,0,0,-0.1947916,-4866.817
2.366,-0.02337499,-5.267078,-268250.1,0,0,0,-0.1947916,-4833.833
2.37,-0.02337499,-5.245453,-267148.8,0,0,0,-0.1947916,-4813.986
2.374,-0.0236111,-5.223481,-266029.7,0,0,0,-0.1967592,-4793.821
2.378,-0.0236111,-5.202129,-264942.3,0,0,0,-0.1967592,-4774.226
2.382,-0.0236111,-5.181228,-263877.8,0,0,0,-0.1967592,-4755.044
2.388,-0.0236111,-5.152465,-262412.9,0,0,0,-0.1967592,-4728.647
2.396,-0.0236111,-5.120042,-260761.6,0,0,0,-0.1967592,-4698.891
2.402,-0.02384721,-5.101692,-259827.1,0,0,0,-0.1987268,-4682.051
2.412,-0.02384721,-5.080682,-258757,0,0,0,-0.1987268,-4662.768
2.446,-0.02431944,-5.064986,-257957.6,0,0,0,-0.202662,-4648.363
2.47,-0.02455555,-5.045441,-256962.2,0,0,0,-0.2046295,-4630.427
2.494,-0.02455555,-5.067866,-258104.3,0,0,0,-0.2046295,-4651.007
2.502,-0.02479165,-5.082636,-258856.5,0,0,0,-0.2065971,-4664.562
2.514,-0.02479165,-5.106676,-260080.9,0,0,0,-0.2065971,-4686.624
2.544,-0.02526388,-5.105488,-260020.4,0,0,0,-0.2105323,-4685.535
2.56,-0.02526388,-5.127615,-261147.3,0,0,0,-0.2105323,-4705.841
2.592,-0.0257361,-5.143018,-261931.8,0,0,0,-0.2144675,-4719.978
2.604,-0.0257361,-5.168368,-263222.8,0,0,0,-0.2144675,-4743.242
2.614,-0.02597221,-5.186377,-264140,0,0,0,-0.2164351,-4759.769
2.638,-0.02620832,-5.199812,-264824.3,0,0,0,-0.2184027,-4772.1
2.662,-0.02644443,-5.218728,-265787.7,0,0,0,-0.2203703,-4789.46
2.686,-0.02668055,-5.206368,-265158.2,0,0,0,-0.2223379,-4778.116
2.694,-0.02668055,-5.229424,-266332.4,0,0,0,-0.2223379,-4799.276
2.702,-0.02668055,-5.253421,-267554.5,0,0,0,-0.2223379,-4821.298
2.714,-0.02691665,-5.281111,-268964.8,0,0,0,-0.2243055,-4846.711
2.73,-0.02715277,-5.303008,-270080,0,0,0,-0.2262731,-4866.807
2.754,-0.02738888,-5.312243,-270550.3,0,0,0,-0.2282407,-4875.282
2.784,-0.02762499,-5.329822,-271445.6,0,0,0,-0.2302082,-4891.415
2.796,-0.02762499,-5.351235,-272536.2,0,0,0,-0.2302082,-4911.067
2.81,-0.0278611,-5.366771,-273327.4,0,0,0,-0.2321758,-4925.325
2.836,-0.02809721,-5.363084,-273139.7,0,0,0,-0.2341434,-4921.942
2.87,-0.02856943,-5.363639,-273167.9,0,0,0,-0.2380786,-4922.45
2.894,-0.02880554,-5.379055,-273953,0,0,0,-0.2400462,-4936.598
2.91,-0.02880554,-5.401274,-275084.6,0,0,0,-0.2400462,-4956.99
2.924,-0.02904166,-5.388711,-274444.8,0,0,0,-0.2420138,-4945.46
2.932,-0.02904166,-5.365859,-273281,0,0,0,-0.2420138,-4924.488
2.94,-0.02904166,-5.340276,-271978,0,0,0,-0.2420138,-4901.01
2.966,-0.02927776,-5.341966,-272064.1,0,0,0,-0.2439814,-4902.561
2.978,-0.02951388,-5.355137,-272734.9,0,0,0,-0.245949,-4914.648
2.998,-0.02974999,-5.376244,-273809.9,0,0,0,-0.2479166,-4934.019
3.014,-0.02974999,-5.397778,-274906.6,0,0,0,-0.2479166,-4953.781
3.038,-0.03022221,-5.401162,-275078.9,0,0,0,-0.2518517,-4956.888
3.072,-0.03045832,-5.418253,-275949.4,0,0,0,-0.2538193,-4972.572
3.086,-0.03069443,-5.436833,-276895.7,0,0,0,-0.2557869,-4989.625
3.11,-0.03093054,-5.450006,-277566.5,0,0,0,-0.2577545,-5001.713
3.132,-0.03116666,-5.471855,-278679.3,0,0,0,-0.2597221,-5021.765
3.166,-0.03140276,-5.487971,-279500.1,0,0,0,-0.2616897,-5036.556
3.178,-0.03140276,-5.514768,-280864.8,0,0,0,-0.2616897,-5061.148
3.186,-0.03163887,-5.530872,-281685,0,0,0,-0.2636573,-5075.928
3.226,-0.03187499,-5.545734,-282441.9,0,0,0,-0.2656249,-5089.568
3.254,-0.03234721,-5.545215,-282415.5,0,0,0,-0.2695601,-5089.091
3.276,-0.03258332,-5.567848,-283568.2,0,0,0,-0.2715277,-5109.862
3.29,-0.03258332,-5.590765,-284735.3,0,0,0,-0.2715277,-5130.894
3.312,-0.03281943,-5.611976,-285815.6,0,0,0,-0.2734953,-5150.36
3.348,-0.03305554,-5.631243,-286796.9,0,0,0,-0.2754628,-5168.043
3.374,-0.03352777,-5.641414,-287314.9,0,0,0,-0.2793981,-5177.377
3.408,-0.03376387,-5.662039,-288365.3,0,0,0,-0.2813656,-5196.306
3.43,-0.03399999,-5.64904,-287703.2,0,0,0,-0.2833332,-5184.375
3.442,-0.03399999,-5.626642,-286562.5,0,0,0,-0.2833332,-5163.82
3.45,-0.0342361,-5.610687,-285750,0,0,0,-0.2853008,-5149.178
3.464,-0.0342361,-5.585481,-284466.3,0,0,0,-0.2853008,-5126.045
3.49,-0.03470832,-5.588874,-284639,0,0,0,-0.289236,-5129.159
3.524,-0.03494443,-5.577943,-284082.3,0,0,0,-0.2912036,-5119.127
3.56,-0.03541665,-5.566324,-283490.6,0,0,0,-0.2951388,-5108.464
3.584,-0.03565276,-5.57921,-284146.8,0,0,0,-0.2971064,-5120.29
3.626,-0.03588887,-5.576953,-284031.9,0,0,0,-0.299074,-5118.218
3.634,-0.03612498,-5.559761,-283156.3,0,0,0,-0.3010415,-5102.44
3.65,-0.0363611,-5.540349,-282167.7,0,0,0,-0.3030091,-5084.625
3.7,-0.03683332,-5.529161,-281597.8,0,0,0,-0.3069443,-5074.357
3.724,-0.03706943,-5.513344,-280792.3,0,0,0,-0.3089119,-5059.842
3.748,-0.03730554,-5.495007,-279858.4,0,0,0,-0.3108795,-5043.013
3.774,-0.03754165,-5.471082,-278639.9,0,0,0,-0.3128471,-5021.056
3.788,-0.03754165,-5.448782,-277504.2,0,0,0,-0.3128471,-5000.59
3.82,-0.03801387,-5.448034,-277466.1,0,0,0,-0.3167823,-4999.904
3.842,-0.03824999,-5.470493,-278609.9,0,0,0,-0.3187499,-5020.516
3.88,-0.0384861,-5.490113,-279609.2,0,0,0,-0.3207175,-5038.521
3.904,-0.03872221,-5.511624,-280704.7,0,0,0,-0.322685,-5058.263
3.928,-0.03895832,-5.526748,-281475,0,0,0,-0.3246527,-5072.143
3.948,-0.03919443,-5.54408,-282357.7,0,0,0,-0.3266203,-5088.05
3.982,-0.03966665,-5.543108,-282308.2,0,0,0,-0.3305554,-5087.157
4.024,-0.03990276,-5.522083,-281237.4,0,0,0,-0.332523,-5067.862
4.03,-0.04013887,-5.503174,-280274.4,0,0,0,-0.3344906,-5050.508
4.036,-0.04013887,-5.474766,-278827.6,0,0,0,-0.3344906,-5024.437
4.04,-0.04013887,-5.453543,-277746.7,0,0,0,-0.3344906,-5004.96
4.044,-0.04013887,-5.432487,-276674.3,0,0,0,-0.3344906,-4985.636
4.052,-0.04037498,-5.396915,-274862.6,0,0,0,-0.3364582,-4952.989
4.06,-0.04037498,-5.373018,-273645.6,0,0,0,-0.3364582,-4931.059
4.072,-0.04037498,-5.350105,-272478.6,0,0,0,-0.3364582,-4910.029
4.084,-0.04061109,-5.322419,-271068.6,0,0,0,-0.3384258,-4884.622
4.108,-0.0408472,-5.333018,-271608.4,0,0,0,-0.3403934,-4894.349
4.124,-0.04108332,-5.350878,-272518,0,0,0,-0.342361,-4910.74
4.158,-0.04131943,-5.362276,-273098.5,0,0,0,-0.3443286,-4921.199
4.174,-0.04155554,-5.375359,-273764.8,0,0,0,-0.3462962,-4933.207
4.192,-0.04155554,-5.398431,-274939.8,0,0,0,-0.3462962,-4954.381
4.224,-0.04202776,-5.414971,-275782.2,0,0,0,-0.3502313,-4969.561
4.254,-0.04226387,-5.425349,-276310.8,0,0,0,-0.3521989,-4979.085
4.264,-0.04226387,-5.451004,-277617.4,0,0,0,-0.3521989,-5002.629
4.27,-0.04249998,-5.469074,-278537.7,0,0,0,-0.3541665,-5019.213
4.28,-0.04249998,-5.493721,-279792.9,0,0,0,-0.3541665,-5041.833
4.29,-0.04273609,-5.506918,-280465,0,0,0,-0.3561341,-5053.944
4.324,-0.04297221,-5.519649,-281113.4,0,0,0,-0.3581017,-5065.628
4.336,-0.04320832,-5.534604,-281875.1,0,0,0,-0.3600693,-5079.353
4.36,-0.04344442,-5.552859,-282804.8,0,0,0,-0.3620369,-5096.106
4.382,-0.04344442,-5.573398,-283850.8,0,0,0,-0.3620369,-5114.956
4.408,-0.04391665,-5.582847,-284332.1,0,0,0,-0.3659721,-5123.628
4.454,-0.04438887,-5.587502,-284569.2,0,0,0,-0.3699073,-5127.9
4.478,-0.04462499,-5.564584,-283401.9,0,0,0,-0.3718749,-5106.867
4.494,-0.04462499,-5.541814,-282242.3,0,0,0,-0.3718749,-5085.97
4.53,-0.0450972,-5.524059,-281338,0,0,0,-0.37581,-5069.676
4.554,-0.04533332,-5.536973,-281995.7,0,0,0,-0.3777776,-5081.527
4.576,-0.04533332,-5.558878,-283111.3,0,0,0,-0.3777776,-5101.63
4.588,-0.04556942,-5.573363,-283849,0,0,0,-0.3797452,-5114.923
4.602,-0.04580554,-5.592782,-284838,0,0,0,-0.3817128,-5132.745
4.618,-0.04580554,-5.617524,-286098.2,0,0,0,-0.3817128,-5155.452
4.646,-0.04627776,-5.633799,-286927,0,0,0,-0.385648,-5170.389
4.692,-0.04674998,-5.652167,-287862.5,0,0,0,-0.3895831,-5187.246
4.712,-0.04674998,-5.674102,-288979.7,0,0,0,-0.3895831,-5207.377
4.722,-0.04698609,-5.694168,-290001.6,0,0,0,-0.3915508,-5225.792
4.736,-0.04698609,-5.716895,-291159.1,0,0,0,-0.3915508,-5246.649
4.758,-0.0472222,-5.729486,-291800.3,0,0,0,-0.3935184,-5258.205
4.774,-0.04745831,-5.742723,-292474.5,0,0,0,-0.3954859,-5270.353
4.786,-0.04769443,-5.759447,-293326.3,0,0,0,-0.3974535,-5285.702
4.798,-0.04793053,-5.774382,-294086.9,0,0,0,-0.3994211,-5299.408
4.816,-0.04816664,-5.795401,-295157.3,0,0,0,-0.4013887,-5318.698
4.834,-0.04840276,-5.817225,-296268.8,0,0,0,-0.4033563,-5338.727
4.85,-0.04863887,-5.835287,-297188.7,0,0,0,-0.4053239,-5355.303
4.884,-0.04911109,-5.826809,-296757,0,0,0,-0.4092591,-5347.523
4.902,-0.04911109,-5.805319,-295662.5,0,0,0,-0.4092591,-5327.8
4.93,-0.04958331,-5.796764,-295226.8,0,0,0,-0.4131942,-5319.948
4.956,-0.04981942,-5.775199,-294128.5,0,0,0,-0.4151618,-5300.158
4.984,-0.05005554,-5.771006,-293914.9,0,0,0,-0.4171295,-5296.31
5.002,-0.05005554,-5.791695,-294968.6,0,0,0,-0.4171295,-5315.297
5.042,-0.05052776,-5.804912,-295641.7,0,0,0,-0.4210646,-5327.426
5.082,-0.05076387,-5.817505,-296283.1,0,0,0,-0.4230323,-5338.984
5.104,-0.05099998,-5.839593,-297408,0,0,0,-0.4249998,-5359.255
5.116,-0.05099998,-5.865054,-298704.8,0,0,0,-0.4249998,-5382.622
5.146,-0.0514722,-5.864462,-298674.6,0,0,0,-0.428935,-5382.079
5.168,-0.05170831,-5.88511,-299726.2,0,0,0,-0.4309026,-5401.028
5.192,-0.05194442,-5.900589,-300514.6,0,0,0,-0.4328702,-5415.234
5.21,-0.05194442,-5.921863,-301598,0,0,0,-0.4328702,-5434.758
5.238,-0.05241664,-5.930304,-302027.9,0,0,0,-0.4368054,-5442.504
5.258,-0.05241664,-5.952529,-303159.8,0,0,0,-0.4368054,-5462.901
5.266,-0.05265275,-5.968692,-303983,0,0,0,-0.4387729,-5477.735
5.278,-0.05265275,-5.992057,-305172.9,0,0,0,-0.4387729,-5499.178
5.308,-0.05312498,-6.003249,-305742.9,0,0,0,-0.4427081,-5509.449
5.326,-0.05312498,-5.979537,-304535.3,0,0,0,-0.4427081,-5487.688
5.334,-0.05336109,-5.964339,-303761.3,0,0,0,-0.4446757,-5473.74
5.35,-0.0535972,-5.951001,-303082,0,0,0,-0.4466433,-5461.499
5.38,-0.05383331,-5.939414,-302491.9,0,0,0,-0.4486109,-5450.865
5.39,-0.05383331,-5.912712,-301132,0,0,0,-0.4486109,-5426.36
5.396,-0.05406942,-5.89533,-300246.7,0,0,0,-0.4505785,-5410.407
5.41,-0.05406942,-5.87241,-299079.4,0,0,0,-0.4505785,-5389.373
5.424,-0.05430553,-5.857217,-298305.6,0,0,0,-0.4525461,-5375.429
5.434,-0.05430553,-5.829148,-296876.1,0,0,0,-0.4525461,-5349.669
5.44,-0.05454164,-5.809655,-295883.3,0,0,0,-0.4545137,-5331.78
5.45,-0.05454164,-5.785327,-294644.3,0,0,0,-0.4545137,-5309.453
5.468,-0.05477776,-5.762411,-293477.2,0,0,0,-0.4564813,-5288.422
5.48,-0.05477776,-5.738104,-292239.2,0,0,0,-0.4564813,-5266.114
5.492,-0.05477776,-5.715515,-291088.8,0,0,0,-0.4564813,-5245.383
5.502,-0.05501387,-5.697845,-290188.8,0,0,0,-0.4584489,-5229.166
5.516,-0.05501387,-5.671634,-288854,0,0,0,-0.4584489,-5205.112
5.522,-0.05524998,-5.65465,-287989,0,0,0,-0.4604165,-5189.524
5.534,-0.05524998,-5.633001,-286886.4,0,0,0,-0.4604165,-5169.656
5.556,-0.05548609,-5.650338,-287769.4,0,0,0,-0.4623841,-5185.567
5.566,-0.05548609,-5.67521,-289036.1,0,0,0,-0.4623841,-5208.394
5.576,-0.0557222,-5.695795,-290084.4,0,0,0,-0.4643517,-5227.285
5.594,-0.0557222,-5.719265,-291279.8,0,0,0,-0.4643517,-5248.825
5.624,-0.05595831,-5.712526,-290936.6,0,0,0,-0.4663192,-5242.64
5.642,-0.05619442,-5.723292,-291484.9,0,0,0,-0.4682868,-5252.521
5.652,-0.05643053,-5.747329,-292709,0,0,0,-0.4702544,-5274.58
5.664,-0.05643053,-5.773759,-294055.2,0,0,0,-0.4702544,-5298.836
5.676,-0.05666664,-5.787274,-294743.5,0,0,0,-0.472222,-5311.24
5.7,-0.05690275,-5.807194,-295758,0,0,0,-0.4741896,-5329.521
5.736,-0.05713886,-5.809171,-295858.6,0,0,0,-0.4761572,-5331.335
5.75,-0.05737497,-5.831412,-296991.3,0,0,0,-0.4781248,-5351.747
5.762,-0.05737497,-5.855008,-298193.1,0,0,0,-0.4781248,-5373.402
5.774,-0.05737497,-5.87767,-299347.3,0,0,0,-0.4781248,-5394.2
5.796,-0.05761109,-5.869341,-298923.1,0,0,0,-0.4800924,-5386.556
5.816,-0.0578472,-5.871249,-299020.3,0,0,0,-0.48206,-5388.307
5.826,-0.05808331,-5.897302,-300347.1,0,0,0,-0.4840276,-5412.217
5.84,-0.05808331,-5.921676,-301588.5,0,0,0,-0.4840276,-5434.586
5.858,-0.05831942,-5.938948,-302468.1,0,0,0,-0.4859952,-5450.437
5.87,-0.05831942,-5.964803,-303784.9,0,0,0,-0.4859952,-5474.166
5.888,-0.05855553,-5.957757,-303426.1,0,0,0,-0.4879628,-5467.699
5.896,-0.05879164,-5.935094,-302271.8,0,0,0,-0.4899304,-5446.9
5.916,-0.05879164,-5.93455,-302244.2,0,0,0,-0.4899304,-5446.401
5.924,-0.05902775,-5.95318,-303193,0,0,0,-0.4918979,-5463.499
5.932,-0.05902775,-5.97593,-304351.6,0,0,0,-0.4918979,-5484.377
5.942,-0.05926386,-6.001022,-305629.5,0,0,0,-0.4938655,-5507.405
5.954,-0.05926386,-6.024262,-306813.2,0,0,0,-0.4938655,-5528.734
5.974,-0.05949998,-6.047345,-307988.8,0,0,0,-0.4958331,-5549.918
6.004,-0.05973608,-6.040446,-307637.4,0,0,0,-0.4978007,-5543.586
6.032,-0.06020831,-6.038152,-307520.6,0,0,0,-0.5017359,-5541.481
6.048,-0.06020831,-6.015535,-306368.7,0,0,0,-0.5017359,-5520.725
6.064,-0.06044442,-5.996423,-305395.3,0,0,0,-0.5037035,-5503.185
6.078,-0.06044442,-5.972697,-304187,0,0,0,-0.5037035,-5481.411
6.09,-0.06068053,-5.954176,-303243.7,0,0,0,-0.5056711,-5464.413
6.116,-0.06091664,-5.962537,-303669.5,0,0,0,-0.5076387,-5472.086
6.128,-0.06115275,-5.978163,-304465.4,0,0,0,-0.5096063,-5486.427
6.162,-0.06138886,-5.96178,-303630.9,0,0,0,-0.5115739,-5471.391
6.2,-0.06186108,-5.975478,-304328.6,0,0,0,-0.515509,-5483.963
6.224,-0.0620972,-5.997658,-305458.2,0,0,0,-0.5174766,-5504.318
6.27,-0.06256942,-5.999623,-305558.3,0,0,0,-0.5214118,-5506.122
6.284,-0.06256942,-6.025147,-306858.2,0,0,0,-0.5214118,-5529.546
6.314,-0.06280552,-6.043002,-307767.6,0,0,0,-0.5233794,-5545.933
6.322,-0.06304164,-6.058704,-308567.3,0,0,0,-0.525347,-5560.342
6.34,-0.06304164,-6.057206,-308491,0,0,0,-0.525347,-5558.968
6.346,-0.06327775,-6.036832,-307453.3,0,0,0,-0.5273145,-5540.271
6.354,-0.06327775,-6.008294,-305999.9,0,0,0,-0.5273145,-5514.08
6.366,-0.06351386,-5.990288,-305082.9,0,0,0,-0.5292822,-5497.555
6.386,-0.06351386,-6.014136,-306297.4,0,0,0,-0.5292822,-5519.441
6.398,-0.06374998,-6.028204,-307013.9,0,0,0,-0.5312498,-5532.352
6.412,-0.06398609,-6.047938,-308018.9,0,0,0,-0.5332174,-5550.462
6.436,-0.0642222,-6.068646,-309073.6,0,0,0,-0.535185,-5569.467
6.45,-0.0642222,-6.042144,-307723.9,0,0,0,-0.535185,-5545.145
6.458,-0.0642222,-6.011234,-306149.7,0,0,0,-0.535185,-5516.778
6.466,-0.0644583,-5.984477,-304786.9,0,0,0,-0.5371525,-5492.222
6.476,-0.0644583,-5.961637,-303623.7,0,0,0,-0.5371525,-5471.26
6.484,-0.06469441,-5.94611,-302832.9,0,0,0,-0.5391201,-5457.01
6.498,-0.06469441,-5.923633,-301688.1,0,0,0,-0.5391201,-5436.382
6.516,-0.06493053,-5.936459,-302341.4,0,0,0,-0.5410877,-5448.153
6.526,-0.06493053,-5.960426,-303562,0,0,0,-0.5410877,-5470.149
6.532,-0.06516664,-5.975668,-304338.3,0,0,0,-0.5430554,-5484.137
6.548,-0.06516664,-5.997341,-305442.1,0,0,0,-0.5430554,-5504.027
6.58,-0.06563886,-5.991899,-305164.9,0,0,0,-0.5469905,-5499.033
6.614,-0.06587497,-5.999409,-305547.4,0,0,0,-0.5489581,-5505.925
6.626,-0.06587497,-6.02551,-306876.7,0,0,0,-0.5489581,-5529.879
6.654,-0.06634719,-6.035617,-307391.5,0,0,0,-0.5528933,-5539.155
6.702,-0.06681942,-6.019826,-306587.2,0,0,0,-0.5568284,-5524.663
6.712,-0.06681942,-6.041934,-307713.2,0,0,0,-0.5568284,-5544.952
6.724,-0.06705553,-6.071336,-309210.6,0,0,0,-0.5587961,-5571.936
6.75,-0.06729164,-6.092952,-310311.5,0,0,0,-0.5607637,-5591.773
6.778,-0.06752774,-6.064661,-308870.7,0,0,0,-0.5627312,-5565.81
6.786,-0.06752774,-6.039588,-307593.7,0,0,0,-0.5627312,-5542.799
6.794,-0.06776386,-6.018336,-306511.4,0,0,0,-0.5646988,-5523.296
6.818,-0.06799997,-6.007264,-305947.4,0,0,0,-0.5666664,-5513.134
6.862,-0.06823608,-5.986083,-304868.7,0,0,0,-0.568634,-5493.696
6.868,-0.0684722,-5.968867,-303991.9,0,0,0,-0.5706016,-5477.896
6.876,-0.0684722,-5.941916,-302619.3,0,0,0,-0.5706016,-5453.161
6.886,-0.0684722,-5.917571,-301379.4,0,0,0,-0.5706016,-5430.818
6.914,-0.06894442,-5.926973,-301858.3,0,0,0,-0.5745368,-5439.448
6.936,-0.06918052,-5.949023,-302981.3,0,0,0,-0.5765043,-5459.684
6.954,-0.06918052,-5.97117,-304109.2,0,0,0,-0.5765043,-5480.009
6.976,-0.06941664,-5.96183,-303633.5,0,0,0,-0.578472,-5471.438
7.004,-0.06988886,-5.963088,-303697.6,0,0,0,-0.5824072,-5472.592
7.018,-0.06988886,-5.990291,-305083,0,0,0,-0.5824072,-5497.557
7.026,-0.06988886,-6.013124,-306245.9,0,0,0,-0.5824072,-5518.512
7.032,-0.07012497,-6.029953,-307103,0,0,0,-0.5843747,-5533.957
7.042,-0.07012497,-6.054649,-308360.7,0,0,0,-0.5843747,-5556.621
7.074,-0.0705972,-6.063257,-308799.2,0,0,0,-0.58831,-5564.521
7.112,-0.0708333,-6.06821,-309051.4,0,0,0,-0.5902776,-5569.067
7.12,-0.07106941,-6.087799,-310049.1,0,0,0,-0.5922451,-5587.045
7.134,-0.07106941,-6.112589,-311311.6,0,0,0,-0.5922451,-5609.795
7.17,-0.07154164,-6.111768,-311269.8,0,0,0,-0.5961803,-5609.042
7.216,-0.07177775,-6.11555,-311462.4,0,0,0,-0.5981479,-5612.513
7.224,-0.07201386,-6.131776,-312288.8,0,0,0,-0.6001155,-5627.404
7.242,-0.07224997,-6.148802,-313155.9,0,0,0,-0.6020831,-5643.029
7.284,-0.07248608,-6.132224,-312311.6,0,0,0,-0.6040506,-5627.815
7.302,-0.07272219,-6.11753,-311563.3,0,0,0,-0.6060182,-5614.33
7.326,-0.0729583,-6.123706,-311877.8,0,0,0,-0.6079859,-5619.998
7.346,-0.07319441,-6.146055,-313016,0,0,0,-0.6099535,-5640.509
7.38,-0.07366664,-6.145614,-312993.5,0,0,0,-0.6138886,-5640.104
7.426,-0.07413886,-6.149254,-313179,0,0,0,-0.6178238,-5643.445
7.476,-0.07461108,-6.142652,-312842.7,0,0,0,-0.621759,-5637.386
7.5,-0.07484719,-6.130002,-312198.4,0,0,0,-0.6237266,-5625.776
7.522,-0.0750833,-6.110157,-311187.8,0,0,0,-0.6256942,-5607.563
7.548,-0.07531942,-6.09903,-310621.1,0,0,0,-0.6276618,-5597.352
7.594,-0.07579163,-6.091119,-310218.2,0,0,0,-0.6315969,-5590.092
7.64,-0.07626386,-6.10857,-311106.9,0,0,0,-0.6355321,-5606.107
7.664,-0.07649997,-6.122799,-311831.6,0,0,0,-0.6374997,-5619.166
7.688,-0.07673609,-6.139757,-312695.3,0,0,0,-0.6394674,-5634.729
7.726,-0.07697219,-6.15715,-313581.1,0,0,0,-0.6414349,-5650.691
7.758,-0.07744441,-6.169813,-314226,0,0,0,-0.6453701,-5662.313
7.806,-0.07791664,-6.16998,-314234.5,0,0,0,-0.6493053,-5662.466
7.822,-0.07791664,-6.19586,-315552.5,0,0,0,-0.6493053,-5686.217
7.83,-0.07815275,-6.209949,-316270.1,0,0,0,-0.651273,-5699.147
7.862,-0.07838886,-6.19276,-315394.7,0,0,0,-0.6532405,-5683.372
7.898,-0.07886108,-6.191828,-315347.2,0,0,0,-0.6571757,-5682.517
7.914,-0.07886108,-6.21989,-316776.4,0,0,0,-0.6571757,-5708.27
7.922,-0.07909719,-6.232262,-317406.5,0,0,0,-0.6591433,-5719.625
7.944,-0.0793333,-6.242668,-317936.5,0,0,0,-0.6611109,-5729.175
7.968,-0.07956942,-6.218146,-316687.6,0,0,0,-0.6630785,-5706.669
7.98,-0.07956942,-6.192659,-315389.5,0,0,0,-0.6630785,-5683.279
8.004,-0.07980552,-6.196619,-315591.3,0,0,0,-0.665046,-5686.914
8.04,-0.08027774,-6.210017,-316273.6,0,0,0,-0.6689812,-5699.209
8.086,-0.08074997,-6.215036,-316529.2,0,0,0,-0.6729164,-5703.815
8.11,-0.08098608,-6.233517,-317470.4,0,0,0,-0.674884,-5720.776
8.128,-0.08098608,-6.256873,-318659.9,0,0,0,-0.674884,-5742.211
8.154,-0.0814583,-6.260489,-318844.1,0,0,0,-0.6788192,-5745.53
8.176,-0.08169441,-6.281015,-319889.5,0,0,0,-0.6807867,-5764.368
8.2,-0.08193052,-6.297767,-320742.7,0,0,0,-0.6827543,-5779.742
8.218,-0.08193052,-6.322668,-322010.8,0,0,0,-0.6827543,-5802.594
8.226,-0.08216663,-6.337182,-322750,0,0,0,-0.6847219,-5815.915
8.264,-0.08263885,-6.342704,-323031.3,0,0,0,-0.6886571,-5820.982
8.304,-0.08287497,-6.359476,-323885.5,0,0,0,-0.6906247,-5836.375
8.318,-0.08311108,-6.375959,-324724.9,0,0,0,-0.6925923,-5851.501
8.332,-0.08334719,-6.396245,-325758.1,0,0,0,-0.6945599,-5870.119
8.352,-0.0835833,-6.405656,-326237.4,0,0,0,-0.6965275,-5878.756
8.376,-0.08381941,-6.390309,-325455.8,0,0,0,-0.6984951,-5864.672
8.4,-0.08405552,-6.406535,-326282.2,0,0,0,-0.7004626,-5879.563
8.418,-0.08405552,-6.381696,-325017.1,0,0,0,-0.7004626,-5856.767
8.424,-0.08429163,-6.365195,-324176.7,0,0,0,-0.7024302,-5841.623
8.436,-0.08429163,-6.340445,-322916.2,0,0,0,-0.7024302,-5818.909
8.446,-0.08452775,-6.323071,-322031.3,0,0,0,-0.7043979,-5802.964
8.454,-0.08452775,-6.300954,-320905,0,0,0,-0.7043979,-5782.667
8.462,-0.08452775,-6.274049,-319534.7,0,0,0,-0.7043979,-5757.975
8.47,-0.08452775,-6.249067,-318262.4,0,0,0,-0.7043979,-5735.047
8.478,-0.08476386,-6.232613,-317424.4,0,0,0,-0.7063655,-5719.947
8.496,-0.08499997,-6.213878,-316470.2,0,0,0,-0.708333,-5702.753
8.532,-0.08523608,-6.216632,-316610.5,0,0,0,-0.7103007,-5705.281
8.568,-0.0857083,-6.211963,-316372.7,0,0,0,-0.7142358,-5700.996
8.614,-0.08594441,-6.205622,-316049.8,0,0,0,-0.7162035,-5695.176
8.636,-0.08618053,-6.216984,-316628.4,0,0,0,-0.7181711,-5705.604
8.656,-0.08641663,-6.233507,-317469.9,0,0,0,-0.7201386,-5720.768
8.676,-0.08665274,-6.258521,-318743.8,0,0,0,-0.7221062,-5743.724
8.69,-0.08688885,-6.27673,-319671.3,0,0,0,-0.7240738,-5760.435
8.716,-0.08712496,-6.287955,-320242.9,0,0,0,-0.7260414,-5770.736
8.738,-0.08712496,-6.264485,-319047.6,0,0,0,-0.7260414,-5749.198
8.75,-0.08736108,-6.276192,-319643.8,0,0,0,-0.728009,-5759.941
8.768,-0.08759719,-6.290501,-320372.6,0,0,0,-0.7299766,-5773.073
8.792,-0.0878333,-6.306413,-321183,0,0,0,-0.7319442,-5787.676
8.82,-0.08806941,-6.28441,-320062.4,0,0,0,-0.7339118,-5767.483
8.844,-0.08830551,-6.304126,-321066.5,0,0,0,-0.7358793,-5785.578
8.856,-0.08830551,-6.3301,-322389.4,0,0,0,-0.7358793,-5809.416
8.87,-0.08854163,-6.346438,-323221.4,0,0,0,-0.7378469,-5824.409
8.902,-0.08877774,-6.320955,-321923.6,0,0,0,-0.7398145,-5801.022
8.916,-0.08901386,-6.298935,-320802.1,0,0,0,-0.7417821,-5780.813
8.94,-0.08924997,-6.315815,-321661.8,0,0,0,-0.7437497,-5796.305
8.958,-0.08924997,-6.339794,-322883.1,0,0,0,-0.7437497,-5818.312
8.966,-0.08948608,-6.355549,-323685.4,0,0,0,-0.7457173,-5832.771
8.978,-0.08948608,-6.377501,-324803.5,0,0,0,-0.7457173,-5852.917
9.006,-0.08995829,-6.369465,-324394.2,0,0,0,-0.7496524,-5845.542
9.04,-0.09019441,-6.381056,-324984.5,0,0,0,-0.7516201,-5856.18
9.076,-0.09066664,-6.386189,-325246,0,0,0,-0.7555553,-5860.891
9.108,-0.09090274,-6.376073,-324730.7,0,0,0,-0.7575228,-5851.606
9.132,-0.09113885,-6.377419,-324799.3,0,0,0,-0.7594904,-5852.841
9.146,-0.09137496,-6.394578,-325673.2,0,0,0,-0.761458,-5868.589
9.188,-0.09184719,-6.408708,-326392.8,0,0,0,-0.7653932,-5881.557
9.21,-0.09208329,-6.3852,-325195.6,0,0,0,-0.7673607,-5859.982
9.234,-0.09231941,-6.371542,-324500,0,0,0,-0.7693284,-5847.448
9.254,-0.09231941,-6.393204,-325603.2,0,0,0,-0.7693284,-5867.329
9.272,-0.09255552,-6.407827,-326347.9,0,0,0,-0.771296,-5880.748
9.3,-0.09279162,-6.401896,-326045.9,0,0,0,-0.7732635,-5875.306
9.328,-0.09326385,-6.410193,-326468.4,0,0,0,-0.7771988,-5882.92
9.346,-0.09326385,-6.431327,-327544.8,0,0,0,-0.7771988,-5902.315
9.356,-0.09349996,-6.446471,-328316.1,0,0,0,-0.7791663,-5916.214
9.372,-0.09373607,-6.465695,-329295.2,0,0,0,-0.7811339,-5933.856
9.416,-0.09420829,-6.461945,-329104.2,0,0,0,-0.7850691,-5930.416
9.43,-0.09420829,-6.486134,-330336.1,0,0,0,-0.7850691,-5952.614
9.464,-0.09468052,-6.507779,-331438.4,0,0,0,-0.7890043,-5972.479
9.514,-0.09515274,-6.499279,-331005.6,0,0,0,-0.7929395,-5964.678
9.54,-0.09538885,-6.511384,-331622.1,0,0,0,-0.7949071,-5975.787
9.566,-0.09562496,-6.528728,-332505.4,0,0,0,-0.7968747,-5991.705
9.59,-0.09586107,-6.5032,-331205.3,0,0,0,-0.7988423,-5968.277
9.624,-0.09609718,-6.51125,-331615.3,0,0,0,-0.8008099,-5975.665
9.634,-0.09633329,-6.527271,-332431.2,0,0,0,-0.8027774,-5990.368
9.646,-0.09633329,-6.552132,-333697.4,0,0,0,-0.8027774,-6013.184
9.656,-0.0965694,-6.573328,-334776.8,0,0,0,-0.804745,-6032.636
9.672,-0.0965694,-6.594644,-335862.5,0,0,0,-0.804745,-6052.199
9.698,-0.09704163,-6.585244,-335383.7,0,0,0,-0.8086802,-6043.572
9.712,-0.09704163,-6.564959,-334350.7,0,0,0,-0.8086802,-6024.956
9.744,-0.09727774,-6.573014,-334760.9,0,0,0,-0.8106478,-6032.349
9.756,-0.09751385,-6.585387,-335391,0,0,0,-0.8126154,-6043.703
9.782,-0.09774995,-6.580226,-335128.2,0,0,0,-0.8145829,-6038.967
9.792,-0.09798607,-6.557862,-333989.2,0,0,0,-0.8165506,-6018.442
9.806,-0.09798607,-6.537248,-332939.3,0,0,0,-0.8165506,-5999.524
9.838,-0.09845829,-6.524772,-332303.9,0,0,0,-0.8204858,-5988.075
9.862,-0.09869441,-6.511921,-331649.4,0,0,0,-0.8224534,-5976.28
9.886,-0.09893051,-6.488605,-330462,0,0,0,-0.8244209,-5954.882
9.898,-0.09893051,-6.463611,-329189,0,0,0,-0.8244209,-5931.944
9.906,-0.09893051,-6.44217,-328097,0,0,0,-0.8244209,-5912.267
9.938,-0.09940273,-6.430986,-327527.4,0,0,0,-0.8283561,-5902.003
9.97,-0.09963885,-6.420371,-326986.8,0,0,0,-0.8303237,-5892.26
9.98,-0.09963885,-6.39345,-325615.7,0,0,0,-0.8303237,-5867.554
9.988,-0.09963885,-6.356438,-323730.7,0,0,0,-0.8303237,-5833.586
9.994,-0.09987496,-6.327581,-322261.1,0,0,0,-0.8322913,-5807.104
10,-0.09987496,-6.298017,-320755.4,0,0,0,-0.8322913,-5779.971
10.004,-0.09987496,-6.276419,-319655.4,0,0,0,-0.8322913,-5760.15
10.008,-0.09987496,-6.252792,-318452.1,0,0,0,-0.8322913,-5738.466
10.012,-0.09987496,-6.227032,-317140.2,0,0,0,-0.8322913,-5714.825
10.016,-0.1001111,-6.199182,-315721.8,0,0,0,-0.834259,-5689.266
"Specimen",2
"Specimen name:",""
"Width:",6.350000,"mm"
"Thickness:",1.524000,"mm"
"Length:",12.000000,"mm"
"Diameter:",5.000000,"um"
"Inner diameter:",0.500000,"mm"
"Outer diameter:",1.000000,"mm"
"Wall thickness:",0.500000,"mm"
"Area:",19.634954,"um*um"
"Linear density:",1.000000,"den"
"Sled weight:",9.806650,"N"
"Loading span:",0.000000,"mm"
"Support span:",1.000000,"mm"
"Span ratio:","2"
"Fixture type:","3-point"
"Comment:",""
"Included"
"Time sec","Extension mm","Load N","Stress MPa","Cycle Count ","Total Cycle Count ","Repetitions Count ","Strain [Exten.] %","Tenacity gf/tex"
0,0,-4.016261,-204546.5,0,0,0,0,-3685.902
0.014,0,-4.039112,-205710.3,0,0,0,0,-3706.873
0.038,0,-4.037202,-205613,0,0,0,0,-3705.121
0.05,0,-4.009727,-204213.8,0,0,0,0,-3679.906
0.07,0,-4.010768,-204266.7,0,0,0,0,-3680.86
0.082,0,-4.033725,-205435.9,0,0,0,0,-3701.929
0.094,-0.000236111,-4.061645,-206857.9,0,0,0,-0.001967592,-3727.553
0.102,-0.000236111,-4.095955,-208605.3,0,0,0,-0.001967592,-3759.04
0.106,-0.000236111,-4.116922,-209673.1,0,0,0,-0.001967592,-3778.283
0.11,-0.000236111,-4.137996,-210746.4,0,0,0,-0.001967592,-3797.624
0.118,-0.000236111,-4.17072,-212413,0,0,0,-0.001967592,-3827.656
0.136,-0.000472222,-4.185322,-213156.7,0,0,0,-0.003935183,-3841.057
0.172,-0.0007083331,-4.206107,-214215.3,0,0,0,-0.005902776,-3860.132
0.182,-0.0007083331,-4.232724,-215570.9,0,0,0,-0.005902776,-3884.56
0.19,-0.0007083331,-4.258606,-216889,0,0,0,-0.005902776,-3908.313
0.198,-0.0007083331,-4.285499,-218258.7,0,0,0,-0.005902776,-3932.993
0.206,-0.0007083331,-4.309243,-219467.9,0,0,0,-0.005902776,-3954.784
0.216,-0.000944444,-4.324818,-220261.2,0,0,0,-0.007870367,-3969.078
0.248,-0.001180555,-4.3424,-221156.6,0,0,0,-0.009837959,-3985.215
0.27,-0.001180555,-4.364855,-222300.3,0,0,0,-0.009837959,-4005.822
0.284,-0.001416666,-4.390317,-223597,0,0,0,-0.01180555,-4029.189
0.292,-0.001416666,-4.417914,-225002.5,0,0,0,-0.01180555,-4054.517
0.3,-0.001416666,-4.445699,-226417.6,0,0,0,-0.01180555,-4080.016
0.314,-0.001416666,-4.469756,-227642.8,0,0,0,-0.01180555,-4102.094
0.332,-0.001416666,-4.491822,-228766.6,0,0,0,-0.01180555,-4122.346
0.352,-0.001652777,-4.486614,-228501.4,0,0,0,-0.01377314,-4117.565
0.36,-0.001652777,-4.463457,-227322,0,0,0,-0.01377314,-4096.313
0.37,-0.001652777,-4.440004,-226127.5,0,0,0,-0.01377314,-4074.789
0.384,-0.001652777,-4.465222,-227411.9,0,0,0,-0.01377314,-4097.933
0.392,-0.001652777,-4.491711,-228760.9,0,0,0,-0.01377314,-4122.243
0.4,-0.001652777,-4.515251,-229959.9,0,0,0,-0.01377314,-4143.847
0.412,-0.001888888,-4.540688,-231255.3,0,0,0,-0.01574073,-4167.192
0.424,-0.002124999,-4.568593,-232676.5,0,0,0,-0.01770833,-4192.801
0.436,-0.002124999,-4.593711,-233955.8,0,0,0,-0.01770833,-4215.854
0.446,-0.00236111,-4.612837,-234929.9,0,0,0,-0.01967592,-4233.407
0.456,-0.002597221,-4.632729,-235943,0,0,0,-0.02164351,-4251.662
0.466,-0.002597221,-4.659161,-237289.1,0,0,0,-0.02164351,-4275.92
0.472,-0.002833332,-4.680836,-238393,0,0,0,-0.0236111,-4295.812
0.48,-0.002833332,-4.714279,-240096.2,0,0,0,-0.0236111,-4326.503
0.486,-0.003069443,-4.739408,-241376.1,0,0,0,-0.02557869,-4349.566
0.494,-0.003069443,-4.767902,-242827.3,0,0,0,-0.02557869,-4375.716
0.502,-0.003305554,-4.792307,-244070.2,0,0,0,-0.02754628,-4398.114
0.51,-0.003305554,-4.814015,-245175.8,0,0,0,-0.02754628,-4418.036
0.518,-0.003541665,-4.833762,-246181.5,0,0,0,-0.02951388,-4436.159
0.532,-0.003777776,-4.857898,-247410.7,0,0,0,-0.03148147,-4458.31
0.548,-0.004013887,-4.880645,-248569.2,0,0,0,-0.03344906,-4479.186
0.558,-0.004013887,-4.907859,-249955.2,0,0,0,-0.03344906,-4504.162
0.564,-0.004249998,-4.925023,-250829.4,0,0,0,-0.03541665,-4519.914
0.574,-0.004249998,-4.949773,-252089.9,0,0,0,-0.03541665,-4542.627
0.59,-0.004486109,-4.974519,-253350.2,0,0,0,-0.03738425,-4565.338
0.602,-0.00472222,-4.992367,-254259.2,0,0,0,-0.03935184,-4581.718
0.61,-0.004958331,-5.011235,-255220.1,0,0,0,-0.04131943,-4599.034
0.618,-0.004958331,-5.03253,-256304.6,0,0,0,-0.04131943,-4618.577
0.626,-0.005194443,-5.054418,-257419.4,0,0,0,-0.04328702,-4638.665
0.642,-0.005430553,-5.077276,-258583.6,0,0,0,-0.04525461,-4659.643
0.658,-0.005430553,-5.099124,-259696.3,0,0,0,-0.04525461,-4679.694
0.666,-0.005666665,-5.114569,-260482.9,0,0,0,-0.0472222,-4693.868
0.676,-0.005902775,-5.134935,-261520.1,0,0,0,-0.04918979,-4712.559
[...]
5.558,-0.05524998,-13.49981,-687539.7,0,0,0,-0.4604165,-12389.38
5.568,-0.05548609,-13.5138,-688252.1,0,0,0,-0.4623841,-12402.22
5.584,-0.0557222,-13.53031,-689092.9,0,0,0,-0.4643517,-12417.37
5.598,-0.0557222,-13.55503,-690352.2,0,0,0,-0.4643517,-12440.06
5.606,-0.05595831,-13.5741,-691323.2,0,0,0,-0.4663192,-12457.56
5.618,-0.05595831,-13.59825,-692553.4,0,0,0,-0.4663192,-12479.72
5.632,-0.05619442,-13.61042,-693173.1,0,0,0,-0.4682868,-12490.89
5.65,-0.05619442,-13.63196,-694269.9,0,0,0,-0.4682868,-12510.65
5.664,-0.05643053,-13.65452,-695418.8,0,0,0,-0.4702544,-12531.36
5.68,-0.05666664,-13.66822,-696116.8,0,0,0,-0.472222,-12543.94
5.694,-0.05666664,-13.69396,-697427.6,0,0,0,-0.472222,-12567.56
5.702,-0.05690275,-13.71296,-698395.3,0,0,0,-0.4741896,-12584.99
5.738,-0.05713886,-13.73535,-699535.5,0,0,0,-0.4761572,-12605.54
5.75,-0.05713886,-13.7594,-700760.3,0,0,0,-0.4761572,-12627.61
5.76,-0.05737497,-13.77485,-701547.6,0,0,0,-0.4781248,-12641.8
5.774,-0.05737497,-13.79921,-702788.1,0,0,0,-0.4781248,-12664.15
5.78,-0.05761109,-13.81386,-703534.1,0,0,0,-0.4800924,-12677.59
5.79,-0.05761109,-13.83808,-704767.4,0,0,0,-0.4800924,-12699.82
5.802,-0.0578472,-13.85294,-705524.4,0,0,0,-0.48206,-12713.46
5.82,-0.0578472,-13.87572,-706684.4,0,0,0,-0.48206,-12734.36
5.836,-0.05808331,-13.89387,-707608.8,0,0,0,-0.4840276,-12751.02
5.856,-0.05831942,-13.91776,-708825.9,0,0,0,-0.4859952,-12772.95
5.87,-0.05831942,-13.94115,-710016.9,0,0,0,-0.4859952,-12794.42
5.88,-0.05855553,-13.95575,-710760.4,0,0,0,-0.4879628,-12807.81
5.896,-0.05879164,-13.97282,-711630.1,0,0,0,-0.4899304,-12823.48
5.91,-0.05879164,-13.99352,-712684.3,0,0,0,-0.4899304,-12842.48
5.918,-0.05902775,-14.00851,-713447.3,0,0,0,-0.4918979,-12856.23
5.93,-0.05902775,-14.03193,-714640.3,0,0,0,-0.4918979,-12877.73
5.942,-0.05926386,-14.05125,-715624.5,0,0,0,-0.4938655,-12895.46
5.958,-0.05926386,-14.07533,-716850.7,0,0,0,-0.4938655,-12917.56
5.97,-0.05949998,-14.10041,-718127.9,0,0,0,-0.4958331,-12940.57
5.986,-0.05973608,-14.11366,-718802.8,0,0,0,-0.4978007,-12952.74
6.006,-0.05973608,-14.13689,-719985.8,0,0,0,-0.4978007,-12974.05
6.014,-0.05997219,-14.15873,-721098,0,0,0,-0.4997683,-12994.09
6.026,-0.05997219,-14.18544,-722458.5,0,0,0,-0.4997683,-13018.61
6.034,-0.06020831,-14.20055,-723228.1,0,0,0,-0.5017359,-13032.48
6.052,-0.06020831,-14.223,-724371.3,0,0,0,-0.5017359,-13053.08
6.068,-0.06044442,-14.23936,-725204.9,0,0,0,-0.5037035,-13068.1
6.082,-0.06068053,-14.25156,-725825.9,0,0,0,-0.5056711,-13079.29
6.096,-0.06068053,-14.27333,-726934.9,0,0,0,-0.5056711,-13099.27
6.108,-0.06068053,-14.29546,-728061.6,0,0,0,-0.5056711,-13119.58
6.118,-0.06091664,-14.30898,-728750.4,0,0,0,-0.5076387,-13131.99
6.142,-0.06115275,-14.33067,-729855.3,0,0,0,-0.5096063,-13151.9
6.154,-0.06115275,-14.35696,-731193.8,0,0,0,-0.5096063,-13176.02
6.164,-0.06138886,-14.37566,-732146.1,0,0,0,-0.5115739,-13193.18
6.194,-0.06162497,-14.39233,-732995.5,0,0,0,-0.5135415,-13208.49
6.206,-0.06186108,-14.41809,-734307.3,0,0,0,-0.515509,-13232.13
6.214,-0.06186108,-14.43936,-735390.8,0,0,0,-0.515509,-13251.65
6.222,-0.06186108,-14.46136,-736510.9,0,0,0,-0.515509,-13271.83
6.23,-0.0620972,-14.48011,-737465.8,0,0,0,-0.5174766,-13289.04
6.242,-0.0620972,-14.50305,-738634.2,0,0,0,-0.5174766,-13310.09
6.272,-0.06256942,-14.52095,-739546,0,0,0,-0.5214118,-13326.52
6.296,-0.06280552,-14.53534,-740278.8,0,0,0,-0.5233794,-13339.73
6.306,-0.06280552,-14.56111,-741591.1,0,0,0,-0.5233794,-13363.38
6.314,-0.06280552,-14.58504,-742810,0,0,0,-0.5233794,-13385.34
6.322,-0.06304164,-14.60894,-744027.3,0,0,0,-0.525347,-13407.28
6.332,-0.06304164,-14.63063,-745131.9,0,0,0,-0.525347,-13427.18
6.366,-0.06351386,-14.64439,-745832.8,0,0,0,-0.5292822,-13439.81
6.39,-0.06374998,-14.66903,-747087.7,0,0,0,-0.5312498,-13462.42
6.398,-0.06374998,-14.69343,-748330.1,0,0,0,-0.5312498,-13484.81
6.406,-0.06374998,-14.72016,-749691.6,0,0,0,-0.5312498,-13509.35
6.412,-0.06398609,-14.73621,-750509.3,0,0,0,-0.5332174,-13524.08
6.428,-0.06398609,-14.75827,-751632.4,0,0,0,-0.5332174,-13544.32
6.446,-0.0642222,-14.778,-752637.2,0,0,0,-0.535185,-13562.43
6.458,-0.0644583,-14.7968,-753594.8,0,0,0,-0.5371525,-13579.68
6.478,-0.06469441,-14.81841,-754695.6,0,0,0,-0.5391201,-13599.52
6.492,-0.06469441,-14.84031,-755810.6,0,0,0,-0.5391201,-13619.61
6.502,-0.06493053,-14.86657,-757148.2,0,0,0,-0.5410877,-13643.71
6.512,-0.06493053,-14.891,-758392.4,0,0,0,-0.5410877,-13666.13
6.524,-0.06516664,-14.91812,-759773.4,0,0,0,-0.5430554,-13691.02
6.536,-0.06516664,-14.94087,-760932.1,0,0,0,-0.5430554,-13711.9
6.564,-0.06563886,-14.93994,-760885.1,0,0,0,-0.5469905,-13711.05
6.59,-0.06587497,-14.96073,-761943.7,0,0,0,-0.5489581,-13730.13
6.598,-0.06587497,-14.9853,-763194.8,0,0,0,-0.5489581,-13752.67
6.606,-0.06587497,-15.00942,-764423.4,0,0,0,-0.5489581,-13774.81
6.614,-0.06611108,-15.03346,-765647.7,0,0,0,-0.5509257,-13796.87
6.624,-0.06611108,-15.0581,-766902.6,0,0,0,-0.5509257,-13819.49
6.64,-0.06634719,-15.0799,-768012.8,0,0,0,-0.5528933,-13839.49
6.68,-0.06658331,-15.08525,-768285.3,0,0,0,-0.5548609,-13844.4
6.692,-0.06658331,-15.11249,-769672.8,0,0,0,-0.5548609,-13869.41
6.7,-0.06681942,-15.1333,-770732.8,0,0,0,-0.5568284,-13888.51
6.712,-0.06681942,-15.16035,-772110.2,0,0,0,-0.5568284,-13913.33
6.724,-0.06705553,-15.17762,-772989.8,0,0,0,-0.5587961,-13929.18
6.75,-0.06729164,-15.197,-773976.8,0,0,0,-0.5607637,-13946.96
6.784,-0.06752774,-15.21598,-774943.3,0,0,0,-0.5627312,-13964.38
6.796,-0.06752774,-15.24539,-776441.3,0,0,0,-0.5627312,-13991.37
6.804,-0.06776386,-15.26395,-777386.6,0,0,0,-0.5646988,-14008.41
6.812,-0.06776386,-15.28898,-778661.3,0,0,0,-0.5646988,-14031.38
6.822,-0.06776386,-15.30969,-779716.3,0,0,0,-0.5646988,-14050.39
6.832,-0.06799997,-15.3223,-780358.6,0,0,0,-0.5666664,-14061.96
6.848,-0.06823608,-15.33435,-780972.3,0,0,0,-0.568634,-14073.02
6.872,-0.0684722,-15.35253,-781897.9,0,0,0,-0.5706016,-14089.7
6.888,-0.0684722,-15.37385,-782983.9,0,0,0,-0.5706016,-14109.27
6.894,-0.0687083,-15.38978,-783794.9,0,0,0,-0.5725692,-14123.88
6.902,-0.0687083,-15.41664,-785163,0,0,0,-0.5725692,-14148.54
6.91,-0.0687083,-15.44089,-786398.2,0,0,0,-0.5725692,-14170.79
6.918,-0.06894442,-15.45478,-787105.3,0,0,0,-0.5745368,-14183.54
6.946,-0.06918052,-15.47565,-788168.4,0,0,0,-0.5765043,-14202.7
6.958,-0.06918052,-15.49701,-789256.3,0,0,0,-0.5765043,-14222.3
6.968,-0.06941664,-15.51638,-790242.9,0,0,0,-0.578472,-14240.08
6.98,-0.06941664,-15.53732,-791309.3,0,0,0,-0.578472,-14259.29
6.988,-0.06965275,-15.55296,-792105.6,0,0,0,-0.5804396,-14273.64
7,-0.06965275,-15.5811,-793538.7,0,0,0,-0.5804396,-14299.47
7.01,-0.06988886,-15.60117,-794561.1,0,0,0,-0.5824072,-14317.89
7.028,-0.07012497,-15.61441,-795235.3,0,0,0,-0.5843747,-14330.04
7.052,-0.07036108,-15.63274,-796168.9,0,0,0,-0.5863424,-14346.86
7.066,-0.07036108,-15.65618,-797362.9,0,0,0,-0.5863424,-14368.38
7.074,-0.0705972,-15.67104,-798119.8,0,0,0,-0.58831,-14382.02
7.086,-0.0705972,-15.69549,-799364.8,0,0,0,-0.58831,-14404.45
7.098,-0.0705972,-15.72109,-800668.4,0,0,0,-0.58831,-14427.94
7.106,-0.0708333,-15.73916,-801588.6,0,0,0,-0.5902776,-14444.53
7.124,-0.07106941,-15.7573,-802512.5,0,0,0,-0.5922451,-14461.17
7.158,-0.07130553,-15.77756,-803544.6,0,0,0,-0.5942127,-14479.77
7.172,-0.07154164,-15.79966,-804670.2,0,0,0,-0.5961803,-14500.05
7.184,-0.07154164,-15.82226,-805821,0,0,0,-0.5961803,-14520.79
7.196,-0.07177775,-15.85079,-807274,0,0,0,-0.5981479,-14546.97
7.208,-0.07177775,-15.87533,-808523.9,0,0,0,-0.5981479,-14569.5
7.242,-0.07201386,-15.89502,-809526.9,0,0,0,-0.6001155,-14587.57
7.25,-0.07224997,-15.90914,-810246,0,0,0,-0.6020831,-14600.53
7.262,-0.07224997,-15.93427,-811525.6,0,0,0,-0.6020831,-14623.59
7.272,-0.07248608,-15.95042,-812348.1,0,0,0,-0.6040506,-14638.41
7.284,-0.07248608,-15.97518,-813609,0,0,0,-0.6040506,-14661.13
7.294,-0.07272219,-15.99807,-814775.3,0,0,0,-0.6060182,-14682.15
7.31,-0.0729583,-16.01753,-815766.3,0,0,0,-0.6079859,-14700
7.33,-0.0729583,-16.03942,-816880.9,0,0,0,-0.6079859,-14720.09
7.34,-0.07319441,-16.05839,-817847.1,0,0,0,-0.6099535,-14737.5
7.352,-0.07319441,-16.08236,-819067.9,0,0,0,-0.6099535,-14759.5
7.366,-0.07343053,-16.1055,-820246.2,0,0,0,-0.6119211,-14780.73
7.38,-0.07343053,-16.12637,-821309.1,0,0,0,-0.6119211,-14799.89
7.388,-0.07366664,-16.1416,-822085,0,0,0,-0.6138886,-14813.87
7.404,-0.07390274,-16.1601,-823027.2,0,0,0,-0.6158562,-14830.84
7.426,-0.07413886,-16.17796,-823936.9,0,0,0,-0.6178238,-14847.24
7.438,-0.07413886,-16.20221,-825171.6,0,0,0,-0.6178238,-14869.49
7.45,-0.07437497,-16.22117,-826137.7,0,0,0,-0.6197914,-14886.9
7.47,-0.07437497,-16.24351,-827275.1,0,0,0,-0.6197914,-14907.39
7.48,-0.07461108,-16.26323,-828279.5,0,0,0,-0.621759,-14925.49
7.492,-0.07461108,-16.29239,-829764.8,0,0,0,-0.621759,-14952.26
7.506,-0.07484719,-16.31141,-830733.3,0,0,0,-0.6237266,-14969.71
7.532,-0.0750833,-16.32731,-831543,0,0,0,-0.6256942,-14984.3
7.55,-0.07531942,-16.35075,-832736.7,0,0,0,-0.6276618,-15005.81
7.562,-0.07531942,-16.37871,-834160.9,0,0,0,-0.6276618,-15031.47
7.57,-0.07555552,-16.4004,-835265.4,0,0,0,-0.6296294,-15051.38
7.582,-0.07555552,-16.42982,-836764,0,0,0,-0.6296294,-15078.38
7.592,-0.07579163,-16.45337,-837963.3,0,0,0,-0.6315969,-15099.99
7.606,-0.07579163,-16.47507,-839068.4,0,0,0,-0.6315969,-15119.91
7.638,-0.07626386,-16.46949,-838784.3,0,0,0,-0.6355321,-15114.79
7.656,-0.07626386,-16.49634,-840151.5,0,0,0,-0.6355321,-15139.42
7.662,-0.07649997,-16.51226,-840962.6,0,0,0,-0.6374997,-15154.04
7.674,-0.07649997,-16.53647,-842195.4,0,0,0,-0.6374997,-15176.25
7.686,-0.07673609,-16.55753,-843267.9,0,0,0,-0.6394674,-15195.58
7.7,-0.07673609,-16.58102,-844464.6,0,0,0,-0.6394674,-15217.14
7.71,-0.07697219,-16.59321,-845085.2,0,0,0,-0.6414349,-15228.33
7.732,-0.0772083,-16.61331,-846109.1,0,0,0,-0.6434025,-15246.78
7.746,-0.0772083,-16.63717,-847324.1,0,0,0,-0.6434025,-15268.67
7.756,-0.07744441,-16.65885,-848428.1,0,0,0,-0.6453701,-15288.57
7.766,-0.07744441,-16.6845,-849734.6,0,0,0,-0.6453701,-15312.11
7.776,-0.07744441,-16.70932,-850998.7,0,0,0,-0.6453701,-15334.89
7.784,-0.07768052,-16.7262,-851858.4,0,0,0,-0.6473377,-15350.38
7.8,-0.07791664,-16.7427,-852698.5,0,0,0,-0.6493053,-15365.52
7.822,-0.07815275,-16.76361,-853763.8,0,0,0,-0.651273,-15384.71
7.844,-0.07838886,-16.78668,-854938.6,0,0,0,-0.6532405,-15405.88
7.856,-0.07838886,-16.80919,-856085.1,0,0,0,-0.6532405,-15426.54
7.868,-0.07862496,-16.83322,-857308.7,0,0,0,-0.655208,-15448.59
7.88,-0.07862496,-16.85525,-858431.1,0,0,0,-0.655208,-15468.82
7.892,-0.07886108,-16.876,-859487.9,0,0,0,-0.6571757,-15487.86
7.904,-0.07886108,-16.89829,-860623.1,0,0,0,-0.6571757,-15508.32
7.938,-0.0793333,-16.9209,-861774.4,0,0,0,-0.6611109,-15529.06
7.95,-0.0793333,-16.94494,-862998.6,0,0,0,-0.6611109,-15551.13
7.96,-0.07956942,-16.96952,-864250.5,0,0,0,-0.6630785,-15573.68
7.976,-0.07956942,-16.99168,-865379,0,0,0,-0.6630785,-15594.02
7.992,-0.07980552,-17.01092,-866358.9,0,0,0,-0.665046,-15611.68
8.002,-0.07980552,-17.03585,-867628.9,0,0,0,-0.665046,-15634.56
8.014,-0.08004164,-17.05705,-868708.4,0,0,0,-0.6670136,-15654.01
8.034,-0.08027774,-17.08041,-869898.1,0,0,0,-0.6689812,-15675.45
8.046,-0.08027774,-17.10363,-871080.5,0,0,0,-0.6689812,-15696.76
8.054,-0.08051386,-17.1193,-871878.6,0,0,0,-0.6709488,-15711.14
8.07,-0.08074997,-17.13592,-872725.3,0,0,0,-0.6729164,-15726.4
8.088,-0.08074997,-17.16022,-873963.1,0,0,0,-0.6729164,-15748.7
8.096,-0.08098608,-17.17631,-874782.5,0,0,0,-0.674884,-15763.47
8.11,-0.08098608,-17.19866,-875920.6,0,0,0,-0.674884,-15783.98
8.12,-0.08122219,-17.21273,-876637.3,0,0,0,-0.6768516,-15796.89
8.132,-0.0814583,-17.23091,-877563.1,0,0,0,-0.6788192,-15813.58
8.146,-0.0814583,-17.2572,-878902.1,0,0,0,-0.6788192,-15837.7
8.154,-0.08169441,-17.27423,-879769.4,0,0,0,-0.6807867,-15853.33
8.166,-0.08169441,-17.2992,-881040.9,0,0,0,-0.6807867,-15876.25
8.176,-0.08193052,-17.31731,-881963.3,0,0,0,-0.6827543,-15892.87
8.198,-0.08216663,-17.33511,-882869.7,0,0,0,-0.6847219,-15909.2
8.214,-0.08216663,-17.35839,-884055.3,0,0,0,-0.6847219,-15930.56
8.222,-0.08240275,-17.37858,-885084,0,0,0,-0.6866896,-15949.1
8.236,-0.08240275,-17.40303,-886329.3,0,0,0,-0.6866896,-15971.54
8.254,-0.08263885,-17.42719,-887559.7,0,0,0,-0.6886571,-15993.71
8.266,-0.08263885,-17.44923,-888682.1,0,0,0,-0.6886571,-16013.94
8.296,-0.08311108,-17.4667,-889571.9,0,0,0,-0.6925923,-16029.97
8.312,-0.08311108,-17.49166,-890843,0,0,0,-0.6925923,-16052.88
8.32,-0.08334719,-17.50539,-891542.3,0,0,0,-0.6945599,-16065.48
8.334,-0.08334719,-17.52616,-892599.9,0,0,0,-0.6945599,-16084.54
8.344,-0.0835833,-17.54037,-893323.9,0,0,0,-0.6965275,-16097.58
8.36,-0.0835833,-17.56698,-894678.7,0,0,0,-0.6965275,-16122
8.37,-0.08381941,-17.58591,-895643.3,0,0,0,-0.6984951,-16139.38
8.388,-0.08381941,-17.60738,-896736.4,0,0,0,-0.6984951,-16159.08
8.404,-0.08405552,-17.6287,-897822.3,0,0,0,-0.7004626,-16178.64
8.418,-0.08405552,-17.6523,-899024.3,0,0,0,-0.7004626,-16200.3
8.426,-0.08429163,-17.66622,-899733.1,0,0,0,-0.7024302,-16213.08
8.444,-0.08452775,-17.68849,-900867.3,0,0,0,-0.7043979,-16233.51
8.466,-0.08452775,-17.70915,-901919.5,0,0,0,-0.7043979,-16252.47
8.476,-0.08476386,-17.72235,-902591.9,0,0,0,-0.7063655,-16264.59
8.494,-0.08499997,-17.7447,-903730.1,0,0,0,-0.708333,-16285.1
8.522,-0.08523608,-17.76847,-904940.8,0,0,0,-0.7103007,-16306.92
8.53,-0.08523608,-17.79256,-906167.6,0,0,0,-0.7103007,-16329.02
8.544,-0.08547218,-17.8101,-907060.8,0,0,0,-0.7122682,-16345.12
8.57,-0.0857083,-17.83061,-908105.4,0,0,0,-0.7142358,-16363.94
8.582,-0.0857083,-17.85666,-909432.5,0,0,0,-0.7142358,-16387.86
8.608,-0.08594441,-17.86745,-909981.9,0,0,0,-0.7162035,-16397.76
8.616,-0.08594441,-17.89124,-911193.6,0,0,0,-0.7162035,-16419.59
8.622,-0.08618053,-17.90871,-912083,0,0,0,-0.7181711,-16435.62
8.648,-0.08641663,-17.92407,-912865.3,0,0,0,-0.7201386,-16449.71
8.662,-0.08641663,-17.94915,-914142.7,0,0,0,-0.7201386,-16472.73
8.67,-0.08641663,-17.97185,-915298.6,0,0,0,-0.7201386,-16493.56
8.678,-0.08665274,-17.98906,-916175.3,0,0,0,-0.7221062,-16509.36
8.698,-0.08688885,-18.01237,-917362.3,0,0,0,-0.7240738,-16530.75
8.712,-0.08688885,-18.03945,-918741.5,0,0,0,-0.7240738,-16555.6
8.722,-0.08712496,-18.05924,-919749.3,0,0,0,-0.7260414,-16573.77
8.744,-0.08712496,-18.08206,-920911.9,0,0,0,-0.7260414,-16594.71
8.754,-0.08736108,-18.1038,-922019.1,0,0,0,-0.728009,-16614.67
8.772,-0.08759719,-18.1237,-923032.3,0,0,0,-0.7299766,-16632.92
8.798,-0.0878333,-18.14019,-923872.2,0,0,0,-0.7319442,-16648.06
8.81,-0.0878333,-18.1649,-925130.9,0,0,0,-0.7319442,-16670.74
8.82,-0.08806941,-18.17808,-925801.9,0,0,0,-0.7339118,-16682.83
8.832,-0.08806941,-18.20201,-927021,0,0,0,-0.7339118,-16704.8
8.846,-0.08830551,-18.22537,-928210.4,0,0,0,-0.7358793,-16726.23
8.868,-0.08854163,-18.24313,-929115.1,0,0,0,-0.7378469,-16742.54
8.88,-0.08854163,-18.2665,-930305,0,0,0,-0.7378469,-16763.98
8.89,-0.08877774,-18.28339,-931165.3,0,0,0,-0.7398145,-16779.48
8.906,-0.08877774,-18.30728,-932382.2,0,0,0,-0.7398145,-16801.41
8.918,-0.08901386,-18.32562,-933316.1,0,0,0,-0.7417821,-16818.24
8.93,-0.08901386,-18.34661,-934385.3,0,0,0,-0.7417821,-16837.5
8.944,-0.08924997,-18.36352,-935246.6,0,0,0,-0.7437497,-16853.03
8.964,-0.08948608,-18.38245,-936210.6,0,0,0,-0.7457173,-16870.39
8.972,-0.08948608,-18.407,-937460.8,0,0,0,-0.7457173,-16892.93
8.978,-0.08972218,-18.42467,-938360.9,0,0,0,-0.7476848,-16909.14
9,-0.08995829,-18.42987,-938625.6,0,0,0,-0.7496524,-16913.91
9.022,-0.08995829,-18.45641,-939977.1,0,0,0,-0.7496524,-16938.27
9.028,-0.09019441,-18.47699,-941025.6,0,0,0,-0.7516201,-16957.16
9.038,-0.09019441,-18.4992,-942156.7,0,0,0,-0.7516201,-16977.54
9.054,-0.09043052,-18.51683,-943054.5,0,0,0,-0.7535877,-16993.72
9.064,-0.09043052,-18.54116,-944293.4,0,0,0,-0.7535877,-17016.05
9.072,-0.09066664,-18.56307,-945409.4,0,0,0,-0.7555553,-17036.16
9.096,-0.09090274,-18.58227,-946387.4,0,0,0,-0.7575228,-17053.78
9.118,-0.09090274,-18.60763,-947678.8,0,0,0,-0.7575228,-17077.05
9.128,-0.09113885,-18.62913,-948774,0,0,0,-0.7594904,-17096.79
9.142,-0.09113885,-18.65267,-949972.5,0,0,0,-0.7594904,-17118.38
9.152,-0.09137496,-18.67355,-951036.3,0,0,0,-0.761458,-17137.55
9.164,-0.09137496,-18.70159,-952464.1,0,0,0,-0.761458,-17163.28
9.184,-0.09161107,-18.7189,-953345.9,0,0,0,-0.7634256,-17179.17
9.198,-0.09184719,-18.73699,-954267.2,0,0,0,-0.7653932,-17195.77
9.21,-0.09184719,-18.76244,-955563.2,0,0,0,-0.7653932,-17219.13
9.236,-0.09231941,-18.77255,-956078.1,0,0,0,-0.7693284,-17228.4
9.248,-0.09231941,-18.7984,-957394.6,0,0,0,-0.7693284,-17252.13
9.256,-0.09231941,-18.82389,-958692.9,0,0,0,-0.7693284,-17275.53
9.282,-0.09279162,-18.83724,-959372.6,0,0,0,-0.7732635,-17287.77
9.3,-0.09279162,-18.86106,-960585.9,0,0,0,-0.7732635,-17309.63
9.308,-0.09302774,-18.88107,-961604.8,0,0,0,-0.7752311,-17328
9.316,-0.09302774,-18.90138,-962639.4,0,0,0,-0.7752311,-17346.64
9.324,-0.09326385,-18.91899,-963536.3,0,0,0,-0.7771988,-17362.8
9.338,-0.09326385,-18.94181,-964698.7,0,0,0,-0.7771988,-17383.75
9.348,-0.09349996,-18.96521,-965890.2,0,0,0,-0.7791663,-17405.22
9.362,-0.09349996,-18.98893,-967098.3,0,0,0,-0.7791663,-17426.99
9.382,-0.09373607,-19.00492,-967912.7,0,0,0,-0.7811339,-17441.66
9.39,-0.09397218,-19.02188,-968776.2,0,0,0,-0.7831016,-17457.22
9.402,-0.09397218,-19.04975,-970196.1,0,0,0,-0.7831016,-17482.81
9.412,-0.09420829,-19.0709,-971273,0,0,0,-0.7850691,-17502.22
9.424,-0.09420829,-19.09326,-972411.6,0,0,0,-0.7850691,-17522.73
9.434,-0.0944444,-19.10899,-973212.9,0,0,0,-0.7870367,-17537.17
9.45,-0.0944444,-19.13138,-974353.2,0,0,0,-0.7870367,-17557.72
9.46,-0.09468052,-19.14782,-975190.7,0,0,0,-0.7890043,-17572.81
9.474,-0.09491662,-19.17078,-976359.8,0,0,0,-0.7909719,-17593.88
9.496,-0.09515274,-19.19159,-977419.8,0,0,0,-0.7929395,-17612.98
9.512,-0.09515274,-19.21502,-978612.8,0,0,0,-0.7929395,-17634.48
9.524,-0.09538885,-19.24048,-979909.4,0,0,0,-0.7949071,-17657.84
9.536,-0.09538885,-19.26686,-981253.3,0,0,0,-0.7949071,-17682.06
9.544,-0.09562496,-19.28499,-982176.5,0,0,0,-0.7968747,-17698.7
9.556,-0.09562496,-19.3085,-983373.8,0,0,0,-0.7968747,-17720.27
9.576,-0.09586107,-19.32443,-984185.2,0,0,0,-0.7988423,-17734.89
9.596,-0.09609718,-19.34582,-985274.8,0,0,0,-0.8008099,-17754.53
9.612,-0.09633329,-19.36299,-986149.1,0,0,0,-0.8027774,-17770.28
9.626,-0.09633329,-19.38606,-987323.9,0,0,0,-0.8027774,-17791.45
9.636,-0.0965694,-19.4034,-988206.9,0,0,0,-0.804745,-17807.36
9.656,-0.09680552,-19.42425,-989269.1,0,0,0,-0.8067126,-17826.5
9.668,-0.09680552,-19.44962,-990560.8,0,0,0,-0.8067126,-17849.78
9.674,-0.09704163,-19.46505,-991346.9,0,0,0,-0.8086802,-17863.95
9.688,-0.09704163,-19.48961,-992597.8,0,0,0,-0.8086802,-17886.48
9.7,-0.09727774,-19.50752,-993509.9,0,0,0,-0.8106478,-17902.92
9.712,-0.09751385,-19.53304,-994809.7,0,0,0,-0.8126154,-17926.34
9.72,-0.09751385,-19.55391,-995872.7,0,0,0,-0.8126154,-17945.5
9.736,-0.09751385,-19.5789,-997145.2,0,0,0,-0.8126154,-17968.43
9.754,-0.09774995,-19.5909,-997756.4,0,0,0,-0.8145829,-17979.44
9.768,-0.09798607,-19.60725,-998589.1,0,0,0,-0.8165506,-17994.45
9.8,-0.09822218,-19.61995,-999235.9,0,0,0,-0.8185182,-18006.1
9.812,-0.09822218,-19.64396,-1000459,0,0,0,-0.8185182,-18028.14
9.822,-0.09822218,-19.66766,-1001666,0,0,0,-0.8185182,-18049.89
9.83,-0.09845829,-19.68256,-1002424,0,0,0,-0.8204858,-18063.56
9.85,-0.09845829,-19.70618,-1003627,0,0,0,-0.8204858,-18085.24
9.874,-0.09869441,-19.72739,-1004708,0,0,0,-0.8224534,-18104.71
9.896,-0.09893051,-19.75032,-1005876,0,0,0,-0.8244209,-18125.75
9.91,-0.09893051,-19.77385,-1007074,0,0,0,-0.8244209,-18147.35
9.922,-0.09916662,-19.79322,-1008061,0,0,0,-0.8263885,-18165.12
9.938,-0.09916662,-19.81536,-1009188,0,0,0,-0.8263885,-18185.44
9.956,-0.09940273,-19.83039,-1009953,0,0,0,-0.8283561,-18199.23
9.978,-0.09963885,-19.85404,-1011158,0,0,0,-0.8303237,-18220.93
9.992,-0.09987496,-19.86872,-1011905,0,0,0,-0.8322913,-18234.41
10.006,-0.09987496,-19.89021,-1013000,0,0,0,-0.8322913,-18254.13
10.018,-0.1001111,-19.91394,-1014209,0,0,0,-0.834259,-18275.91