File: raw-data/Sp15_245L_sec-001_group-01_bendtest-aluminum2.raw
"Test Type","Manual"
"Method Name:","C:\INSTRON\user\template\Sp15_245Lsect001_group-3_aluminum_bendtest.mtM"
"Name:","4FtPerMin"
"Operator ID:","Jaques"
"Company:","BSU"
"Lab name:",""
"Test date:","1/26/15"
"Temperature:",""
"Humidity:",""
"Note 1:",""
"Note 2:",""
"Note 3:",""
"Geometry:","Circular"
"Specimen",2
"Specimen name:",""
"Width:",6.350000,"mm"
"Thickness:",1.524000,"mm"
"Length:",12.000000,"mm"
"Diameter:",5.000000,"um"
"Inner diameter:",0.500000,"mm"
"Outer diameter:",1.000000,"mm"
"Wall thickness:",0.500000,"mm"
"Area:",19.634954,"um*um"
"Linear density:",1.000000,"den"
"Sled weight:",9.806650,"N"
"Loading span:",0.000000,"mm"
"Support span:",1.000000,"mm"
"Span ratio:","2"
"Fixture type:","3-point"
"Comment:",""
"Included"
"Time sec","Extension mm","Load N","Stress MPa","Cycle Count ","Total Cycle Count ","Repetitions Count ","Strain [Exten.] %","Tenacity gf/tex"
0,0,-4.016261,-204546.5,0,0,0,0,-3685.902
0.014,0,-4.039112,-205710.3,0,0,0,0,-3706.873
0.038,0,-4.037202,-205613,0,0,0,0,-3705.121
0.05,0,-4.009727,-204213.8,0,0,0,0,-3679.906
0.07,0,-4.010768,-204266.7,0,0,0,0,-3680.86
0.082,0,-4.033725,-205435.9,0,0,0,0,-3701.929
0.094,-0.000236111,-4.061645,-206857.9,0,0,0,-0.001967592,-3727.553
0.102,-0.000236111,-4.095955,-208605.3,0,0,0,-0.001967592,-3759.04
0.106,-0.000236111,-4.116922,-209673.1,0,0,0,-0.001967592,-3778.283
0.11,-0.000236111,-4.137996,-210746.4,0,0,0,-0.001967592,-3797.624
0.118,-0.000236111,-4.17072,-212413,0,0,0,-0.001967592,-3827.656
0.136,-0.000472222,-4.185322,-213156.7,0,0,0,-0.003935183,-3841.057
0.172,-0.0007083331,-4.206107,-214215.3,0,0,0,-0.005902776,-3860.132
0.182,-0.0007083331,-4.232724,-215570.9,0,0,0,-0.005902776,-3884.56
0.19,-0.0007083331,-4.258606,-216889,0,0,0,-0.005902776,-3908.313
0.198,-0.0007083331,-4.285499,-218258.7,0,0,0,-0.005902776,-3932.993
0.206,-0.0007083331,-4.309243,-219467.9,0,0,0,-0.005902776,-3954.784
0.216,-0.000944444,-4.324818,-220261.2,0,0,0,-0.007870367,-3969.078
0.248,-0.001180555,-4.3424,-221156.6,0,0,0,-0.009837959,-3985.215
0.27,-0.001180555,-4.364855,-222300.3,0,0,0,-0.009837959,-4005.822
0.284,-0.001416666,-4.390317,-223597,0,0,0,-0.01180555,-4029.189
0.292,-0.001416666,-4.417914,-225002.5,0,0,0,-0.01180555,-4054.517
0.3,-0.001416666,-4.445699,-226417.6,0,0,0,-0.01180555,-4080.016
0.314,-0.001416666,-4.469756,-227642.8,0,0,0,-0.01180555,-4102.094
0.332,-0.001416666,-4.491822,-228766.6,0,0,0,-0.01180555,-4122.346
0.352,-0.001652777,-4.486614,-228501.4,0,0,0,-0.01377314,-4117.565
0.36,-0.001652777,-4.463457,-227322,0,0,0,-0.01377314,-4096.313
0.37,-0.001652777,-4.440004,-226127.5,0,0,0,-0.01377314,-4074.789
0.384,-0.001652777,-4.465222,-227411.9,0,0,0,-0.01377314,-4097.933
0.392,-0.001652777,-4.491711,-228760.9,0,0,0,-0.01377314,-4122.243
0.4,-0.001652777,-4.515251,-229959.9,0,0,0,-0.01377314,-4143.847
0.412,-0.001888888,-4.540688,-231255.3,0,0,0,-0.01574073,-4167.192
0.424,-0.002124999,-4.568593,-232676.5,0,0,0,-0.01770833,-4192.801
0.436,-0.002124999,-4.593711,-233955.8,0,0,0,-0.01770833,-4215.854
0.446,-0.00236111,-4.612837,-234929.9,0,0,0,-0.01967592,-4233.407
0.456,-0.002597221,-4.632729,-235943,0,0,0,-0.02164351,-4251.662
0.466,-0.002597221,-4.659161,-237289.1,0,0,0,-0.02164351,-4275.92
0.472,-0.002833332,-4.680836,-238393,0,0,0,-0.0236111,-4295.812
0.48,-0.002833332,-4.714279,-240096.2,0,0,0,-0.0236111,-4326.503
0.486,-0.003069443,-4.739408,-241376.1,0,0,0,-0.02557869,-4349.566
0.494,-0.003069443,-4.767902,-242827.3,0,0,0,-0.02557869,-4375.716
0.502,-0.003305554,-4.792307,-244070.2,0,0,0,-0.02754628,-4398.114
0.51,-0.003305554,-4.814015,-245175.8,0,0,0,-0.02754628,-4418.036
0.518,-0.003541665,-4.833762,-246181.5,0,0,0,-0.02951388,-4436.159
0.532,-0.003777776,-4.857898,-247410.7,0,0,0,-0.03148147,-4458.31
0.548,-0.004013887,-4.880645,-248569.2,0,0,0,-0.03344906,-4479.186
0.558,-0.004013887,-4.907859,-249955.2,0,0,0,-0.03344906,-4504.162
0.564,-0.004249998,-4.925023,-250829.4,0,0,0,-0.03541665,-4519.914
0.574,-0.004249998,-4.949773,-252089.9,0,0,0,-0.03541665,-4542.627
0.59,-0.004486109,-4.974519,-253350.2,0,0,0,-0.03738425,-4565.338
0.602,-0.00472222,-4.992367,-254259.2,0,0,0,-0.03935184,-4581.718
0.61,-0.004958331,-5.011235,-255220.1,0,0,0,-0.04131943,-4599.034
0.618,-0.004958331,-5.03253,-256304.6,0,0,0,-0.04131943,-4618.577
0.626,-0.005194443,-5.054418,-257419.4,0,0,0,-0.04328702,-4638.665
0.642,-0.005430553,-5.077276,-258583.6,0,0,0,-0.04525461,-4659.643
0.658,-0.005430553,-5.099124,-259696.3,0,0,0,-0.04525461,-4679.694
0.666,-0.005666665,-5.114569,-260482.9,0,0,0,-0.0472222,-4693.868
0.676,-0.005902775,-5.134935,-261520.1,0,0,0,-0.04918979,-4712.559
0.686,-0.005902775,-5.159038,-262747.6,0,0,0,-0.04918979,-4734.679
0.692,-0.006138886,-5.174872,-263554.1,0,0,0,-0.05115739,-4749.211
0.7,-0.006138886,-5.196757,-264668.7,0,0,0,-0.05115739,-4769.295
0.708,-0.006138886,-5.220178,-265861.5,0,0,0,-0.05115739,-4790.79
0.716,-0.006374997,-5.239418,-266841.4,0,0,0,-0.05312498,-4808.447
0.726,-0.006611108,-5.258717,-267824.3,0,0,0,-0.05509257,-4826.159
0.74,-0.006611108,-5.281637,-268991.6,0,0,0,-0.05509257,-4847.194
0.754,-0.00684722,-5.297136,-269780.9,0,0,0,-0.05706016,-4861.418
0.768,-0.00708333,-5.321218,-271007.4,0,0,0,-0.05902775,-4883.519
0.78,-0.007319441,-5.344881,-272212.6,0,0,0,-0.06099534,-4905.236
0.792,-0.007319441,-5.367915,-273385.7,0,0,0,-0.06099534,-4926.375
0.802,-0.007555552,-5.389014,-274460.3,0,0,0,-0.06296293,-4945.739
0.814,-0.007555552,-5.412424,-275652.5,0,0,0,-0.06296293,-4967.222
0.824,-0.007791664,-5.434799,-276792,0,0,0,-0.06493053,-4987.757
0.834,-0.008027775,-5.452881,-277712.9,0,0,0,-0.06689812,-5004.352
0.854,-0.008263885,-5.473879,-278782.4,0,0,0,-0.06886571,-5023.623
0.872,-0.008263885,-5.496467,-279932.8,0,0,0,-0.06886571,-5044.353
0.88,-0.008499997,-5.510732,-280659.3,0,0,0,-0.0708333,-5057.444
0.892,-0.008499997,-5.537224,-282008.5,0,0,0,-0.0708333,-5081.758
0.902,-0.008736108,-5.559198,-283127.6,0,0,0,-0.0728009,-5101.923
0.916,-0.008972219,-5.580453,-284210.1,0,0,0,-0.07476849,-5121.43
0.938,-0.008972219,-5.60157,-285285.6,0,0,0,-0.07476849,-5140.81
0.948,-0.00920833,-5.616192,-286030.3,0,0,0,-0.07673608,-5154.23
0.96,-0.00944444,-5.634756,-286975.8,0,0,0,-0.07870367,-5171.267
0.974,-0.00944444,-5.65765,-288141.8,0,0,0,-0.07870367,-5192.278
0.984,-0.009680551,-5.68161,-289362,0,0,0,-0.08067126,-5214.267
0.992,-0.009680551,-5.7026,-290431.1,0,0,0,-0.08067126,-5233.531
0.998,-0.009916663,-5.71825,-291228.1,0,0,0,-0.08263886,-5247.893
1.008,-0.009916663,-5.741833,-292429.2,0,0,0,-0.08263886,-5269.536
1.02,-0.01015277,-5.755589,-293129.8,0,0,0,-0.08460645,-5282.161
1.05,-0.01038889,-5.766744,-293697.8,0,0,0,-0.08657404,-5292.398
1.066,-0.010625,-5.790443,-294904.8,0,0,0,-0.08854163,-5314.147
1.082,-0.010625,-5.813872,-296098.1,0,0,0,-0.08854163,-5335.649
1.092,-0.01086111,-5.840516,-297455.1,0,0,0,-0.09050922,-5360.102
1.102,-0.01086111,-5.865606,-298732.9,0,0,0,-0.09050922,-5383.128
1.114,-0.01109722,-5.88235,-299585.6,0,0,0,-0.09247681,-5398.495
1.136,-0.01133333,-5.898696,-300418.2,0,0,0,-0.09444441,-5413.497
1.154,-0.01133333,-5.920903,-301549.1,0,0,0,-0.09444441,-5433.877
1.17,-0.01156944,-5.935701,-302302.8,0,0,0,-0.096412,-5447.457
1.182,-0.01156944,-5.957658,-303421,0,0,0,-0.096412,-5467.608
1.194,-0.01180555,-5.977382,-304425.6,0,0,0,-0.09837959,-5485.71
1.206,-0.01180555,-6.002181,-305688.6,0,0,0,-0.09837959,-5508.469
1.216,-0.01204166,-6.024274,-306813.8,0,0,0,-0.1003472,-5528.745
1.232,-0.01227777,-6.044292,-307833.3,0,0,0,-0.1023148,-5547.116
1.258,-0.01251388,-6.063036,-308787.9,0,0,0,-0.1042824,-5564.319
1.27,-0.01251388,-6.085008,-309906.9,0,0,0,-0.1042824,-5584.483
1.282,-0.01274999,-6.104297,-310889.3,0,0,0,-0.10625,-5602.186
1.304,-0.01274999,-6.126911,-312041,0,0,0,-0.10625,-5622.939
1.314,-0.01298611,-6.141447,-312781.3,0,0,0,-0.1082175,-5636.28
1.33,-0.01322222,-6.163071,-313882.7,0,0,0,-0.1101851,-5656.125
1.352,-0.01322222,-6.185758,-315038.1,0,0,0,-0.1101851,-5676.946
1.362,-0.01345833,-6.203136,-315923.1,0,0,0,-0.1121527,-5692.895
1.376,-0.01369444,-6.218382,-316699.6,0,0,0,-0.1141203,-5706.887
1.394,-0.01369444,-6.241214,-317862.4,0,0,0,-0.1141203,-5727.84
1.406,-0.01393055,-6.269663,-319311.3,0,0,0,-0.1160879,-5753.949
1.42,-0.01393055,-6.293563,-320528.5,0,0,0,-0.1160879,-5775.883
1.444,-0.01416666,-6.307706,-321248.8,0,0,0,-0.1180555,-5788.863
1.458,-0.01440277,-6.324754,-322117.1,0,0,0,-0.1200231,-5804.509
1.484,-0.01463888,-6.346359,-323217.4,0,0,0,-0.1219907,-5824.337
1.494,-0.01463888,-6.370019,-324422.4,0,0,0,-0.1219907,-5846.05
1.5,-0.01487499,-6.388996,-325388.9,0,0,0,-0.1239583,-5863.467
1.508,-0.01487499,-6.41381,-326652.7,0,0,0,-0.1239583,-5886.24
1.518,-0.0151111,-6.433033,-327631.7,0,0,0,-0.1259259,-5903.881
1.542,-0.01534721,-6.451169,-328555.3,0,0,0,-0.1278935,-5920.525
1.56,-0.01534721,-6.473231,-329678.9,0,0,0,-0.1278935,-5940.772
1.59,-0.01558333,-6.48365,-330209.6,0,0,0,-0.1298611,-5950.335
1.598,-0.01581944,-6.501604,-331124,0,0,0,-0.1318286,-5966.812
1.61,-0.01581944,-6.524442,-332287.1,0,0,0,-0.1318286,-5987.771
1.624,-0.01605555,-6.546961,-333434,0,0,0,-0.1337962,-6008.438
1.638,-0.01629166,-6.567671,-334488.8,0,0,0,-0.1357638,-6027.444
1.658,-0.01652777,-6.585094,-335376.1,0,0,0,-0.1377314,-6043.434
1.672,-0.01652777,-6.610663,-336678.3,0,0,0,-0.1377314,-6066.9
1.68,-0.01676388,-6.628729,-337598.4,0,0,0,-0.139699,-6083.48
1.692,-0.01699999,-6.652422,-338805.1,0,0,0,-0.1416666,-6105.224
1.704,-0.01699999,-6.673057,-339856,0,0,0,-0.1416666,-6124.162
1.716,-0.0172361,-6.69363,-340903.8,0,0,0,-0.1436342,-6143.042
1.728,-0.0172361,-6.717594,-342124.3,0,0,0,-0.1436342,-6165.036
1.74,-0.01747222,-6.730937,-342803.8,0,0,0,-0.1456018,-6177.281
1.762,-0.01770833,-6.754234,-343990.3,0,0,0,-0.1475694,-6198.662
1.78,-0.01794444,-6.776532,-345126,0,0,0,-0.149537,-6219.126
1.798,-0.01794444,-6.799326,-346286.8,0,0,0,-0.149537,-6240.044
1.81,-0.01818055,-6.820879,-347384.5,0,0,0,-0.1515046,-6259.825
1.84,-0.01841666,-6.842191,-348469.9,0,0,0,-0.1534722,-6279.384
1.872,-0.01865277,-6.857129,-349230.7,0,0,0,-0.1554397,-6293.093
1.886,-0.01865277,-6.880697,-350431,0,0,0,-0.1554397,-6314.723
1.898,-0.01888888,-6.894068,-351112,0,0,0,-0.1574073,-6326.994
1.918,-0.01888888,-6.918336,-352348,0,0,0,-0.1574073,-6349.265
1.93,-0.01912499,-6.937645,-353331.4,0,0,0,-0.1593749,-6366.986
1.944,-0.0193611,-6.95822,-354379.3,0,0,0,-0.1613425,-6385.869
1.966,-0.0193611,-6.983808,-355682.4,0,0,0,-0.1613425,-6409.352
1.974,-0.01959721,-7.000461,-356530.6,0,0,0,-0.1633101,-6424.635
1.986,-0.01959721,-7.022998,-357678.3,0,0,0,-0.1633101,-6445.318
1.996,-0.01983333,-7.036353,-358358.5,0,0,0,-0.1652777,-6457.575
2.01,-0.02006944,-7.056805,-359400.1,0,0,0,-0.1672453,-6476.344
2.022,-0.02006944,-7.082267,-360696.9,0,0,0,-0.1672453,-6499.712
2.032,-0.02030555,-7.103779,-361792.5,0,0,0,-0.1692129,-6519.455
2.044,-0.02030555,-7.128747,-363064.1,0,0,0,-0.1692129,-6542.369
2.07,-0.02054166,-7.148204,-364055,0,0,0,-0.1711805,-6560.226
2.084,-0.02077777,-7.170978,-365214.9,0,0,0,-0.1731481,-6581.126
2.1,-0.02101388,-7.190624,-366215.5,0,0,0,-0.1751157,-6599.156
2.114,-0.02101388,-7.212175,-367313.1,0,0,0,-0.1751157,-6618.935
2.122,-0.02124999,-7.227767,-368107.2,0,0,0,-0.1770833,-6633.244
2.134,-0.02124999,-7.250664,-369273.3,0,0,0,-0.1770833,-6654.257
2.154,-0.0214861,-7.272169,-370368.6,0,0,0,-0.1790509,-6673.994
2.168,-0.02172221,-7.288101,-371179.9,0,0,0,-0.1810184,-6688.615
2.19,-0.02195833,-7.310191,-372305,0,0,0,-0.1829861,-6708.888
2.202,-0.02195833,-7.333388,-373486.4,0,0,0,-0.1829861,-6730.177
2.212,-0.02219444,-7.350037,-374334.3,0,0,0,-0.1849536,-6745.457
2.228,-0.02219444,-7.372938,-375500.7,0,0,0,-0.1849536,-6766.474
2.242,-0.02243054,-7.393697,-376557.9,0,0,0,-0.1869212,-6785.525
2.256,-0.02243054,-7.41581,-377684.1,0,0,0,-0.1869212,-6805.82
2.284,-0.02290277,-7.413983,-377591.1,0,0,0,-0.1908564,-6804.143
2.292,-0.02290277,-7.43734,-378780.6,0,0,0,-0.1908564,-6825.578
2.3,-0.02290277,-7.465452,-380212.3,0,0,0,-0.1908564,-6851.378
2.308,-0.02313888,-7.489424,-381433.2,0,0,0,-0.192824,-6873.378
2.322,-0.02313888,-7.516017,-382787.6,0,0,0,-0.192824,-6897.784
2.332,-0.02337499,-7.529424,-383470.4,0,0,0,-0.1947916,-6910.088
2.356,-0.0236111,-7.552056,-384623.1,0,0,0,-0.1967592,-6930.859
2.38,-0.02384721,-7.573971,-385739.2,0,0,0,-0.1987268,-6950.971
2.398,-0.02384721,-7.596779,-386900.8,0,0,0,-0.1987268,-6971.903
2.41,-0.02408332,-7.612278,-387690.2,0,0,0,-0.2006944,-6986.127
2.422,-0.02408332,-7.633522,-388772.1,0,0,0,-0.2006944,-7005.623
2.436,-0.02431944,-7.653867,-389808.3,0,0,0,-0.202662,-7024.295
2.452,-0.02455555,-7.676666,-390969.4,0,0,0,-0.2046295,-7045.218
2.468,-0.02455555,-7.697605,-392035.8,0,0,0,-0.2046295,-7064.435
2.484,-0.02479165,-7.719708,-393161.5,0,0,0,-0.2065971,-7084.72
2.498,-0.02502777,-7.741436,-394268.1,0,0,0,-0.2085647,-7104.661
2.51,-0.02502777,-7.764691,-395452.5,0,0,0,-0.2085647,-7126.003
2.522,-0.02526388,-7.784796,-396476.4,0,0,0,-0.2105323,-7144.455
2.534,-0.02526388,-7.806602,-397587,0,0,0,-0.2105323,-7164.467
2.544,-0.02549999,-7.821482,-398344.8,0,0,0,-0.2124999,-7178.123
2.568,-0.0257361,-7.83844,-399208.5,0,0,0,-0.2144675,-7193.686
2.59,-0.02597221,-7.863266,-400472.9,0,0,0,-0.2164351,-7216.47
2.6,-0.02597221,-7.886422,-401652.2,0,0,0,-0.2164351,-7237.721
2.61,-0.02597221,-7.910176,-402862,0,0,0,-0.2164351,-7259.521
2.624,-0.02620832,-7.928138,-403776.8,0,0,0,-0.2184027,-7276.005
2.636,-0.02644443,-7.943959,-404582.5,0,0,0,-0.2203703,-7290.525
2.648,-0.02644443,-7.966632,-405737.3,0,0,0,-0.2203703,-7311.333
2.68,-0.02691665,-7.969467,-405881.6,0,0,0,-0.2243055,-7313.935
2.694,-0.02691665,-7.996965,-407282.1,0,0,0,-0.2243055,-7339.171
2.706,-0.02715277,-8.022173,-408565.9,0,0,0,-0.2262731,-7362.306
2.718,-0.02715277,-8.048026,-409882.6,0,0,0,-0.2262731,-7386.032
2.73,-0.02738888,-8.070201,-411011.9,0,0,0,-0.2282407,-7406.383
2.75,-0.02738888,-8.093026,-412174.4,0,0,0,-0.2282407,-7427.331
2.764,-0.02762499,-8.109583,-413017.7,0,0,0,-0.2302082,-7442.525
2.778,-0.0278611,-8.128487,-413980.4,0,0,0,-0.2321758,-7459.875
2.796,-0.0278611,-8.153052,-415231.5,0,0,0,-0.2321758,-7482.419
2.804,-0.02809721,-8.170791,-416135,0,0,0,-0.2341434,-7498.699
2.814,-0.02809721,-8.195592,-417398.1,0,0,0,-0.2341434,-7521.46
2.824,-0.02809721,-8.217072,-418492.1,0,0,0,-0.2341434,-7541.173
2.852,-0.02856943,-8.225081,-418899.9,0,0,0,-0.2380786,-7548.523
2.876,-0.02880554,-8.245257,-419927.5,0,0,0,-0.2400462,-7567.04
2.894,-0.02880554,-8.267416,-421056,0,0,0,-0.2400462,-7587.376
2.904,-0.02904166,-8.291211,-422267.9,0,0,0,-0.2420138,-7609.214
2.912,-0.02904166,-8.313031,-423379.2,0,0,0,-0.2420138,-7629.239
2.926,-0.02927776,-8.333211,-424406.9,0,0,0,-0.2439814,-7647.759
2.954,-0.02951388,-8.357218,-425629.6,0,0,0,-0.245949,-7669.791
2.966,-0.02951388,-8.380948,-426838.2,0,0,0,-0.245949,-7691.569
2.98,-0.02974999,-8.397255,-427668.7,0,0,0,-0.2479166,-7706.536
2.992,-0.0299861,-8.414065,-428524.8,0,0,0,-0.2498841,-7721.963
3,-0.0299861,-8.436648,-429675,0,0,0,-0.2498841,-7742.688
3.008,-0.0299861,-8.462378,-430985.4,0,0,0,-0.2498841,-7766.301
3.014,-0.03022221,-8.477089,-431734.6,0,0,0,-0.2518517,-7779.803
3.036,-0.03045832,-8.491304,-432458.6,0,0,0,-0.2538193,-7792.848
3.06,-0.03069443,-8.508357,-433327.1,0,0,0,-0.2557869,-7808.499
3.082,-0.03069443,-8.529553,-434406.6,0,0,0,-0.2557869,-7827.951
3.092,-0.03093054,-8.550727,-435484.9,0,0,0,-0.2577545,-7847.383
3.102,-0.03093054,-8.575221,-436732.4,0,0,0,-0.2577545,-7869.862
3.112,-0.03116666,-8.595007,-437740.2,0,0,0,-0.2597221,-7888.021
3.13,-0.03116666,-8.617939,-438908.1,0,0,0,-0.2597221,-7909.067
3.154,-0.03140276,-8.635053,-439779.7,0,0,0,-0.2616897,-7924.773
3.168,-0.03163887,-8.647901,-440434,0,0,0,-0.2636573,-7936.564
3.18,-0.03163887,-8.67132,-441626.7,0,0,0,-0.2636573,-7958.057
3.192,-0.03187499,-8.69143,-442650.9,0,0,0,-0.2656249,-7976.513
3.208,-0.0321111,-8.711305,-443663.1,0,0,0,-0.2675925,-7994.752
3.224,-0.0321111,-8.733974,-444817.7,0,0,0,-0.2675925,-8015.557
3.25,-0.03234721,-8.753204,-445797,0,0,0,-0.2695601,-8033.206
3.264,-0.03258332,-8.770066,-446655.8,0,0,0,-0.2715277,-8048.681
3.276,-0.03258332,-8.793604,-447854.6,0,0,0,-0.2715277,-8070.282
3.286,-0.03281943,-8.812096,-448796.4,0,0,0,-0.2734953,-8087.253
3.302,-0.03305554,-8.836679,-450048.4,0,0,0,-0.2754628,-8109.814
3.318,-0.03305554,-8.857798,-451123.9,0,0,0,-0.2754628,-8129.196
3.332,-0.03329165,-8.876236,-452063,0,0,0,-0.2774304,-8146.118
3.346,-0.03352777,-8.89289,-452911.2,0,0,0,-0.2793981,-8161.402
3.366,-0.03352777,-8.914552,-454014.4,0,0,0,-0.2793981,-8181.282
3.378,-0.03376387,-8.934621,-455036.5,0,0,0,-0.2813656,-8199.7
3.39,-0.03376387,-8.958005,-456227.5,0,0,0,-0.2813656,-8221.161
3.41,-0.03399999,-8.978473,-457269.9,0,0,0,-0.2833332,-8239.945
3.424,-0.0342361,-8.995342,-458129,0,0,0,-0.2853008,-8255.427
3.436,-0.0342361,-9.016763,-459220,0,0,0,-0.2853008,-8275.086
3.448,-0.03447221,-9.031442,-459967.6,0,0,0,-0.2872684,-8288.557
3.468,-0.03447221,-9.053879,-461110.3,0,0,0,-0.2872684,-8309.148
3.48,-0.03470832,-9.073352,-462102.1,0,0,0,-0.289236,-8327.021
3.498,-0.03494443,-9.094535,-463180.9,0,0,0,-0.2912036,-8346.461
3.518,-0.03494443,-9.117177,-464334,0,0,0,-0.2912036,-8367.239
3.528,-0.03518054,-9.132587,-465118.9,0,0,0,-0.2931712,-8381.383
3.542,-0.03541665,-9.148523,-465930.5,0,0,0,-0.2951388,-8396.008
3.562,-0.03565276,-9.167539,-466898.9,0,0,0,-0.2971064,-8413.459
3.576,-0.03565276,-9.191929,-468141.1,0,0,0,-0.2971064,-8435.844
3.584,-0.03588887,-9.207082,-468912.8,0,0,0,-0.299074,-8449.75
3.6,-0.03588887,-9.232501,-470207.4,0,0,0,-0.299074,-8473.077
3.608,-0.03612498,-9.247142,-470953.1,0,0,0,-0.3010415,-8486.515
3.62,-0.03612498,-9.271446,-472190.8,0,0,0,-0.3010415,-8508.819
3.628,-0.0363611,-9.289403,-473105.4,0,0,0,-0.3030091,-8525.3
3.64,-0.0363611,-9.312681,-474290.9,0,0,0,-0.3030091,-8546.662
3.672,-0.03659721,-9.33539,-475447.5,0,0,0,-0.3049767,-8567.504
3.682,-0.03683332,-9.356027,-476498.6,0,0,0,-0.3069443,-8586.443
3.694,-0.03683332,-9.381508,-477796.3,0,0,0,-0.3069443,-8609.828
3.714,-0.03706943,-9.397808,-478626.5,0,0,0,-0.3089119,-8624.788
3.728,-0.03730554,-9.416771,-479592.2,0,0,0,-0.3108795,-8642.19
3.74,-0.03730554,-9.444701,-481014.7,0,0,0,-0.3108795,-8667.823
3.754,-0.03754165,-9.462095,-481900.5,0,0,0,-0.3128471,-8683.786
3.78,-0.03777776,-9.47704,-482661.7,0,0,0,-0.3148147,-8697.502
3.792,-0.03801387,-9.506306,-484152.2,0,0,0,-0.3167823,-8724.36
3.8,-0.03801387,-9.5283,-485272.3,0,0,0,-0.3167823,-8744.546
3.814,-0.03824999,-9.551653,-486461.7,0,0,0,-0.3187499,-8765.978
3.842,-0.0384861,-9.570789,-487436.3,0,0,0,-0.3207175,-8783.539
3.864,-0.03872221,-9.590412,-488435.7,0,0,0,-0.322685,-8801.549
3.884,-0.03872221,-9.612679,-489569.8,0,0,0,-0.322685,-8821.984
3.896,-0.03895832,-9.638383,-490878.8,0,0,0,-0.3246527,-8845.574
3.908,-0.03895832,-9.660169,-491988.3,0,0,0,-0.3246527,-8865.567
3.92,-0.03919443,-9.682725,-493137.2,0,0,0,-0.3266203,-8886.269
3.934,-0.03919443,-9.707155,-494381.3,0,0,0,-0.3266203,-8908.688
3.948,-0.03943054,-9.727203,-495402.4,0,0,0,-0.3285878,-8927.088
3.964,-0.03966665,-9.746535,-496386.9,0,0,0,-0.3305554,-8944.829
3.988,-0.03990276,-9.761604,-497154.4,0,0,0,-0.332523,-8958.66
4.008,-0.03990276,-9.785764,-498384.9,0,0,0,-0.332523,-8980.832
4.02,-0.04013887,-9.80532,-499380.8,0,0,0,-0.3344906,-8998.779
4.034,-0.04037498,-9.823414,-500302.4,0,0,0,-0.3364582,-9015.386
4.054,-0.04037498,-9.847699,-501539.2,0,0,0,-0.3364582,-9037.672
4.062,-0.04061109,-9.860787,-502205.8,0,0,0,-0.3384258,-9049.684
4.074,-0.04061109,-9.883245,-503349.6,0,0,0,-0.3384258,-9070.295
4.086,-0.0408472,-9.899372,-504170.9,0,0,0,-0.3403934,-9085.096
4.1,-0.04108332,-9.922444,-505345.9,0,0,0,-0.342361,-9106.27
4.112,-0.04108332,-9.948921,-506694.4,0,0,0,-0.342361,-9130.568
4.124,-0.04131943,-9.968547,-507693.9,0,0,0,-0.3443286,-9148.58
4.146,-0.04155554,-9.9893,-508750.9,0,0,0,-0.3462962,-9167.626
4.164,-0.04155554,-10.01476,-510047.6,0,0,0,-0.3462962,-9190.993
4.178,-0.04179165,-10.03303,-510978,0,0,0,-0.3482637,-9207.759
4.192,-0.04202776,-10.04716,-511697.9,0,0,0,-0.3502313,-9220.731
4.21,-0.04202776,-10.07273,-512999.8,0,0,0,-0.3502313,-9244.191
4.222,-0.04226387,-10.09189,-513975.9,0,0,0,-0.3521989,-9261.779
4.236,-0.04226387,-10.11294,-515047.9,0,0,0,-0.3521989,-9281.097
4.246,-0.04249998,-10.12708,-515767.9,0,0,0,-0.3541665,-9294.071
4.262,-0.04273609,-10.14944,-516906.7,0,0,0,-0.3561341,-9314.594
4.274,-0.04273609,-10.173,-518106.6,0,0,0,-0.3561341,-9336.215
4.286,-0.04297221,-10.18672,-518805.6,0,0,0,-0.3581017,-9348.812
4.302,-0.04297221,-10.20712,-519844.6,0,0,0,-0.3581017,-9367.534
4.318,-0.04320832,-10.23025,-521022.3,0,0,0,-0.3600693,-9388.755
4.346,-0.04344442,-10.24936,-521995.5,0,0,0,-0.3620369,-9406.292
4.362,-0.04368054,-10.27268,-523183.5,0,0,0,-0.3640045,-9427.7
4.374,-0.04368054,-10.29604,-524372.8,0,0,0,-0.3640045,-9449.132
4.386,-0.04391665,-10.32091,-525639.5,0,0,0,-0.3659721,-9471.957
4.4,-0.04391665,-10.34337,-526783.7,0,0,0,-0.3659721,-9492.574
4.412,-0.04415276,-10.36051,-527656.2,0,0,0,-0.3679397,-9508.298
4.426,-0.04438887,-10.3762,-528455.4,0,0,0,-0.3699073,-9522.7
4.45,-0.04462499,-10.39704,-529516.9,0,0,0,-0.3718749,-9541.827
4.464,-0.04462499,-10.42169,-530772.4,0,0,0,-0.3718749,-9564.45
4.472,-0.04486109,-10.43852,-531629.4,0,0,0,-0.3738424,-9579.894
4.484,-0.04486109,-10.46212,-532831.3,0,0,0,-0.3738424,-9601.553
4.494,-0.0450972,-10.4779,-533635.3,0,0,0,-0.37581,-9616.039
4.512,-0.0450972,-10.49903,-534711.2,0,0,0,-0.37581,-9635.428
4.524,-0.04533332,-10.51621,-535586.3,0,0,0,-0.3777776,-9651.196
4.54,-0.04556942,-10.53228,-536404.4,0,0,0,-0.3797452,-9665.939
4.556,-0.04556942,-10.55306,-537463.1,0,0,0,-0.3797452,-9685.018
4.566,-0.04580554,-10.5718,-538417.1,0,0,0,-0.3817128,-9702.208
4.582,-0.04580554,-10.59495,-539596.3,0,0,0,-0.3817128,-9723.455
4.594,-0.04604165,-10.60869,-540296.4,0,0,0,-0.3836804,-9736.072
4.606,-0.04627776,-10.62495,-541124.5,0,0,0,-0.385648,-9750.994
4.624,-0.04627776,-10.64704,-542249.5,0,0,0,-0.385648,-9771.267
4.638,-0.04651387,-10.67007,-543422.2,0,0,0,-0.3876156,-9792.398
4.65,-0.04651387,-10.69219,-544548.6,0,0,0,-0.3876156,-9812.697
4.66,-0.04674998,-10.708,-545353.8,0,0,0,-0.3895831,-9827.206
4.672,-0.04674998,-10.72929,-546438.1,0,0,0,-0.3895831,-9846.745
4.682,-0.04698609,-10.74532,-547254.6,0,0,0,-0.3915508,-9861.459
4.696,-0.0472222,-10.76251,-548130.1,0,0,0,-0.3935184,-9877.234
4.718,-0.04745831,-10.78835,-549446.1,0,0,0,-0.3954859,-9900.949
4.73,-0.04745831,-10.80935,-550515.8,0,0,0,-0.3954859,-9920.224
4.754,-0.04769443,-10.83232,-551685.5,0,0,0,-0.3974535,-9941.302
4.764,-0.04793053,-10.85102,-552637.8,0,0,0,-0.3994211,-9958.462
4.774,-0.04793053,-10.87646,-553933.4,0,0,0,-0.3994211,-9981.809
4.786,-0.04816664,-10.90347,-555309,0,0,0,-0.4013887,-10006.6
4.8,-0.04840276,-10.91752,-556024.6,0,0,0,-0.4033563,-10019.49
4.82,-0.04863887,-10.93563,-556947.3,0,0,0,-0.4053239,-10036.12
4.83,-0.04863887,-10.96174,-558276.9,0,0,0,-0.4053239,-10060.08
4.84,-0.04887498,-10.98059,-559237.1,0,0,0,-0.4072915,-10077.38
4.862,-0.04887498,-11.00167,-560310.6,0,0,0,-0.4072915,-10096.73
4.872,-0.04911109,-11.01638,-561059.6,0,0,0,-0.4092591,-10110.22
4.884,-0.04911109,-11.03954,-562239.4,0,0,0,-0.4092591,-10131.48
4.892,-0.0493472,-11.05437,-562994.6,0,0,0,-0.4112267,-10145.09
4.908,-0.04958331,-11.077,-564146.8,0,0,0,-0.4131942,-10165.85
4.924,-0.04958331,-11.10084,-565361.1,0,0,0,-0.4131942,-10187.73
4.94,-0.04981942,-11.12306,-566492.6,0,0,0,-0.4151618,-10208.12
4.954,-0.04981942,-11.14589,-567655.7,0,0,0,-0.4151618,-10229.08
4.968,-0.05005554,-11.15876,-568311,0,0,0,-0.4171295,-10240.89
4.984,-0.05029164,-11.17199,-568984.8,0,0,0,-0.419097,-10253.03
5,-0.05029164,-11.19498,-570155.6,0,0,0,-0.419097,-10274.13
5.026,-0.05052776,-11.21453,-571151.3,0,0,0,-0.4210646,-10292.07
5.044,-0.05076387,-11.23322,-572103.3,0,0,0,-0.4230323,-10309.23
5.06,-0.05099998,-11.25123,-573020.6,0,0,0,-0.4249998,-10325.76
5.074,-0.05099998,-11.27313,-574135.6,0,0,0,-0.4249998,-10345.85
5.086,-0.05123609,-11.29515,-575257.3,0,0,0,-0.4269674,-10366.06
5.098,-0.05123609,-11.32124,-576585.9,0,0,0,-0.4269674,-10390
5.108,-0.0514722,-11.33493,-577283.3,0,0,0,-0.428935,-10402.57
5.132,-0.05170831,-11.35389,-578248.7,0,0,0,-0.4309026,-10419.97
5.144,-0.05170831,-11.37655,-579402.8,0,0,0,-0.4309026,-10440.76
5.154,-0.05194442,-11.39035,-580105.9,0,0,0,-0.4328702,-10453.44
5.168,-0.05194442,-11.41483,-581352.7,0,0,0,-0.4328702,-10475.9
5.176,-0.05218054,-11.43434,-582345.9,0,0,0,-0.4348378,-10493.8
5.188,-0.05218054,-11.46056,-583681.5,0,0,0,-0.4348378,-10517.87
5.208,-0.05241664,-11.48129,-584737.2,0,0,0,-0.4368054,-10536.89
5.222,-0.05265275,-11.49786,-585581.3,0,0,0,-0.4387729,-10552.1
5.246,-0.05288887,-11.51512,-586460.4,0,0,0,-0.4407406,-10567.94
5.264,-0.05288887,-11.54013,-587733.9,0,0,0,-0.4407406,-10590.89
5.276,-0.05312498,-11.56337,-588917.7,0,0,0,-0.4427081,-10612.22
5.29,-0.05312498,-11.5847,-590003.9,0,0,0,-0.4427081,-10631.8
5.304,-0.05336109,-11.60246,-590908.4,0,0,0,-0.4446757,-10648.1
5.32,-0.0535972,-11.6217,-591888.3,0,0,0,-0.4466433,-10665.75
5.352,-0.05383331,-11.64096,-592869.1,0,0,0,-0.4486109,-10683.43
5.362,-0.05383331,-11.66611,-594150.1,0,0,0,-0.4486109,-10706.51
5.372,-0.05406942,-11.69081,-595408.3,0,0,0,-0.4505785,-10729.18
5.384,-0.05406942,-11.71461,-596620.1,0,0,0,-0.4505785,-10751.02
5.394,-0.05430553,-11.73293,-597553.3,0,0,0,-0.4525461,-10767.83
5.406,-0.05430553,-11.75428,-598640.7,0,0,0,-0.4525461,-10787.43
5.426,-0.05454164,-11.77535,-599713.5,0,0,0,-0.4545137,-10806.76
5.446,-0.05477776,-11.79708,-600820.3,0,0,0,-0.4564813,-10826.71
5.47,-0.05501387,-11.81708,-601839.1,0,0,0,-0.4584489,-10845.06
5.482,-0.05524998,-11.83765,-602886.3,0,0,0,-0.4604165,-10863.94
5.496,-0.05524998,-11.86011,-604030.6,0,0,0,-0.4604165,-10884.55
5.514,-0.05548609,-11.88033,-605060.2,0,0,0,-0.4623841,-10903.11
5.528,-0.0557222,-11.90445,-606288.8,0,0,0,-0.4643517,-10925.25
5.544,-0.0557222,-11.92546,-607358.5,0,0,0,-0.4643517,-10944.52
5.564,-0.05595831,-11.94119,-608159.6,0,0,0,-0.4663192,-10958.96
5.574,-0.05619442,-11.96,-609117.6,0,0,0,-0.4682868,-10976.22
5.586,-0.05619442,-11.98835,-610561.9,0,0,0,-0.4682868,-11002.25
5.598,-0.05643053,-12.00415,-611366.2,0,0,0,-0.4702544,-11016.74
5.614,-0.05643053,-12.02543,-612450.3,0,0,0,-0.4702544,-11036.28
5.622,-0.05666664,-12.03939,-613161,0,0,0,-0.472222,-11049.08
5.642,-0.05666664,-12.06133,-614278.3,0,0,0,-0.472222,-11069.22
5.656,-0.05690275,-12.0799,-615224.1,0,0,0,-0.4741896,-11086.26
5.668,-0.05713886,-12.10333,-616417.6,0,0,0,-0.4761572,-11107.77
5.686,-0.05713886,-12.12768,-617657.8,0,0,0,-0.4761572,-11130.12
5.702,-0.05737497,-12.14703,-618643.2,0,0,0,-0.4781248,-11147.87
5.714,-0.05761109,-12.16689,-619654.6,0,0,0,-0.4800924,-11166.1
5.734,-0.05761109,-12.18989,-620825.8,0,0,0,-0.4800924,-11187.2
5.744,-0.0578472,-12.20236,-621461.3,0,0,0,-0.48206,-11198.65
5.758,-0.0578472,-12.22668,-622699.8,0,0,0,-0.48206,-11220.97
5.77,-0.05808331,-12.24602,-623684.8,0,0,0,-0.4840276,-11238.72
5.786,-0.05831942,-12.26013,-624403.1,0,0,0,-0.4859952,-11251.67
5.802,-0.05831942,-12.2824,-625537.5,0,0,0,-0.4859952,-11272.11
5.812,-0.05855553,-12.29578,-626218.9,0,0,0,-0.4879628,-11284.38
5.834,-0.05855553,-12.31751,-627325.4,0,0,0,-0.4879628,-11304.32
5.844,-0.05879164,-12.3295,-627936.1,0,0,0,-0.4899304,-11315.33
5.854,-0.05879164,-12.35429,-629198.9,0,0,0,-0.4899304,-11338.08
5.86,-0.05902775,-12.36915,-629955.6,0,0,0,-0.4918979,-11351.72
5.872,-0.05902775,-12.39294,-631167.4,0,0,0,-0.4918979,-11373.56
5.886,-0.05926386,-12.41107,-632090.9,0,0,0,-0.4938655,-11390.2
5.91,-0.05949998,-12.43268,-633191.1,0,0,0,-0.4958331,-11410.02
5.928,-0.05949998,-12.45601,-634379.3,0,0,0,-0.4958331,-11431.43
5.942,-0.05973608,-12.47828,-635513.4,0,0,0,-0.4978007,-11451.87
5.972,-0.05997219,-12.49471,-636350.5,0,0,0,-0.4997683,-11466.95
5.988,-0.06020831,-12.51927,-637601,0,0,0,-0.5017359,-11489.49
6.002,-0.06044442,-12.53139,-638218.7,0,0,0,-0.5037035,-11500.62
6.016,-0.06044442,-12.55548,-639445.5,0,0,0,-0.5037035,-11522.73
6.026,-0.06068053,-12.57791,-640587.4,0,0,0,-0.5056711,-11543.3
6.038,-0.06068053,-12.60147,-641787.4,0,0,0,-0.5056711,-11564.93
6.05,-0.06091664,-12.61482,-642467.6,0,0,0,-0.5076387,-11577.18
6.076,-0.06115275,-12.6382,-643658.3,0,0,0,-0.5096063,-11598.64
6.09,-0.06115275,-12.6643,-644987.6,0,0,0,-0.5096063,-11622.59
6.1,-0.06138886,-12.68343,-645961.6,0,0,0,-0.5115739,-11640.14
6.116,-0.06138886,-12.70688,-647156.2,0,0,0,-0.5115739,-11661.67
6.132,-0.06162497,-12.72674,-648167.4,0,0,0,-0.5135415,-11679.9
6.144,-0.06162497,-12.74769,-649234.5,0,0,0,-0.5135415,-11699.12
6.158,-0.06186108,-12.76096,-649910.4,0,0,0,-0.515509,-11711.3
6.18,-0.0620972,-12.77802,-650779.4,0,0,0,-0.5174766,-11726.96
6.192,-0.06233331,-12.80291,-652046.9,0,0,0,-0.5194442,-11749.8
6.204,-0.06233331,-12.82792,-653320.8,0,0,0,-0.5194442,-11772.76
6.234,-0.06256942,-12.84487,-654183.6,0,0,0,-0.5214118,-11788.31
6.242,-0.06280552,-12.85918,-654912.4,0,0,0,-0.5233794,-11801.44
6.254,-0.06280552,-12.88485,-656220,0,0,0,-0.5233794,-11825
6.264,-0.06304164,-12.90517,-657254.8,0,0,0,-0.525347,-11843.65
6.276,-0.06304164,-12.93099,-658570.2,0,0,0,-0.525347,-11867.35
6.292,-0.06327775,-12.95292,-659686.8,0,0,0,-0.5273145,-11887.47
6.308,-0.06351386,-12.96567,-660336.1,0,0,0,-0.5292822,-11899.17
6.328,-0.06351386,-12.99037,-661594.1,0,0,0,-0.5292822,-11921.84
6.346,-0.06374998,-13.01389,-662791.8,0,0,0,-0.5312498,-11943.42
6.368,-0.06398609,-13.0376,-663999.7,0,0,0,-0.5332174,-11965.19
6.38,-0.06398609,-13.06598,-665445.1,0,0,0,-0.5332174,-11991.24
6.392,-0.0642222,-13.08558,-666443.1,0,0,0,-0.535185,-12009.22
6.418,-0.0644583,-13.10199,-667278.8,0,0,0,-0.5371525,-12024.28
6.428,-0.06469441,-13.11546,-667964.9,0,0,0,-0.5391201,-12036.64
6.456,-0.06493053,-13.13468,-668943.9,0,0,0,-0.5410877,-12054.29
6.464,-0.06493053,-13.1559,-670024.7,0,0,0,-0.5410877,-12073.76
6.47,-0.06516664,-13.17289,-670889.8,0,0,0,-0.5430554,-12089.35
6.48,-0.06516664,-13.19618,-672076,0,0,0,-0.5430554,-12110.72
6.492,-0.06540275,-13.21715,-673144.2,0,0,0,-0.5450229,-12129.97
6.51,-0.06540275,-13.23843,-674227.5,0,0,0,-0.5450229,-12149.49
6.524,-0.06563886,-13.25444,-675043.1,0,0,0,-0.5469905,-12164.19
6.538,-0.06587497,-13.27261,-675968.5,0,0,0,-0.5489581,-12180.87
6.55,-0.06587497,-13.29371,-677043.1,0,0,0,-0.5489581,-12200.23
6.564,-0.06587497,-13.3156,-678157.8,0,0,0,-0.5489581,-12220.32
6.576,-0.06611108,-13.33009,-678895.8,0,0,0,-0.5509257,-12233.62
6.592,-0.06611108,-13.35164,-679993.5,0,0,0,-0.5509257,-12253.4
6.628,-0.06658331,-13.36352,-680598.3,0,0,0,-0.5548609,-12264.29
6.652,-0.06658331,-13.38745,-681817.1,0,0,0,-0.5548609,-12286.26
6.66,-0.06681942,-13.40064,-682488.8,0,0,0,-0.5568284,-12298.36
6.674,-0.06681942,-13.42654,-683808.3,0,0,0,-0.5568284,-12322.14
6.688,-0.06705553,-13.4501,-685007.9,0,0,0,-0.5587961,-12343.76
6.718,-0.06729164,-13.47039,-686041.3,0,0,0,-0.5607637,-12362.38
6.734,-0.06729164,-13.49287,-687186.3,0,0,0,-0.5607637,-12383.01
6.758,-0.06752774,-13.51413,-688268.8,0,0,0,-0.5627312,-12402.52
6.772,-0.06776386,-13.52823,-688987.3,0,0,0,-0.5646988,-12415.46
6.784,-0.06776386,-13.54987,-690089.3,0,0,0,-0.5646988,-12435.32
6.818,-0.06799997,-13.57072,-691151.2,0,0,0,-0.5666664,-12454.46
6.828,-0.06823608,-13.59172,-692220.8,0,0,0,-0.568634,-12473.73
6.84,-0.06823608,-13.61798,-693558.3,0,0,0,-0.568634,-12497.83
6.852,-0.0684722,-13.6365,-694501.4,0,0,0,-0.5706016,-12514.83
6.868,-0.0687083,-13.65972,-695684.1,0,0,0,-0.5725692,-12536.14
6.882,-0.0687083,-13.68215,-696826.4,0,0,0,-0.5725692,-12556.72
6.898,-0.06894442,-13.70016,-697743.4,0,0,0,-0.5745368,-12573.25
6.912,-0.06918052,-13.72048,-698778.3,0,0,0,-0.5765043,-12591.9
6.93,-0.06918052,-13.74384,-699967.8,0,0,0,-0.5765043,-12613.33
6.942,-0.06941664,-13.7573,-700653.5,0,0,0,-0.578472,-12625.69
6.956,-0.06965275,-13.77884,-701750.6,0,0,0,-0.5804396,-12645.46
6.978,-0.06965275,-13.80177,-702918.3,0,0,0,-0.5804396,-12666.5
6.988,-0.06988886,-13.81689,-703688.4,0,0,0,-0.5824072,-12680.38
7,-0.06988886,-13.83899,-704813.8,0,0,0,-0.5824072,-12700.65
7.012,-0.07012497,-13.85987,-705877.4,0,0,0,-0.5843747,-12719.82
7.024,-0.07012497,-13.88575,-707195.7,0,0,0,-0.5843747,-12743.58
7.04,-0.07036108,-13.90426,-708138,0,0,0,-0.5863424,-12760.56
7.064,-0.0705972,-13.92445,-709166.4,0,0,0,-0.58831,-12779.09
7.078,-0.0708333,-13.94414,-710169.1,0,0,0,-0.5902776,-12797.16
7.094,-0.0708333,-13.9672,-711343.8,0,0,0,-0.5902776,-12818.32
7.114,-0.07106941,-13.98629,-712316,0,0,0,-0.5922451,-12835.84
7.124,-0.07130553,-14.00277,-713155.3,0,0,0,-0.5942127,-12850.97
7.136,-0.07130553,-14.02529,-714301.9,0,0,0,-0.5942127,-12871.63
7.15,-0.07154164,-14.03883,-714991.5,0,0,0,-0.5961803,-12884.06
7.18,-0.07177775,-14.06127,-716134.6,0,0,0,-0.5981479,-12904.65
7.194,-0.07177775,-14.08636,-717412.4,0,0,0,-0.5981479,-12927.68
7.204,-0.07201386,-14.09906,-718059.1,0,0,0,-0.6001155,-12939.33
7.218,-0.07224997,-14.12182,-719218.5,0,0,0,-0.6020831,-12960.23
7.228,-0.07224997,-14.14619,-720459.5,0,0,0,-0.6020831,-12982.59
7.24,-0.07248608,-14.16576,-721456.1,0,0,0,-0.6040506,-13000.55
7.262,-0.07272219,-14.18282,-722325.2,0,0,0,-0.6060182,-13016.21
7.276,-0.07272219,-14.20756,-723585.3,0,0,0,-0.6060182,-13038.91
7.286,-0.0729583,-14.22752,-724601.6,0,0,0,-0.6079859,-13057.23
7.3,-0.0729583,-14.25054,-725774.3,0,0,0,-0.6079859,-13078.36
7.318,-0.07319441,-14.26845,-726686.4,0,0,0,-0.6099535,-13094.8
7.33,-0.07343053,-14.28284,-727419.3,0,0,0,-0.6119211,-13108
7.344,-0.07343053,-14.30537,-728566.7,0,0,0,-0.6119211,-13128.68
7.36,-0.07366664,-14.32534,-729583.4,0,0,0,-0.6138886,-13147
7.376,-0.07390274,-14.33977,-730318.4,0,0,0,-0.6158562,-13160.25
7.396,-0.07413886,-14.36318,-731510.9,0,0,0,-0.6178238,-13181.73
7.408,-0.07413886,-14.38753,-732750.9,0,0,0,-0.6178238,-13204.08
7.418,-0.07437497,-14.4065,-733716.9,0,0,0,-0.6197914,-13221.49
7.436,-0.07437497,-14.43026,-734927,0,0,0,-0.6197914,-13243.29
7.444,-0.07461108,-14.44388,-735621,0,0,0,-0.621759,-13255.8
7.456,-0.07461108,-14.46962,-736931.8,0,0,0,-0.621759,-13279.42
7.478,-0.07484719,-14.48464,-737696.8,0,0,0,-0.6237266,-13293.2
7.49,-0.0750833,-14.49932,-738444.2,0,0,0,-0.6256942,-13306.67
7.502,-0.0750833,-14.52287,-739643.5,0,0,0,-0.6256942,-13328.28
7.51,-0.07531942,-14.53891,-740460.7,0,0,0,-0.6276618,-13343.01
7.522,-0.07531942,-14.56682,-741881.9,0,0,0,-0.6276618,-13368.62
7.536,-0.07555552,-14.58845,-742983.7,0,0,0,-0.6296294,-13388.47
7.55,-0.07579163,-14.60915,-744037.7,0,0,0,-0.6315969,-13407.46
7.566,-0.07579163,-14.63101,-745151.4,0,0,0,-0.6315969,-13427.53
7.584,-0.07602775,-14.64783,-746007.9,0,0,0,-0.6335645,-13442.97
7.61,-0.07626386,-14.66839,-747054.8,0,0,0,-0.6355321,-13461.83
7.624,-0.07649997,-14.68678,-747991.6,0,0,0,-0.6374997,-13478.71
7.634,-0.07649997,-14.71151,-749251.1,0,0,0,-0.6374997,-13501.41
7.64,-0.07673609,-14.72654,-750016.4,0,0,0,-0.6394674,-13515.2
7.652,-0.07673609,-14.75079,-751251.4,0,0,0,-0.6394674,-13537.46
7.672,-0.07697219,-14.77343,-752404.9,0,0,0,-0.6414349,-13558.24
7.7,-0.0772083,-14.79525,-753516.1,0,0,0,-0.6434025,-13578.26
7.716,-0.07744441,-14.81711,-754629.3,0,0,0,-0.6453701,-13598.32
7.728,-0.07744441,-14.83795,-755690.5,0,0,0,-0.6453701,-13617.45
7.736,-0.07768052,-14.85335,-756474.9,0,0,0,-0.6473377,-13631.58
7.752,-0.07791664,-14.87587,-757622.1,0,0,0,-0.6493053,-13652.25
7.77,-0.07791664,-14.89782,-758739.9,0,0,0,-0.6493053,-13672.4
7.794,-0.07815275,-14.91114,-759418.2,0,0,0,-0.651273,-13684.62
7.806,-0.07838886,-14.93709,-760739.8,0,0,0,-0.6532405,-13708.43
7.818,-0.07838886,-14.96173,-761994.6,0,0,0,-0.6532405,-13731.05
7.83,-0.07862496,-14.98097,-762974.4,0,0,0,-0.655208,-13748.7
7.842,-0.07862496,-15.00688,-764293.9,0,0,0,-0.655208,-13772.48
7.848,-0.07886108,-15.02251,-765090.3,0,0,0,-0.6571757,-13786.83
7.858,-0.07886108,-15.04314,-766141,0,0,0,-0.6571757,-13805.76
7.89,-0.0793333,-15.05354,-766670.4,0,0,0,-0.6611109,-13815.3
7.902,-0.0793333,-15.07535,-767781.1,0,0,0,-0.6611109,-13835.32
7.914,-0.07956942,-15.0886,-768456.1,0,0,0,-0.6630785,-13847.48
7.928,-0.07956942,-15.11241,-769668.9,0,0,0,-0.6630785,-13869.33
7.938,-0.07980552,-15.13306,-770720.3,0,0,0,-0.665046,-13888.28
7.95,-0.07980552,-15.15768,-771974.4,0,0,0,-0.665046,-13910.88
7.962,-0.08004164,-15.1784,-773029.4,0,0,0,-0.6670136,-13929.89
7.986,-0.08027774,-15.18429,-773329.4,0,0,0,-0.6689812,-13935.3
8.014,-0.08051386,-15.20346,-774306.1,0,0,0,-0.6709488,-13952.9
8.026,-0.08051386,-15.22887,-775600.1,0,0,0,-0.6709488,-13976.21
8.036,-0.08074997,-15.24902,-776626,0,0,0,-0.6729164,-13994.7
8.048,-0.08074997,-15.27382,-777889.2,0,0,0,-0.6729164,-14017.46
8.06,-0.08098608,-15.29192,-778810.9,0,0,0,-0.674884,-14034.07
8.076,-0.08098608,-15.31456,-779963.9,0,0,0,-0.674884,-14054.85
8.098,-0.08122219,-15.33163,-780833.8,0,0,0,-0.6768516,-14070.52
8.112,-0.0814583,-15.34962,-781749.5,0,0,0,-0.6788192,-14087.03
8.124,-0.0814583,-15.37249,-782914.6,0,0,0,-0.6788192,-14108.02
8.136,-0.08169441,-15.39051,-783832.1,0,0,0,-0.6807867,-14124.55
8.15,-0.08193052,-15.4096,-784804.3,0,0,0,-0.6827543,-14142.07
8.162,-0.08193052,-15.43233,-785962.3,0,0,0,-0.6827543,-14162.94
8.172,-0.08216663,-15.4498,-786852.1,0,0,0,-0.6847219,-14178.97
8.206,-0.08240275,-15.45606,-787170.9,0,0,0,-0.6866896,-14184.72
8.218,-0.08240275,-15.47853,-788314.9,0,0,0,-0.6866896,-14205.33
8.226,-0.08263885,-15.49295,-789049.4,0,0,0,-0.6886571,-14218.57
8.238,-0.08263885,-15.51419,-790131.4,0,0,0,-0.6886571,-14238.07
8.25,-0.08287497,-15.53688,-791286.7,0,0,0,-0.6906247,-14258.88
8.264,-0.08287497,-15.55834,-792379.8,0,0,0,-0.6906247,-14278.58
8.276,-0.08311108,-15.57675,-793317.4,0,0,0,-0.6925923,-14295.48
8.292,-0.08311108,-15.59827,-794413.6,0,0,0,-0.6925923,-14315.23
8.308,-0.08334719,-15.61137,-795080.5,0,0,0,-0.6945599,-14327.25
8.324,-0.0835833,-15.6324,-796151.5,0,0,0,-0.6965275,-14346.55
8.332,-0.0835833,-15.65281,-797190.9,0,0,0,-0.6965275,-14365.28
8.342,-0.08381941,-15.67747,-798447.1,0,0,0,-0.6984951,-14387.91
8.364,-0.08405552,-15.69977,-799582.6,0,0,0,-0.7004626,-14408.38
8.38,-0.08405552,-15.72388,-800810.7,0,0,0,-0.7004626,-14430.51
8.39,-0.08429163,-15.74129,-801697.4,0,0,0,-0.7024302,-14446.49
8.424,-0.08452775,-15.75653,-802473.3,0,0,0,-0.7043979,-14460.47
8.436,-0.08452775,-15.77777,-803555.4,0,0,0,-0.7043979,-14479.97
8.446,-0.08476386,-15.79233,-804296.5,0,0,0,-0.7063655,-14493.32
8.458,-0.08476386,-15.81736,-805571.4,0,0,0,-0.7063655,-14516.29
8.468,-0.08499997,-15.83978,-806713.4,0,0,0,-0.708333,-14536.87
8.482,-0.08499997,-15.86433,-807963.5,0,0,0,-0.708333,-14559.4
8.512,-0.08547218,-15.87515,-808514.8,0,0,0,-0.7122682,-14569.33
8.53,-0.08547218,-15.89706,-809630.8,0,0,0,-0.7122682,-14589.44
8.544,-0.0857083,-15.91853,-810724,0,0,0,-0.7142358,-14609.14
8.556,-0.0857083,-15.94493,-812068.8,0,0,0,-0.7142358,-14633.38
8.568,-0.08594441,-15.96864,-813276.3,0,0,0,-0.7162035,-14655.13
8.588,-0.08618053,-15.98666,-814194.1,0,0,0,-0.7181711,-14671.67
8.612,-0.08641663,-16.00905,-815334,0,0,0,-0.7201386,-14692.21
8.638,-0.08665274,-16.02464,-816128.3,0,0,0,-0.7221062,-14706.53
8.652,-0.08665274,-16.0522,-817532,0,0,0,-0.7221062,-14731.82
8.662,-0.08688885,-16.07363,-818623.4,0,0,0,-0.7240738,-14751.49
8.678,-0.08688885,-16.09916,-819923.5,0,0,0,-0.7240738,-14774.92
8.688,-0.08712496,-16.1124,-820597.8,0,0,0,-0.7260414,-14787.07
8.71,-0.08712496,-16.13427,-821711.6,0,0,0,-0.7260414,-14807.14
8.724,-0.08736108,-16.14675,-822347.3,0,0,0,-0.728009,-14818.59
8.738,-0.08759719,-16.17322,-823695.1,0,0,0,-0.7299766,-14842.88
8.752,-0.08759719,-16.19587,-824848.8,0,0,0,-0.7299766,-14863.67
8.764,-0.0878333,-16.21333,-825737.9,0,0,0,-0.7319442,-14879.69
8.776,-0.0878333,-16.23468,-826825.6,0,0,0,-0.7319442,-14899.29
8.79,-0.08806941,-16.25663,-827943.5,0,0,0,-0.7339118,-14919.44
8.826,-0.08830551,-16.2669,-828466.7,0,0,0,-0.7358793,-14928.86
8.838,-0.08830551,-16.29406,-829849.5,0,0,0,-0.7358793,-14953.78
8.848,-0.08854163,-16.31558,-830945.8,0,0,0,-0.7378469,-14973.54
8.862,-0.08854163,-16.33945,-832161.3,0,0,0,-0.7378469,-14995.44
8.876,-0.08877774,-16.35648,-833028.5,0,0,0,-0.7398145,-15011.07
8.892,-0.08901386,-16.37216,-833827.3,0,0,0,-0.7417821,-15025.46
8.906,-0.08901386,-16.39269,-834872.9,0,0,0,-0.7417821,-15044.3
8.936,-0.08924997,-16.41501,-836009.7,0,0,0,-0.7437497,-15064.79
8.948,-0.08948608,-16.43242,-836896.1,0,0,0,-0.7457173,-15080.76
8.96,-0.08948608,-16.45817,-838207.6,0,0,0,-0.7457173,-15104.39
8.976,-0.08972218,-16.47957,-839297.6,0,0,0,-0.7476848,-15124.04
8.99,-0.08995829,-16.49879,-840276.6,0,0,0,-0.7496524,-15141.68
9.002,-0.08995829,-16.52157,-841436.4,0,0,0,-0.7496524,-15162.58
9.014,-0.09019441,-16.53763,-842254.8,0,0,0,-0.7516201,-15177.32
9.038,-0.09043052,-16.55884,-843335.1,0,0,0,-0.7535877,-15196.79
9.05,-0.09043052,-16.58387,-844609.8,0,0,0,-0.7535877,-15219.76
9.058,-0.09066664,-16.59858,-845358.9,0,0,0,-0.7555553,-15233.26
9.082,-0.09090274,-16.62023,-846461.4,0,0,0,-0.7575228,-15253.13
9.094,-0.09090274,-16.6449,-847717.6,0,0,0,-0.7575228,-15275.76
9.106,-0.09113885,-16.66475,-848728.9,0,0,0,-0.7594904,-15293.99
9.128,-0.09137496,-16.6807,-849541.1,0,0,0,-0.761458,-15308.62
9.14,-0.09137496,-16.70336,-850695.3,0,0,0,-0.761458,-15329.42
9.152,-0.09161107,-16.72769,-851934.4,0,0,0,-0.7634256,-15351.75
9.164,-0.09161107,-16.75029,-853085.3,0,0,0,-0.7634256,-15372.49
9.176,-0.09184719,-16.77593,-854391.1,0,0,0,-0.7653932,-15396.02
9.188,-0.09184719,-16.79671,-855449.3,0,0,0,-0.7653932,-15415.09
9.214,-0.09208329,-16.80994,-856123.4,0,0,0,-0.7673607,-15427.24
9.232,-0.09231941,-16.83019,-857154.5,0,0,0,-0.7693284,-15445.82
9.25,-0.09255552,-16.85054,-858191.2,0,0,0,-0.771296,-15464.5
9.262,-0.09255552,-16.87503,-859438.1,0,0,0,-0.771296,-15486.96
9.274,-0.09279162,-16.89935,-860677,0,0,0,-0.7732635,-15509.29
9.296,-0.09302774,-16.9186,-861657.1,0,0,0,-0.7752311,-15526.95
9.314,-0.09302774,-16.94083,-862789.4,0,0,0,-0.7752311,-15547.36
9.336,-0.09326385,-16.96188,-863861.6,0,0,0,-0.7771988,-15566.68
9.354,-0.09349996,-16.98442,-865009.4,0,0,0,-0.7791663,-15587.36
9.362,-0.09349996,-17.00478,-866046.3,0,0,0,-0.7791663,-15606.04
9.376,-0.09373607,-17.02816,-867236.9,0,0,0,-0.7811339,-15627.5
9.392,-0.09397218,-17.04324,-868004.9,0,0,0,-0.7831016,-15641.34
9.408,-0.09397218,-17.06616,-869172.3,0,0,0,-0.7831016,-15662.37
9.426,-0.09420829,-17.08709,-870238.5,0,0,0,-0.7850691,-15681.59
9.438,-0.0944444,-17.10811,-871308.9,0,0,0,-0.7870367,-15700.88
9.45,-0.0944444,-17.1319,-872520.6,0,0,0,-0.7870367,-15722.71
9.462,-0.09468052,-17.15087,-873486.6,0,0,0,-0.7890043,-15740.12
9.478,-0.09468052,-17.17672,-874803.3,0,0,0,-0.7890043,-15763.84
9.494,-0.09491662,-17.20069,-876023.8,0,0,0,-0.7909719,-15785.84
9.51,-0.09515274,-17.21236,-876618.2,0,0,0,-0.7929395,-15796.55
9.526,-0.09515274,-17.23821,-877934.9,0,0,0,-0.7929395,-15820.27
9.54,-0.09538885,-17.2613,-879110.6,0,0,0,-0.7949071,-15841.46
9.558,-0.09562496,-17.28124,-880126.5,0,0,0,-0.7968747,-15859.77
9.572,-0.09562496,-17.30389,-881279.7,0,0,0,-0.7968747,-15880.55
9.582,-0.09586107,-17.32175,-882189.5,0,0,0,-0.7988423,-15896.94
9.598,-0.09586107,-17.34481,-883364.1,0,0,0,-0.7988423,-15918.11
9.616,-0.09609718,-17.36302,-884291.5,0,0,0,-0.8008099,-15934.82
9.64,-0.09633329,-17.38092,-885202.8,0,0,0,-0.8027774,-15951.24
9.654,-0.0965694,-17.40447,-886402.3,0,0,0,-0.804745,-15972.86
9.666,-0.0965694,-17.42626,-887511.9,0,0,0,-0.804745,-15992.85
9.676,-0.09680552,-17.44404,-888417.9,0,0,0,-0.8067126,-16009.18
9.692,-0.09680552,-17.46952,-889715.4,0,0,0,-0.8067126,-16032.56
9.7,-0.09704163,-17.48526,-890517.1,0,0,0,-0.8086802,-16047.01
9.714,-0.09704163,-17.50884,-891718,0,0,0,-0.8086802,-16068.65
9.73,-0.09727774,-17.52516,-892549.2,0,0,0,-0.8106478,-16083.62
9.742,-0.09751385,-17.54026,-893318.2,0,0,0,-0.8126154,-16097.48
9.758,-0.09751385,-17.56183,-894416.7,0,0,0,-0.8126154,-16117.28
9.772,-0.09774995,-17.58587,-895640.9,0,0,0,-0.8145829,-16139.33
9.784,-0.09774995,-17.60872,-896804.8,0,0,0,-0.8145829,-16160.31
9.796,-0.09798607,-17.62841,-897807.8,0,0,0,-0.8165506,-16178.38
9.812,-0.09822218,-17.64539,-898672.2,0,0,0,-0.8185182,-16193.96
9.832,-0.09822218,-17.66636,-899740.4,0,0,0,-0.8185182,-16213.21
9.852,-0.09845829,-17.68096,-900484.1,0,0,0,-0.8204858,-16226.61
9.866,-0.09869441,-17.69854,-901379.1,0,0,0,-0.8224534,-16242.74
9.878,-0.09869441,-17.72582,-902768.4,0,0,0,-0.8224534,-16267.77
9.888,-0.09893051,-17.74894,-903945.9,0,0,0,-0.8244209,-16288.99
9.904,-0.09916662,-17.77308,-905175.3,0,0,0,-0.8263885,-16311.14
9.926,-0.09916662,-17.79917,-906504.1,0,0,0,-0.8263885,-16335.09
9.934,-0.09940273,-17.81859,-907493.2,0,0,0,-0.8283561,-16352.91
9.952,-0.09963885,-17.84186,-908678.3,0,0,0,-0.8303237,-16374.27
9.974,-0.09963885,-17.86724,-909971.1,0,0,0,-0.8303237,-16397.56
9.984,-0.09987496,-17.88937,-911098.1,0,0,0,-0.8322913,-16417.87
9.998,-0.09987496,-17.91415,-912360.4,0,0,0,-0.8322913,-16440.62
10.004,-0.1001111,-17.91885,-912599.5,0,0,0,-0.834259,-16444.93