File: raw-data/Sp15_245L_sec-001_group-01_bendtest-tungsten3.raw
"Test Type","Manual"
"Method Name:","C:\INSTRON\user\template\245L-Mod01.mtM"
"Name:","4FtPerMin"
"Operator ID:","Jaques"
"Company:","BSU"
"Lab name:",""
"Test date:","1/26/15"
"Temperature:",""
"Humidity:",""
"Note 1:",""
"Note 2:",""
"Note 3:",""
"Geometry:","Circular"
"Specimen",3
"Specimen name:",""
"Width:",6.350000,"mm"
"Thickness:",1.524000,"mm"
"Length:",12.000000,"mm"
"Diameter:",5.000000,"um"
"Inner diameter:",0.500000,"mm"
"Outer diameter:",1.000000,"mm"
"Wall thickness:",0.500000,"mm"
"Area:",19.634954,"um*um"
"Linear density:",1.000000,"den"
"Sled weight:",9.806650,"N"
"Loading span:",0.000000,"mm"
"Support span:",1.000000,"mm"
"Span ratio:","2"
"Fixture type:","3-point"
"Comment:",""
"Included"
"Time sec","Extension mm","Load N","Stress MPa","Cycle Count ","Total Cycle Count ","Repetitions Count ","Strain [Exten.] %","Tenacity gf/tex"
0,0,-4.965317,-252881.5,0,0,0,0,-4556.893
0.006,0,-4.979633,-253610.6,0,0,0,0,-4570.031
0.01,0,-4.992541,-254268,0,0,0,0,-4581.877
0.014,0,-5.007477,-255028.7,0,0,0,0,-4595.585
0.018,0,-5.024315,-255886.3,0,0,0,0,-4611.038
0.022,0,-5.042806,-256828,0,0,0,0,-4628.008
0.026,0,-5.061555,-257782.9,0,0,0,0,-4645.215
0.03,0,-5.079649,-258704.4,0,0,0,0,-4661.82
0.034,0,-5.093854,-259427.9,0,0,0,0,-4674.857
0.052,0,-5.076984,-258568.7,0,0,0,0,-4659.375
0.056,0,-5.058025,-257603.1,0,0,0,0,-4641.975
0.058,0,-5.047471,-257065.6,0,0,0,0,-4632.289
0.06,0,-5.036524,-256508.1,0,0,0,0,-4622.243
0.062,0,-5.025493,-255946.2,0,0,0,0,-4612.119
0.064,0,-5.014709,-255397,0,0,0,0,-4602.222
0.066,0,-5.004569,-254880.6,0,0,0,0,-4592.917
0.07,0,-4.987599,-254016.3,0,0,0,0,-4577.342
0.074,0,-4.975278,-253388.8,0,0,0,0,-4566.034
0.08,0,-4.962629,-252744.6,0,0,0,0,-4554.426
0.09,0,-4.951861,-252196.2,0,0,0,0,-4544.543
0.108,0,-4.965908,-252911.6,0,0,0,0,-4557.435
0.112,0,-4.981194,-253690.1,0,0,0,0,-4571.463
0.116,0,-5.002089,-254754.3,0,0,0,0,-4590.641
0.118,0,-5.013986,-255360.2,0,0,0,0,-4601.558
0.12,0,-5.026184,-255981.5,0,0,0,0,-4612.753
0.122,0,-5.03837,-256602.1,0,0,0,0,-4623.937
0.124,0,-5.050465,-257218.1,0,0,0,0,-4635.037
0.126,0,-5.062334,-257822.6,0,0,0,0,-4645.93
0.128,0,-5.073515,-258392,0,0,0,0,-4656.191
0.132,0,-5.091375,-259301.6,0,0,0,0,-4672.582
0.136,0,-5.10197,-259841.2,0,0,0,0,-4682.305
0.15,0,-5.086396,-259048,0,0,0,0,-4668.013
0.154,0,-5.072155,-258322.7,0,0,0,0,-4654.943
0.158,0,-5.057612,-257582.1,0,0,0,0,-4641.596
0.162,0,-5.045773,-256979.1,0,0,0,0,-4630.731
0.168,0,-5.034552,-256407.6,0,0,0,0,-4620.433
0.176,-0.000472222,-5.027652,-256056.2,0,0,0,-0.003935183,-4614.1
0.19,-0.000472222,-5.016868,-255507,0,0,0,-0.003935183,-4604.204
0.208,-0.000472222,-5.029963,-256173.9,0,0,0,-0.003935183,-4616.222
0.212,-0.000472222,-5.047413,-257062.6,0,0,0,-0.003935183,-4632.236
0.214,-0.000472222,-5.057874,-257595.4,0,0,0,-0.003935183,-4641.836
0.216,-0.000472222,-5.069119,-258168.1,0,0,0,-0.003935183,-4652.156
0.218,-0.000472222,-5.080961,-258771.2,0,0,0,-0.003935183,-4663.024
0.22,-0.000472222,-5.093113,-259390.1,0,0,0,-0.003935183,-4674.177
0.222,-0.000472222,-5.105106,-260000.9,0,0,0,-0.003935183,-4685.183
0.224,-0.000472222,-5.116499,-260581.1,0,0,0,-0.003935183,-4695.639
0.226,-0.000472222,-5.127037,-261117.9,0,0,0,-0.003935183,-4705.311
0.23,-0.000472222,-5.144406,-262002.4,0,0,0,-0.003935183,-4721.25
0.234,-0.000472222,-5.155201,-262552.3,0,0,0,-0.003935183,-4731.158
0.242,-0.0007083331,-5.157178,-262652.9,0,0,0,-0.005902776,-4732.972
0.248,-0.0007083331,-5.144031,-261983.4,0,0,0,-0.005902776,-4720.907
0.252,-0.0007083331,-5.132941,-261418.5,0,0,0,-0.005902776,-4710.729
0.256,-0.0007083331,-5.121523,-260837,0,0,0,-0.005902776,-4700.25
0.26,-0.0007083331,-5.110015,-260250.9,0,0,0,-0.005902776,-4689.688
0.264,-0.0007083331,-5.099289,-259704.6,0,0,0,-0.005902776,-4679.845
0.27,-0.0007083331,-5.086461,-259051.3,0,0,0,-0.005902776,-4668.072
0.278,-0.0007083331,-5.074586,-258446.6,0,0,0,-0.005902776,-4657.174
0.286,-0.000944444,-5.068542,-258138.7,0,0,0,-0.007870367,-4651.627
0.296,-0.000944444,-5.078633,-258652.7,0,0,0,-0.007870367,-4660.888
0.3,-0.000944444,-5.089583,-259210.4,0,0,0,-0.007870367,-4670.938
0.304,-0.000944444,-5.10408,-259948.7,0,0,0,-0.007870367,-4684.242
0.308,-0.000944444,-5.121528,-260837.3,0,0,0,-0.007870367,-4700.254
0.312,-0.000944444,-5.140502,-261803.6,0,0,0,-0.007870367,-4717.668
0.316,-0.000944444,-5.160225,-262808.1,0,0,0,-0.007870367,-4735.768
0.32,-0.000944444,-5.179133,-263771.1,0,0,0,-0.007870367,-4753.121
0.324,-0.001180555,-5.195699,-264614.8,0,0,0,-0.009837959,-4768.325
0.328,-0.001180555,-5.20921,-265302.9,0,0,0,-0.009837959,-4780.724
0.332,-0.001180555,-5.21938,-265820.9,0,0,0,-0.009837959,-4790.058
0.354,-0.001180555,-5.209115,-265298.1,0,0,0,-0.009837959,-4780.637
0.358,-0.001180555,-5.195368,-264597.9,0,0,0,-0.009837959,-4768.021
0.362,-0.001180555,-5.178965,-263762.5,0,0,0,-0.009837959,-4752.967
0.366,-0.001180555,-5.161392,-262867.5,0,0,0,-0.009837959,-4736.84
0.37,-0.001180555,-5.144187,-261991.3,0,0,0,-0.009837959,-4721.05
0.374,-0.001180555,-5.129262,-261231.2,0,0,0,-0.009837959,-4707.353
0.378,-0.001180555,-5.118339,-260674.9,0,0,0,-0.009837959,-4697.328
0.394,-0.001180555,-5.133996,-261472.3,0,0,0,-0.009837959,-4711.697
0.398,-0.001180555,-5.149247,-262249,0,0,0,-0.009837959,-4725.693
0.402,-0.001180555,-5.165827,-263093.4,0,0,0,-0.009837959,-4740.91
0.406,-0.001180555,-5.182891,-263962.5,0,0,0,-0.009837959,-4756.57
0.41,-0.001180555,-5.198419,-264753.3,0,0,0,-0.009837959,-4770.821
0.414,-0.001180555,-5.211496,-265419.3,0,0,0,-0.009837959,-4782.822
0.416,-0.001416666,-5.217397,-265719.8,0,0,0,-0.01180555,-4788.238
0.42,-0.001416666,-5.228351,-266277.8,0,0,0,-0.01180555,-4798.291
0.424,-0.001416666,-5.23853,-266796.2,0,0,0,-0.01180555,-4807.633
0.428,-0.001652777,-5.247992,-267278.1,0,0,0,-0.01377314,-4816.317
0.434,-0.001652777,-5.261208,-267951.1,0,0,0,-0.01377314,-4828.445
0.438,-0.001888888,-5.2696,-268378.5,0,0,0,-0.01574073,-4836.147
0.444,-0.001888888,-5.279881,-268902.1,0,0,0,-0.01574073,-4845.582
0.448,-0.002124999,-5.28661,-269244.8,0,0,0,-0.01770833,-4851.757
0.454,-0.002124999,-5.297992,-269824.5,0,0,0,-0.01770833,-4862.204
0.456,-0.00236111,-5.302515,-270054.9,0,0,0,-0.01967592,-4866.355
0.46,-0.00236111,-5.313194,-270598.8,0,0,0,-0.01967592,-4876.155
0.464,-0.002597221,-5.326191,-271260.7,0,0,0,-0.02164351,-4888.083
0.468,-0.002597221,-5.339997,-271963.8,0,0,0,-0.02164351,-4900.754
0.47,-0.002833332,-5.347067,-272323.9,0,0,0,-0.0236111,-4907.242
0.474,-0.002833332,-5.362351,-273102.3,0,0,0,-0.0236111,-4921.269
0.478,-0.003069443,-5.378503,-273924.9,0,0,0,-0.02557869,-4936.092
0.482,-0.003069443,-5.394869,-274758.4,0,0,0,-0.02557869,-4951.112
0.484,-0.003305554,-5.403316,-275188.6,0,0,0,-0.02754628,-4958.864
0.488,-0.003305554,-5.420458,-276061.7,0,0,0,-0.02754628,-4974.596
0.49,-0.003541665,-5.428841,-276488.6,0,0,0,-0.02951388,-4982.29
0.494,-0.003541665,-5.445202,-277321.9,0,0,0,-0.02951388,-4997.305
0.498,-0.003777776,-5.461322,-278142.8,0,0,0,-0.03148147,-5012.099
0.502,-0.003777776,-5.4763,-278905.7,0,0,0,-0.03148147,-5025.844
0.504,-0.004013887,-5.48339,-279266.8,0,0,0,-0.03344906,-5032.352
0.508,-0.004013887,-5.496976,-279958.7,0,0,0,-0.03344906,-5044.82
0.512,-0.004249998,-5.508509,-280546.1,0,0,0,-0.03541665,-5055.404
0.518,-0.004249998,-5.521699,-281217.8,0,0,0,-0.03541665,-5067.51
0.52,-0.004486109,-5.52536,-281404.3,0,0,0,-0.03738425,-5070.869
0.528,-0.00472222,-5.537011,-281997.7,0,0,0,-0.03935184,-5081.562
0.538,-0.004958331,-5.54482,-282395.4,0,0,0,-0.04131943,-5088.729
0.546,-0.004958331,-5.555584,-282943.6,0,0,0,-0.04131943,-5098.607
0.548,-0.005194443,-5.557781,-283055.5,0,0,0,-0.04328702,-5100.624
0.56,-0.005430553,-5.564718,-283408.8,0,0,0,-0.04525461,-5106.989
0.57,-0.005666665,-5.576276,-283997.4,0,0,0,-0.0472222,-5117.597
0.578,-0.005666665,-5.586375,-284511.8,0,0,0,-0.0472222,-5126.866
0.582,-0.005902775,-5.593352,-284867.1,0,0,0,-0.04918979,-5133.269
0.588,-0.005902775,-5.604583,-285439.1,0,0,0,-0.04918979,-5143.576
0.596,-0.005902775,-5.615554,-285997.8,0,0,0,-0.04918979,-5153.645
0.598,-0.006138886,-5.617621,-286103.1,0,0,0,-0.05115739,-5155.542
0.61,-0.006138886,-5.628607,-286662.6,0,0,0,-0.05115739,-5165.624
0.616,-0.006374997,-5.635532,-287015.3,0,0,0,-0.05312498,-5171.979
0.64,-0.006611108,-5.632591,-286865.5,0,0,0,-0.05509257,-5169.28
0.648,-0.006611108,-5.622212,-286336.9,0,0,0,-0.05509257,-5159.755
0.67,-0.006611108,-5.633052,-286889,0,0,0,-0.05509257,-5169.704
0.672,-0.00684722,-5.636846,-287082.2,0,0,0,-0.05706016,-5173.185
0.678,-0.00684722,-5.648616,-287681.7,0,0,0,-0.05706016,-5183.987
0.686,-0.00684722,-5.65974,-288248.2,0,0,0,-0.05706016,-5194.196
0.7,-0.00684722,-5.67004,-288772.8,0,0,0,-0.05706016,-5203.649
0.706,-0.00708333,-5.668061,-288672,0,0,0,-0.05902775,-5201.833
0.726,-0.00708333,-5.657903,-288154.7,0,0,0,-0.05902775,-5192.51
0.736,-0.007319441,-5.654769,-287995.1,0,0,0,-0.06099534,-5189.634
0.766,-0.007555552,-5.654389,-287975.7,0,0,0,-0.06296293,-5189.285
0.778,-0.007555552,-5.666333,-288584,0,0,0,-0.06296293,-5200.247
0.788,-0.007555552,-5.678171,-289186.9,0,0,0,-0.06296293,-5211.111
0.794,-0.007791664,-5.683823,-289474.7,0,0,0,-0.06493053,-5216.297
0.82,-0.007791664,-5.694312,-290008.9,0,0,0,-0.06493053,-5225.924
0.822,-0.008027775,-5.695134,-290050.8,0,0,0,-0.06689812,-5226.679
0.838,-0.008027775,-5.705734,-290590.7,0,0,0,-0.06689812,-5236.407
0.846,-0.008263885,-5.709338,-290774.2,0,0,0,-0.06886571,-5239.714
0.856,-0.008263885,-5.72018,-291326.4,0,0,0,-0.06886571,-5249.665
0.868,-0.008499997,-5.72588,-291616.7,0,0,0,-0.0708333,-5254.896
0.892,-0.008736108,-5.736359,-292150.4,0,0,0,-0.0728009,-5264.513
0.904,-0.008736108,-5.746654,-292674.7,0,0,0,-0.0728009,-5273.961
0.914,-0.008972219,-5.755854,-293143.3,0,0,0,-0.07476849,-5282.404
0.936,-0.00920833,-5.752524,-292973.7,0,0,0,-0.07673608,-5279.348
0.956,-0.00944444,-5.753891,-293043.3,0,0,0,-0.07870367,-5280.603
0.962,-0.00944444,-5.7639,-293553,0,0,0,-0.07870367,-5289.789
0.968,-0.00944444,-5.775912,-294164.8,0,0,0,-0.07870367,-5300.812
0.978,-0.009680551,-5.781897,-294469.6,0,0,0,-0.08067126,-5306.305
1,-0.009916663,-5.783009,-294526.3,0,0,0,-0.08263886,-5307.326
1.01,-0.009916663,-5.793038,-295037,0,0,0,-0.08263886,-5316.53
1.024,-0.01015277,-5.800911,-295438,0,0,0,-0.08460645,-5323.755
1.044,-0.01038889,-5.805045,-295648.5,0,0,0,-0.08657404,-5327.549
1.056,-0.01038889,-5.816517,-296232.8,0,0,0,-0.08657404,-5338.077
1.066,-0.010625,-5.819038,-296361.2,0,0,0,-0.08854163,-5340.391
1.088,-0.01086111,-5.819124,-296365.5,0,0,0,-0.09050922,-5340.469
1.098,-0.01086111,-5.830439,-296941.8,0,0,0,-0.09050922,-5350.854
1.106,-0.01086111,-5.842026,-297532,0,0,0,-0.09050922,-5361.488
1.112,-0.01109722,-5.850052,-297940.7,0,0,0,-0.09247681,-5368.854
1.122,-0.01109722,-5.860176,-298456.3,0,0,0,-0.09247681,-5378.145
1.134,-0.01133333,-5.864307,-298666.7,0,0,0,-0.09444441,-5381.936
1.156,-0.01156944,-5.85639,-298263.5,0,0,0,-0.096412,-5374.67
1.18,-0.01180555,-5.852209,-298050.6,0,0,0,-0.09837959,-5370.833
1.194,-0.01180555,-5.864037,-298652.9,0,0,0,-0.09837959,-5381.688
1.204,-0.01204166,-5.876195,-299272.2,0,0,0,-0.1003472,-5392.846
1.214,-0.01204166,-5.886951,-299819.9,0,0,0,-0.1003472,-5402.717
1.224,-0.01227777,-5.89364,-300160.6,0,0,0,-0.1023148,-5408.856
1.246,-0.01251388,-5.894332,-300195.8,0,0,0,-0.1042824,-5409.491
1.268,-0.01274999,-5.893648,-300161,0,0,0,-0.10625,-5408.863
1.29,-0.01298611,-5.899264,-300447.1,0,0,0,-0.1082175,-5414.018
1.3,-0.01298611,-5.9115,-301070.2,0,0,0,-0.1082175,-5425.247
1.308,-0.01322222,-5.922509,-301630.9,0,0,0,-0.1101851,-5435.351
1.32,-0.01322222,-5.933329,-302182,0,0,0,-0.1101851,-5445.281
1.33,-0.01345833,-5.932913,-302160.8,0,0,0,-0.1121527,-5444.898
1.35,-0.01369444,-5.930874,-302057,0,0,0,-0.1141203,-5443.028
1.372,-0.01393055,-5.921631,-301586.2,0,0,0,-0.1160879,-5434.545
1.394,-0.01416666,-5.928773,-301950,0,0,0,-0.1180555,-5441.1
1.404,-0.01416666,-5.94132,-302588.9,0,0,0,-0.1180555,-5452.614
1.41,-0.01416666,-5.953023,-303185,0,0,0,-0.1180555,-5463.354
1.414,-0.01440277,-5.960716,-303576.8,0,0,0,-0.1200231,-5470.415
1.42,-0.01440277,-5.970966,-304098.8,0,0,0,-0.1200231,-5479.821
1.428,-0.01440277,-5.981763,-304648.7,0,0,0,-0.1200231,-5489.731
1.434,-0.01463888,-5.986135,-304871.3,0,0,0,-0.1219907,-5493.743
1.456,-0.01487499,-5.977056,-304409,0,0,0,-0.1239583,-5485.411
1.48,-0.0151111,-5.971924,-304147.6,0,0,0,-0.1259259,-5480.701
1.49,-0.0151111,-5.98268,-304695.4,0,0,0,-0.1259259,-5490.572
1.5,-0.0151111,-5.994637,-305304.4,0,0,0,-0.1259259,-5501.546
1.504,-0.01534721,-5.999124,-305532.9,0,0,0,-0.1278935,-5505.663
1.512,-0.01534721,-6.010308,-306102.5,0,0,0,-0.1278935,-5515.928
1.52,-0.01534721,-6.020951,-306644.5,0,0,0,-0.1278935,-5525.695
1.53,-0.01558333,-6.029451,-307077.4,0,0,0,-0.1298611,-5533.496
1.556,-0.01581944,-6.02195,-306695.4,0,0,0,-0.1318286,-5526.612
1.58,-0.01605555,-6.032347,-307224.9,0,0,0,-0.1337962,-5536.154
1.604,-0.01629166,-6.038958,-307561.6,0,0,0,-0.1357638,-5542.221
1.614,-0.01629166,-6.050245,-308136.4,0,0,0,-0.1357638,-5552.58
1.622,-0.01629166,-6.060766,-308672.3,0,0,0,-0.1357638,-5562.235
1.63,-0.01652777,-6.066967,-308988.1,0,0,0,-0.1377314,-5567.926
1.654,-0.01676388,-6.069413,-309112.7,0,0,0,-0.139699,-5570.171
1.68,-0.01699999,-6.069246,-309104.2,0,0,0,-0.1416666,-5570.018
1.688,-0.01699999,-6.059175,-308591.3,0,0,0,-0.1416666,-5560.775
1.706,-0.0172361,-6.070139,-309149.7,0,0,0,-0.1436342,-5570.837
1.712,-0.0172361,-6.082999,-309804.6,0,0,0,-0.1436342,-5582.639
1.718,-0.0172361,-6.09601,-310467.3,0,0,0,-0.1436342,-5594.58
1.726,-0.0172361,-6.106104,-310981.3,0,0,0,-0.1436342,-5603.844
1.73,-0.01747222,-6.108462,-311101.4,0,0,0,-0.1456018,-5606.008
1.756,-0.01770833,-6.117048,-311538.7,0,0,0,-0.1475694,-5613.888
1.768,-0.01770833,-6.10674,-311013.7,0,0,0,-0.1475694,-5604.427
1.774,-0.01770833,-6.095376,-310435,0,0,0,-0.1475694,-5593.999
1.782,-0.01794444,-6.085429,-309928.3,0,0,0,-0.149537,-5584.87
1.796,-0.01794444,-6.095573,-310445,0,0,0,-0.149537,-5594.179
1.802,-0.01794444,-6.107339,-311044.2,0,0,0,-0.149537,-5604.977
1.81,-0.01818055,-6.118144,-311594.5,0,0,0,-0.1515046,-5614.894
1.818,-0.01818055,-6.128732,-312133.8,0,0,0,-0.1515046,-5624.611
1.826,-0.01818055,-6.139753,-312695.1,0,0,0,-0.1515046,-5634.725
1.836,-0.01841666,-6.151571,-313297,0,0,0,-0.1534722,-5645.571
1.862,-0.01865277,-6.151012,-313268.5,0,0,0,-0.1554397,-5645.058
1.89,-0.01888888,-6.158052,-313627,0,0,0,-0.1574073,-5651.519
1.908,-0.01888888,-6.147926,-313111.3,0,0,0,-0.1574073,-5642.226
1.914,-0.01888888,-6.137639,-312587.4,0,0,0,-0.1574073,-5632.785
1.918,-0.01912499,-6.135604,-312483.8,0,0,0,-0.1593749,-5630.917
1.926,-0.01912499,-6.146394,-313033.3,0,0,0,-0.1593749,-5640.82
1.932,-0.01912499,-6.161314,-313793.1,0,0,0,-0.1593749,-5654.512
1.938,-0.01912499,-6.17392,-314435.2,0,0,0,-0.1593749,-5666.082
1.944,-0.0193611,-6.179626,-314725.8,0,0,0,-0.1613425,-5671.318
1.972,-0.01959721,-6.185174,-315008.3,0,0,0,-0.1633101,-5676.41
1.99,-0.01959721,-6.195637,-315541.2,0,0,0,-0.1633101,-5686.012
1.996,-0.01983333,-6.197304,-315626.1,0,0,0,-0.1652777,-5687.542
2.008,-0.01983333,-6.208547,-316198.7,0,0,0,-0.1652777,-5697.861
2.016,-0.01983333,-6.219464,-316754.7,0,0,0,-0.1652777,-5707.879
2.022,-0.02006944,-6.226632,-317119.8,0,0,0,-0.1672453,-5714.458
2.048,-0.02030555,-6.231992,-317392.8,0,0,0,-0.1692129,-5719.377
2.062,-0.02030555,-6.244138,-318011.4,0,0,0,-0.1692129,-5730.524
2.07,-0.02054166,-6.250672,-318344.1,0,0,0,-0.1711805,-5736.52
2.092,-0.02054166,-6.239682,-317784.4,0,0,0,-0.1711805,-5726.435
2.094,-0.02077777,-6.238485,-317723.4,0,0,0,-0.1731481,-5725.335
2.112,-0.02077777,-6.250027,-318311.3,0,0,0,-0.1731481,-5735.928
2.116,-0.02101388,-6.255195,-318574.4,0,0,0,-0.1751157,-5740.671
2.13,-0.02101388,-6.265697,-319109.3,0,0,0,-0.1751157,-5750.31
2.138,-0.02124999,-6.265698,-319109.4,0,0,0,-0.1770833,-5750.311
2.156,-0.02124999,-6.277127,-319691.4,0,0,0,-0.1770833,-5760.799
2.162,-0.0214861,-6.281118,-319894.7,0,0,0,-0.1790509,-5764.462
2.182,-0.02172221,-6.273752,-319519.6,0,0,0,-0.1810184,-5757.702
2.198,-0.02172221,-6.28529,-320107.2,0,0,0,-0.1810184,-5768.291
2.204,-0.02172221,-6.298339,-320771.8,0,0,0,-0.1810184,-5780.266
2.206,-0.02195833,-6.302664,-320992.1,0,0,0,-0.1829861,-5784.236
2.212,-0.02195833,-6.313992,-321569,0,0,0,-0.1829861,-5794.632
2.222,-0.02195833,-6.325522,-322156.2,0,0,0,-0.1829861,-5805.214
2.23,-0.02219444,-6.329303,-322348.8,0,0,0,-0.1849536,-5808.684
2.256,-0.02243054,-6.336567,-322718.7,0,0,0,-0.1869212,-5815.35
2.28,-0.02266666,-6.331504,-322460.8,0,0,0,-0.1888888,-5810.704
2.306,-0.02290277,-6.334757,-322626.5,0,0,0,-0.1908564,-5813.689
2.328,-0.02290277,-6.346117,-323205.1,0,0,0,-0.1908564,-5824.114
2.33,-0.02313888,-6.347645,-323282.9,0,0,0,-0.192824,-5825.517
2.344,-0.02313888,-6.357765,-323798.3,0,0,0,-0.192824,-5834.805
2.354,-0.02337499,-6.36264,-324046.6,0,0,0,-0.1947916,-5839.279
2.37,-0.02337499,-6.37317,-324582.9,0,0,0,-0.1947916,-5848.942
2.376,-0.0236111,-6.376571,-324756.1,0,0,0,-0.1967592,-5852.064
2.398,-0.02384721,-6.378876,-324873.5,0,0,0,-0.1987268,-5854.179
2.42,-0.02408332,-6.373948,-324622.5,0,0,0,-0.2006944,-5849.657
2.428,-0.02408332,-6.38433,-325151.3,0,0,0,-0.2006944,-5859.184
2.434,-0.02408332,-6.394417,-325665,0,0,0,-0.2006944,-5868.441
2.442,-0.02431944,-6.406606,-326285.8,0,0,0,-0.202662,-5879.628
2.452,-0.02431944,-6.41786,-326858.9,0,0,0,-0.202662,-5889.956
2.464,-0.02455555,-6.429547,-327454.2,0,0,0,-0.2046295,-5900.682
2.486,-0.02479165,-6.435716,-327768.3,0,0,0,-0.2065971,-5906.343
2.51,-0.02502777,-6.436485,-327807.5,0,0,0,-0.2085647,-5907.05
2.536,-0.02526388,-6.447515,-328369.3,0,0,0,-0.2105323,-5917.172
2.544,-0.02526388,-6.458253,-328916.1,0,0,0,-0.2105323,-5927.026
2.552,-0.02526388,-6.46858,-329442.1,0,0,0,-0.2105323,-5936.504
2.56,-0.02549999,-6.476184,-329829.3,0,0,0,-0.2124999,-5943.483
2.584,-0.0257361,-6.467417,-329382.9,0,0,0,-0.2144675,-5935.438
2.61,-0.02597221,-6.466556,-329339,0,0,0,-0.2164351,-5934.647
2.622,-0.02597221,-6.477841,-329913.7,0,0,0,-0.2164351,-5945.003
2.634,-0.02597221,-6.487933,-330427.7,0,0,0,-0.2164351,-5954.266
2.636,-0.02620832,-6.48925,-330494.8,0,0,0,-0.2184027,-5955.474
2.658,-0.02644443,-6.499438,-331013.7,0,0,0,-0.2203703,-5964.824
2.672,-0.02644443,-6.509655,-331534,0,0,0,-0.2203703,-5974.201
2.682,-0.02668055,-6.517779,-331947.8,0,0,0,-0.2223379,-5981.656
2.704,-0.02691665,-6.524369,-332283.4,0,0,0,-0.2243055,-5987.705
2.722,-0.02691665,-6.535666,-332858.7,0,0,0,-0.2243055,-5998.072
2.728,-0.02715277,-6.543458,-333255.6,0,0,0,-0.2262731,-6005.223
2.736,-0.02715277,-6.554182,-333801.8,0,0,0,-0.2262731,-6015.065
2.75,-0.02738888,-6.558779,-334035.9,0,0,0,-0.2282407,-6019.284
2.774,-0.02762499,-6.553052,-333744.2,0,0,0,-0.2302082,-6014.028
2.786,-0.02762499,-6.564389,-334321.6,0,0,0,-0.2302082,-6024.433
2.796,-0.0278611,-6.568335,-334522.6,0,0,0,-0.2321758,-6028.054
2.82,-0.02809721,-6.579541,-335093.3,0,0,0,-0.2341434,-6038.338
2.83,-0.02809721,-6.590304,-335641.5,0,0,0,-0.2341434,-6048.216
2.842,-0.02833332,-6.599941,-336132.2,0,0,0,-0.236111,-6057.06
2.868,-0.02856943,-6.607519,-336518.2,0,0,0,-0.2380786,-6064.014
2.89,-0.02880554,-6.61045,-336667.5,0,0,0,-0.2400462,-6066.705
2.912,-0.02880554,-6.62119,-337214.5,0,0,0,-0.2400462,-6076.562
2.916,-0.02904166,-6.626856,-337503,0,0,0,-0.2420138,-6081.761
2.928,-0.02904166,-6.637692,-338054.9,0,0,0,-0.2420138,-6091.706
2.938,-0.02927776,-6.637997,-338070.4,0,0,0,-0.2439814,-6091.986
2.962,-0.02951388,-6.641452,-338246.4,0,0,0,-0.245949,-6095.156
2.974,-0.02951388,-6.65237,-338802.4,0,0,0,-0.245949,-6105.177
2.986,-0.02974999,-6.657877,-339082.9,0,0,0,-0.2479166,-6110.23
3.012,-0.0299861,-6.665744,-339483.6,0,0,0,-0.2498841,-6117.45
3.032,-0.03022221,-6.673803,-339894,0,0,0,-0.2518517,-6124.846
3.042,-0.03022221,-6.683893,-340407.8,0,0,0,-0.2518517,-6134.106
3.056,-0.03045832,-6.68845,-340639.9,0,0,0,-0.2538193,-6138.289
3.08,-0.03069443,-6.699439,-341199.6,0,0,0,-0.2557869,-6148.374
3.098,-0.03069443,-6.710441,-341759.9,0,0,0,-0.2557869,-6158.471
3.102,-0.03093054,-6.712502,-341864.9,0,0,0,-0.2577545,-6160.363
3.124,-0.03093054,-6.723017,-342400.5,0,0,0,-0.2577545,-6170.013
3.126,-0.03116666,-6.724556,-342478.8,0,0,0,-0.2597221,-6171.425
3.138,-0.03116666,-6.734896,-343005.4,0,0,0,-0.2597221,-6180.914
3.15,-0.03140276,-6.736063,-343064.9,0,0,0,-0.2616897,-6181.986
3.174,-0.03163887,-6.732008,-342858.3,0,0,0,-0.2636573,-6178.264
3.184,-0.03163887,-6.742718,-343403.8,0,0,0,-0.2636573,-6188.093
3.194,-0.03163887,-6.7533,-343942.8,0,0,0,-0.2636573,-6197.804
3.196,-0.03187499,-6.754545,-344006.2,0,0,0,-0.2656249,-6198.947
3.22,-0.0321111,-6.757607,-344162.1,0,0,0,-0.2675925,-6201.757
3.234,-0.0321111,-6.767877,-344685.2,0,0,0,-0.2675925,-6211.183
3.242,-0.03234721,-6.770079,-344797.3,0,0,0,-0.2695601,-6213.203
3.264,-0.03234721,-6.780489,-345327.5,0,0,0,-0.2695601,-6222.757
3.266,-0.03258332,-6.782662,-345438.1,0,0,0,-0.2715277,-6224.751
3.278,-0.03258332,-6.79297,-345963.1,0,0,0,-0.2715277,-6234.211
3.29,-0.03281943,-6.802954,-346471.6,0,0,0,-0.2734953,-6243.375
3.312,-0.03305554,-6.811171,-346890.1,0,0,0,-0.2754628,-6250.916
3.33,-0.03305554,-6.80079,-346361.4,0,0,0,-0.2754628,-6241.388
3.338,-0.03329165,-6.80043,-346343.1,0,0,0,-0.2774304,-6241.058
3.348,-0.03329165,-6.811504,-346907.1,0,0,0,-0.2774304,-6251.221
3.356,-0.03329165,-6.823258,-347505.7,0,0,0,-0.2774304,-6262.009
3.36,-0.03352777,-6.827336,-347713.4,0,0,0,-0.2793981,-6265.75
3.384,-0.03376387,-6.835565,-348132.5,0,0,0,-0.2813656,-6273.303
3.408,-0.03399999,-6.834597,-348083.2,0,0,0,-0.2833332,-6272.415
3.416,-0.03399999,-6.844955,-348610.7,0,0,0,-0.2833332,-6281.92
3.424,-0.03399999,-6.856675,-349207.6,0,0,0,-0.2833332,-6292.677
3.43,-0.0342361,-6.860612,-349408.1,0,0,0,-0.2853008,-6296.29
3.454,-0.03447221,-6.860156,-349384.9,0,0,0,-0.2872684,-6295.871
3.464,-0.03447221,-6.872322,-350004.5,0,0,0,-0.2872684,-6307.036
3.474,-0.03447221,-6.882601,-350528,0,0,0,-0.2872684,-6316.47
3.476,-0.03470832,-6.882583,-350527.1,0,0,0,-0.289236,-6316.453
3.5,-0.03494443,-6.88058,-350425.1,0,0,0,-0.2912036,-6314.616
3.508,-0.03494443,-6.892432,-351028.7,0,0,0,-0.2912036,-6325.493
3.524,-0.03518054,-6.901539,-351492.5,0,0,0,-0.2931712,-6333.85
3.546,-0.03541665,-6.913037,-352078.1,0,0,0,-0.2951388,-6344.402
3.558,-0.03541665,-6.924659,-352670,0,0,0,-0.2951388,-6355.068
3.57,-0.03565276,-6.928294,-352855.1,0,0,0,-0.2971064,-6358.404
3.594,-0.03588887,-6.924672,-352670.6,0,0,0,-0.299074,-6355.08
3.618,-0.03612498,-6.933521,-353121.3,0,0,0,-0.3010415,-6363.201
3.63,-0.03612498,-6.944134,-353661.8,0,0,0,-0.3010415,-6372.941
3.642,-0.0363611,-6.955392,-354235.2,0,0,0,-0.3030091,-6383.273
3.654,-0.0363611,-6.96601,-354776,0,0,0,-0.3030091,-6393.018
3.666,-0.03659721,-6.967387,-354846.1,0,0,0,-0.3049767,-6394.282
3.688,-0.03683332,-6.961975,-354570.5,0,0,0,-0.3069443,-6389.315
3.702,-0.03683332,-6.973171,-355140.7,0,0,0,-0.3069443,-6399.59
3.712,-0.03706943,-6.984049,-355694.7,0,0,0,-0.3089119,-6409.573
3.73,-0.03706943,-6.99578,-356292.2,0,0,0,-0.3089119,-6420.34
3.734,-0.03730554,-7.000166,-356515.5,0,0,0,-0.3108795,-6424.364
3.744,-0.03730554,-7.012247,-357130.8,0,0,0,-0.3108795,-6435.452
3.758,-0.03754165,-7.019785,-357514.7,0,0,0,-0.3128471,-6442.37
3.782,-0.03777776,-7.012374,-357137.3,0,0,0,-0.3148147,-6435.568
3.798,-0.03777776,-7.022498,-357652.9,0,0,0,-0.3148147,-6444.859
3.806,-0.03801387,-7.024728,-357766.5,0,0,0,-0.3167823,-6446.906
3.824,-0.03801387,-7.036282,-358354.9,0,0,0,-0.3167823,-6457.509
3.83,-0.03824999,-7.04444,-358770.4,0,0,0,-0.3187499,-6464.997
3.856,-0.0384861,-7.048163,-358960,0,0,0,-0.3207175,-6468.413
3.88,-0.03872221,-7.056728,-359396.3,0,0,0,-0.322685,-6476.274
3.9,-0.03872221,-7.066933,-359915.9,0,0,0,-0.322685,-6485.64
3.906,-0.03895832,-7.069682,-360056,0,0,0,-0.3246527,-6488.163
3.918,-0.03895832,-7.080541,-360609,0,0,0,-0.3246527,-6498.128
3.93,-0.03919443,-7.087706,-360973.9,0,0,0,-0.3266203,-6504.704
3.944,-0.03919443,-7.076347,-360395.4,0,0,0,-0.3266203,-6494.279
3.952,-0.03943054,-7.068362,-359988.7,0,0,0,-0.3285878,-6486.951
3.968,-0.03943054,-7.081949,-360680.7,0,0,0,-0.3285878,-6499.42
3.974,-0.03943054,-7.09359,-361273.6,0,0,0,-0.3285878,-6510.104
3.976,-0.03966665,-7.097606,-361478.1,0,0,0,-0.3305554,-6513.79
3.982,-0.03966665,-7.108873,-362051.9,0,0,0,-0.3305554,-6524.129
3.99,-0.03966665,-7.119332,-362584.6,0,0,0,-0.3305554,-6533.729
3.998,-0.03990276,-7.12401,-362822.9,0,0,0,-0.332523,-6538.022
4.018,-0.03990276,-7.13465,-363364.8,0,0,0,-0.332523,-6547.786
4.022,-0.04013887,-7.136024,-363434.7,0,0,0,-0.3344906,-6549.047
4.046,-0.04037498,-7.127819,-363016.8,0,0,0,-0.3364582,-6541.517
4.062,-0.04037498,-7.139005,-363586.5,0,0,0,-0.3364582,-6551.783
4.068,-0.04061109,-7.145268,-363905.5,0,0,0,-0.3384258,-6557.531
4.09,-0.0408472,-7.154977,-364400,0,0,0,-0.3403934,-6566.441
4.102,-0.0408472,-7.165356,-364928.6,0,0,0,-0.3403934,-6575.966
4.114,-0.04108332,-7.165762,-364949.3,0,0,0,-0.342361,-6576.339
4.14,-0.04131943,-7.162005,-364757.9,0,0,0,-0.3443286,-6572.891
4.156,-0.04131943,-7.173347,-365335.6,0,0,0,-0.3443286,-6583.3
4.162,-0.04155554,-7.179474,-365647.6,0,0,0,-0.3462962,-6588.923
4.17,-0.04155554,-7.190718,-366220.3,0,0,0,-0.3462962,-6599.243
4.178,-0.04155554,-7.201208,-366754.5,0,0,0,-0.3462962,-6608.87
4.186,-0.04179165,-7.211566,-367282,0,0,0,-0.3482637,-6618.375
4.194,-0.04179165,-7.221591,-367792.6,0,0,0,-0.3482637,-6627.576
4.208,-0.04202776,-7.222184,-367822.8,0,0,0,-0.3502313,-6628.12
4.218,-0.04202776,-7.20983,-367193.6,0,0,0,-0.3502313,-6616.782
4.226,-0.04202776,-7.199379,-366661.3,0,0,0,-0.3502313,-6607.191
4.234,-0.04226387,-7.202499,-366820.3,0,0,0,-0.3521989,-6610.055
4.244,-0.04226387,-7.21344,-367377.5,0,0,0,-0.3521989,-6620.096
4.252,-0.04226387,-7.225567,-367995.1,0,0,0,-0.3521989,-6631.225
4.258,-0.04249998,-7.232297,-368337.9,0,0,0,-0.3541665,-6637.402
4.27,-0.04249998,-7.242902,-368878,0,0,0,-0.3541665,-6647.134
4.28,-0.04273609,-7.255164,-369502.5,0,0,0,-0.3561341,-6658.388
4.296,-0.04273609,-7.26523,-370015.1,0,0,0,-0.3561341,-6667.625
4.304,-0.04297221,-7.262657,-369884.1,0,0,0,-0.3581017,-6665.265
4.326,-0.04320832,-7.256456,-369568.3,0,0,0,-0.3600693,-6659.573
4.35,-0.04344442,-7.26037,-369767.6,0,0,0,-0.3620369,-6663.165
4.366,-0.04344442,-7.270652,-370291.3,0,0,0,-0.3620369,-6672.602
4.376,-0.04368054,-7.282955,-370917.8,0,0,0,-0.3640045,-6683.892
4.384,-0.04368054,-7.295288,-371546,0,0,0,-0.3640045,-6695.211
4.394,-0.04368054,-7.306172,-372100.3,0,0,0,-0.3640045,-6705.2
4.398,-0.04391665,-7.308062,-372196.6,0,0,0,-0.3659721,-6706.935
4.422,-0.04415276,-7.298955,-371732.8,0,0,0,-0.3679397,-6698.577
4.444,-0.04438887,-7.300209,-371796.6,0,0,0,-0.3699073,-6699.727
4.458,-0.04438887,-7.311725,-372383.1,0,0,0,-0.3699073,-6710.296
4.468,-0.04462499,-7.320412,-372825.5,0,0,0,-0.3718749,-6718.268
4.478,-0.04462499,-7.330738,-373351.4,0,0,0,-0.3718749,-6727.745
4.488,-0.04486109,-7.339978,-373822,0,0,0,-0.3738424,-6736.225
4.5,-0.04486109,-7.35,-374332.4,0,0,0,-0.3738424,-6745.423
4.514,-0.0450972,-7.344099,-374031.9,0,0,0,-0.37581,-6740.007
4.526,-0.0450972,-7.332923,-373462.7,0,0,0,-0.37581,-6729.75
4.538,-0.04533332,-7.327041,-373163.1,0,0,0,-0.3777776,-6724.352
4.548,-0.04533332,-7.338836,-373763.8,0,0,0,-0.3777776,-6735.177
4.556,-0.04533332,-7.351649,-374416.4,0,0,0,-0.3777776,-6746.936
4.562,-0.04556942,-7.361396,-374912.8,0,0,0,-0.3797452,-6755.881
4.576,-0.04556942,-7.3725,-375478.3,0,0,0,-0.3797452,-6766.072
4.588,-0.04580554,-7.380488,-375885.2,0,0,0,-0.3817128,-6773.403
4.612,-0.04604165,-7.390081,-376373.8,0,0,0,-0.3836804,-6782.207
4.634,-0.04627776,-7.399971,-376877.4,0,0,0,-0.385648,-6791.284
4.658,-0.04651387,-7.398688,-376812.1,0,0,0,-0.3876156,-6790.106
4.668,-0.04651387,-7.411424,-377460.7,0,0,0,-0.3876156,-6801.794
4.674,-0.04651387,-7.421746,-377986.4,0,0,0,-0.3876156,-6811.267
4.68,-0.04674998,-7.430252,-378419.6,0,0,0,-0.3895831,-6819.073
4.704,-0.04698609,-7.437815,-378804.8,0,0,0,-0.3915508,-6826.015
4.73,-0.0472222,-7.440031,-378917.7,0,0,0,-0.3935184,-6828.048
4.752,-0.04745831,-7.44729,-379287.4,0,0,0,-0.3954859,-6834.71
4.762,-0.04745831,-7.459109,-379889.3,0,0,0,-0.3954859,-6845.557
4.776,-0.04769443,-7.467162,-380299.5,0,0,0,-0.3974535,-6852.948
4.8,-0.04793053,-7.461871,-380030,0,0,0,-0.3994211,-6848.092
4.816,-0.04793053,-7.473345,-380614.4,0,0,0,-0.3994211,-6858.622
4.822,-0.04816664,-7.47769,-380835.7,0,0,0,-0.4013887,-6862.61
4.848,-0.04840276,-7.487795,-381350.3,0,0,0,-0.4033563,-6871.884
4.86,-0.04840276,-7.499511,-381947,0,0,0,-0.4033563,-6882.636
4.87,-0.04863887,-7.506227,-382289,0,0,0,-0.4053239,-6888.799
4.892,-0.04887498,-7.515208,-382746.4,0,0,0,-0.4072915,-6897.042
4.902,-0.04887498,-7.525897,-383290.8,0,0,0,-0.4072915,-6906.852
4.914,-0.04911109,-7.534324,-383720,0,0,0,-0.4092591,-6914.585
4.938,-0.0493472,-7.545071,-384267.3,0,0,0,-0.4112267,-6924.448
4.958,-0.0493472,-7.555439,-384795.4,0,0,0,-0.4112267,-6933.963
4.96,-0.04958331,-7.556017,-384824.8,0,0,0,-0.4131942,-6934.494
4.984,-0.04981942,-7.559003,-384976.9,0,0,0,-0.4151618,-6937.234
5.006,-0.05005554,-7.567813,-385425.6,0,0,0,-0.4171295,-6945.32
5.03,-0.05029164,-7.578438,-385966.7,0,0,0,-0.419097,-6955.071
5.044,-0.05029164,-7.589796,-386545.1,0,0,0,-0.419097,-6965.494
5.052,-0.05052776,-7.597067,-386915.5,0,0,0,-0.4210646,-6972.167
5.068,-0.05052776,-7.608889,-387517.5,0,0,0,-0.4210646,-6983.017
5.076,-0.05076387,-7.614572,-387807,0,0,0,-0.4230323,-6988.232
5.094,-0.05076387,-7.601563,-387144.4,0,0,0,-0.4230323,-6976.293
5.1,-0.05099998,-7.590144,-386562.9,0,0,0,-0.4249998,-6965.814
5.12,-0.05099998,-7.60057,-387093.8,0,0,0,-0.4249998,-6975.382
5.126,-0.05123609,-7.613115,-387732.8,0,0,0,-0.4269674,-6986.896
5.134,-0.05123609,-7.624122,-388293.4,0,0,0,-0.4269674,-6996.997
5.15,-0.0514722,-7.622179,-388194.4,0,0,0,-0.428935,-6995.214
5.164,-0.0514722,-7.634733,-388833.8,0,0,0,-0.428935,-7006.735
5.172,-0.0514722,-7.645388,-389376.4,0,0,0,-0.428935,-7016.514
5.178,-0.05170831,-7.649285,-389574.9,0,0,0,-0.4309026,-7020.09
5.19,-0.05170831,-7.638238,-389012.3,0,0,0,-0.4309026,-7009.952
5.198,-0.05170831,-7.626258,-388402.1,0,0,0,-0.4309026,-6998.957
5.204,-0.05194442,-7.622368,-388204,0,0,0,-0.4328702,-6995.387
5.218,-0.05194442,-7.634846,-388839.5,0,0,0,-0.4328702,-7006.839
5.226,-0.05194442,-7.646092,-389412.3,0,0,0,-0.4328702,-7017.159
5.23,-0.05218054,-7.649006,-389560.7,0,0,0,-0.4348378,-7019.834
5.252,-0.05218054,-7.660032,-390122.2,0,0,0,-0.4348378,-7029.953
5.256,-0.05241664,-7.662316,-390238.6,0,0,0,-0.4368054,-7032.049
5.28,-0.05265275,-7.667072,-390480.8,0,0,0,-0.4387729,-7036.414
5.302,-0.05288887,-7.673124,-390789,0,0,0,-0.4407406,-7041.968
5.312,-0.05288887,-7.68572,-391430.5,0,0,0,-0.4407406,-7053.528
5.32,-0.05288887,-7.696921,-392000.9,0,0,0,-0.4407406,-7063.807
5.324,-0.05312498,-7.701603,-392239.4,0,0,0,-0.4427081,-7068.104
5.336,-0.05312498,-7.713016,-392820.7,0,0,0,-0.4427081,-7078.579
5.344,-0.05336109,-7.720734,-393213.8,0,0,0,-0.4446757,-7085.662
5.364,-0.0535972,-7.723842,-393372,0,0,0,-0.4466433,-7088.514
5.382,-0.05383331,-7.723243,-393341.5,0,0,0,-0.4486109,-7087.964
5.404,-0.05406942,-7.733421,-393859.9,0,0,0,-0.4505785,-7097.305
5.42,-0.05406942,-7.74437,-394417.5,0,0,0,-0.4505785,-7107.354
5.426,-0.05430553,-7.749699,-394688.9,0,0,0,-0.4525461,-7112.244
5.448,-0.05454164,-7.759786,-395202.7,0,0,0,-0.4545137,-7121.501
5.47,-0.05477776,-7.763327,-395383,0,0,0,-0.4564813,-7124.751
5.494,-0.05501387,-7.773665,-395909.5,0,0,0,-0.4584489,-7134.239
5.51,-0.05501387,-7.785033,-396488.5,0,0,0,-0.4584489,-7144.672
5.518,-0.05524998,-7.791318,-396808.6,0,0,0,-0.4604165,-7150.44
5.534,-0.05524998,-7.802262,-397365.9,0,0,0,-0.4604165,-7160.484
5.542,-0.05548609,-7.802623,-397384.3,0,0,0,-0.4623841,-7160.815
5.562,-0.0557222,-7.801064,-397304.9,0,0,0,-0.4643517,-7159.385
5.586,-0.05595831,-7.810358,-397778.3,0,0,0,-0.4663192,-7167.914
5.61,-0.05619442,-7.817347,-398134.2,0,0,0,-0.4682868,-7174.328
5.62,-0.05619442,-7.827825,-398667.8,0,0,0,-0.4682868,-7183.944
5.636,-0.05643053,-7.835632,-399065.5,0,0,0,-0.4702544,-7191.109
5.658,-0.05666664,-7.840647,-399320.9,0,0,0,-0.472222,-7195.712
5.67,-0.05666664,-7.830091,-398783.3,0,0,0,-0.472222,-7186.023
5.678,-0.05666664,-7.819271,-398232.2,0,0,0,-0.472222,-7176.093
5.684,-0.05690275,-7.815639,-398047.3,0,0,0,-0.4741896,-7172.761
5.696,-0.05690275,-7.826796,-398615.4,0,0,0,-0.4741896,-7183
5.704,-0.05690275,-7.840036,-399289.8,0,0,0,-0.4741896,-7195.151
5.708,-0.05713886,-7.846555,-399621.8,0,0,0,-0.4761572,-7201.133
5.718,-0.05713886,-7.857847,-400196.9,0,0,0,-0.4761572,-7211.497
5.732,-0.05737497,-7.867379,-400682.3,0,0,0,-0.4781248,-7220.245
5.742,-0.05737497,-7.877506,-401198.1,0,0,0,-0.4781248,-7229.539
5.754,-0.05761109,-7.884316,-401544.9,0,0,0,-0.4800924,-7235.789
5.778,-0.0578472,-7.883308,-401493.6,0,0,0,-0.48206,-7234.864
5.792,-0.0578472,-7.895126,-402095.5,0,0,0,-0.48206,-7245.709
5.804,-0.05808331,-7.902599,-402476.1,0,0,0,-0.4840276,-7252.567
5.826,-0.05808331,-7.912689,-402989.9,0,0,0,-0.4840276,-7261.828
5.828,-0.05831942,-7.914384,-403076.3,0,0,0,-0.4859952,-7263.383
5.852,-0.05855553,-7.920338,-403379.5,0,0,0,-0.4879628,-7268.847
5.862,-0.05855553,-7.909724,-402838.9,0,0,0,-0.4879628,-7259.106
5.876,-0.05879164,-7.903951,-402544.9,0,0,0,-0.4899304,-7253.809
5.9,-0.05902775,-7.915094,-403112.5,0,0,0,-0.4918979,-7264.035
5.91,-0.05902775,-7.92726,-403732.1,0,0,0,-0.4918979,-7275.2
5.918,-0.05902775,-7.940199,-404391,0,0,0,-0.4918979,-7287.075
5.924,-0.05902775,-7.951947,-404989.3,0,0,0,-0.4918979,-7297.856
5.926,-0.05926386,-7.955475,-405169,0,0,0,-0.4938655,-7301.094
5.934,-0.05926386,-7.96568,-405688.8,0,0,0,-0.4938655,-7310.46
5.948,-0.05949998,-7.969135,-405864.8,0,0,0,-0.4958331,-7313.631
5.972,-0.05973608,-7.975345,-406181,0,0,0,-0.4978007,-7319.33
5.996,-0.05997219,-7.986952,-406772.1,0,0,0,-0.4997683,-7329.981
6.01,-0.05997219,-7.998416,-407356,0,0,0,-0.4997683,-7340.503
6.018,-0.06020831,-8.005726,-407728.3,0,0,0,-0.5017359,-7347.212
6.042,-0.06044442,-8.008371,-407863,0,0,0,-0.5037035,-7349.639
6.064,-0.06068053,-8.008599,-407874.6,0,0,0,-0.5056711,-7349.849
6.088,-0.06091664,-8.010866,-407990.1,0,0,0,-0.5076387,-7351.929
6.104,-0.06091664,-8.021671,-408540.4,0,0,0,-0.5076387,-7361.846
6.112,-0.06115275,-8.027879,-408856.5,0,0,0,-0.5096063,-7367.542
6.136,-0.06138886,-8.033785,-409157.3,0,0,0,-0.5115739,-7372.963
6.15,-0.06138886,-8.044983,-409727.6,0,0,0,-0.5115739,-7383.24
6.16,-0.06162497,-8.056261,-410302,0,0,0,-0.5135415,-7393.59
6.184,-0.06186108,-8.058585,-410420.4,0,0,0,-0.515509,-7395.723
6.208,-0.0620972,-8.069439,-410973.2,0,0,0,-0.5174766,-7405.684
6.218,-0.0620972,-8.080481,-411535.5,0,0,0,-0.5174766,-7415.817
6.23,-0.06233331,-8.077697,-411393.7,0,0,0,-0.5194442,-7413.263
6.24,-0.06233331,-8.067478,-410873.3,0,0,0,-0.5194442,-7403.885
6.254,-0.06256942,-8.065307,-410762.7,0,0,0,-0.5214118,-7401.892
6.266,-0.06256942,-8.075827,-411298.5,0,0,0,-0.5214118,-7411.546
6.276,-0.06256942,-8.0872,-411877.7,0,0,0,-0.5214118,-7421.984
6.278,-0.06280552,-8.089543,-411997.1,0,0,0,-0.5233794,-7424.135
6.286,-0.06280552,-8.100744,-412567.5,0,0,0,-0.5233794,-7434.414
6.298,-0.06280552,-8.111429,-413111.7,0,0,0,-0.5233794,-7444.221
6.302,-0.06304164,-8.113654,-413225,0,0,0,-0.525347,-7446.262
6.32,-0.06304164,-8.124123,-413758.2,0,0,0,-0.525347,-7455.87
6.326,-0.06327775,-8.124615,-413783.3,0,0,0,-0.5273145,-7456.322
6.346,-0.06327775,-8.114292,-413257.5,0,0,0,-0.5273145,-7446.848
6.352,-0.06351386,-8.114343,-413260.1,0,0,0,-0.5292822,-7446.894
6.364,-0.06351386,-8.125841,-413845.7,0,0,0,-0.5292822,-7457.446
6.376,-0.06351386,-8.136512,-414389.2,0,0,0,-0.5292822,-7467.24
6.378,-0.06374998,-8.137639,-414446.5,0,0,0,-0.5312498,-7468.274
6.404,-0.06398609,-8.138394,-414485,0,0,0,-0.5332174,-7468.967
6.426,-0.0642222,-8.148786,-415014.3,0,0,0,-0.535185,-7478.504
6.444,-0.0642222,-8.158844,-415526.5,0,0,0,-0.535185,-7487.735
6.452,-0.0644583,-8.160634,-415617.7,0,0,0,-0.5371525,-7489.378
6.468,-0.0644583,-8.170685,-416129.6,0,0,0,-0.5371525,-7498.602
6.474,-0.06469441,-8.174649,-416331.5,0,0,0,-0.5391201,-7502.24
6.498,-0.06493053,-8.17912,-416559.2,0,0,0,-0.5410877,-7506.343
6.52,-0.06516664,-8.18125,-416667.6,0,0,0,-0.5430554,-7508.298
6.542,-0.06540275,-8.19075,-417151.5,0,0,0,-0.5450229,-7517.017
6.562,-0.06540275,-8.20136,-417691.8,0,0,0,-0.5450229,-7526.753
6.566,-0.06563886,-8.203818,-417817.1,0,0,0,-0.5469905,-7529.01
6.59,-0.06587497,-8.209131,-418087.6,0,0,0,-0.5489581,-7533.885
6.614,-0.06611108,-8.211027,-418184.2,0,0,0,-0.5509257,-7535.625
6.622,-0.06611108,-8.223951,-418842.4,0,0,0,-0.5509257,-7547.486
6.636,-0.06611108,-8.234444,-419376.8,0,0,0,-0.5509257,-7557.117
6.638,-0.06634719,-8.234998,-419405,0,0,0,-0.5528933,-7557.625
6.66,-0.06658331,-8.245683,-419949.2,0,0,0,-0.5548609,-7567.431
6.67,-0.06658331,-8.256818,-420516.3,0,0,0,-0.5548609,-7577.65
6.684,-0.06681942,-8.265634,-420965.3,0,0,0,-0.5568284,-7585.741
6.706,-0.06705553,-8.266315,-421000,0,0,0,-0.5587961,-7586.366
6.73,-0.06729164,-8.273807,-421381.6,0,0,0,-0.5607637,-7593.242
6.748,-0.06729164,-8.285686,-421986.6,0,0,0,-0.5607637,-7604.144
6.754,-0.06752774,-8.291246,-422269.7,0,0,0,-0.5627312,-7609.247
6.778,-0.06776386,-8.296435,-422534,0,0,0,-0.5646988,-7614.008
6.8,-0.06799997,-8.29538,-422480.2,0,0,0,-0.5666664,-7613.04
6.826,-0.06823608,-8.302893,-422862.9,0,0,0,-0.568634,-7619.936
6.834,-0.06823608,-8.315786,-423519.5,0,0,0,-0.568634,-7631.768
6.84,-0.06823608,-8.325883,-424033.8,0,0,0,-0.568634,-7641.034
6.848,-0.0684722,-8.334048,-424449.6,0,0,0,-0.5706016,-7648.527
6.87,-0.0687083,-8.339764,-424740.7,0,0,0,-0.5725692,-7653.773
6.892,-0.06894442,-8.349837,-425253.7,0,0,0,-0.5745368,-7663.018
6.914,-0.06918052,-8.350887,-425307.2,0,0,0,-0.5765043,-7663.981
6.93,-0.06918052,-8.361502,-425847.8,0,0,0,-0.5765043,-7673.723
6.938,-0.06941664,-8.365553,-426054.1,0,0,0,-0.578472,-7677.441
6.96,-0.06965275,-8.376379,-426605.5,0,0,0,-0.5804396,-7687.376
6.976,-0.06965275,-8.386661,-427129.2,0,0,0,-0.5804396,-7696.813
6.982,-0.06988886,-8.390513,-427325.3,0,0,0,-0.5824072,-7700.348
7.006,-0.07012497,-8.396096,-427609.7,0,0,0,-0.5843747,-7705.471
7.028,-0.07036108,-8.403602,-427991.9,0,0,0,-0.5863424,-7712.36
7.052,-0.0705972,-8.410329,-428334.5,0,0,0,-0.58831,-7718.534
7.062,-0.0705972,-8.421104,-428883.3,0,0,0,-0.58831,-7728.423
7.072,-0.0705972,-8.432856,-429481.8,0,0,0,-0.58831,-7739.208
7.074,-0.0708333,-8.435051,-429593.6,0,0,0,-0.5902776,-7741.222
7.086,-0.0708333,-8.445911,-430146.7,0,0,0,-0.5902776,-7751.189
7.1,-0.07106941,-8.441096,-429901.5,0,0,0,-0.5922451,-7746.771
7.124,-0.07130553,-8.44982,-430345.8,0,0,0,-0.5942127,-7754.776
7.132,-0.07130553,-8.460721,-430901,0,0,0,-0.5942127,-7764.781
7.144,-0.07130553,-8.472451,-431498.4,0,0,0,-0.5942127,-7775.546
7.148,-0.07154164,-8.475349,-431646,0,0,0,-0.5961803,-7778.206
7.172,-0.07177775,-8.474169,-431585.9,0,0,0,-0.5981479,-7777.123
7.194,-0.07177775,-8.484244,-432099,0,0,0,-0.5981479,-7786.369
7.198,-0.07201386,-8.486258,-432201.6,0,0,0,-0.6001155,-7788.217
7.22,-0.07224997,-8.49332,-432561.3,0,0,0,-0.6020831,-7794.699
7.24,-0.07224997,-8.50369,-433089.4,0,0,0,-0.6020831,-7804.216
7.242,-0.07248608,-8.505277,-433170.2,0,0,0,-0.6040506,-7805.672
7.266,-0.07272219,-8.513438,-433585.8,0,0,0,-0.6060182,-7813.161
7.288,-0.0729583,-8.521361,-433989.4,0,0,0,-0.6079859,-7820.433
7.308,-0.0729583,-8.532042,-434533.3,0,0,0,-0.6079859,-7830.235
7.31,-0.07319441,-8.533945,-434630.3,0,0,0,-0.6099535,-7831.982
7.322,-0.07319441,-8.544162,-435150.6,0,0,0,-0.6099535,-7841.358
7.334,-0.07343053,-8.549114,-435402.8,0,0,0,-0.6119211,-7845.903
7.356,-0.07366664,-8.556767,-435792.6,0,0,0,-0.6138886,-7852.927
7.37,-0.07366664,-8.567623,-436345.5,0,0,0,-0.6138886,-7862.89
7.38,-0.07390274,-8.572323,-436584.8,0,0,0,-0.6158562,-7867.203
7.402,-0.07413886,-8.564356,-436179.1,0,0,0,-0.6178238,-7859.891
7.418,-0.07413886,-8.574517,-436696.6,0,0,0,-0.6178238,-7869.216
7.426,-0.07437497,-8.579951,-436973.3,0,0,0,-0.6197914,-7874.204
7.448,-0.07461108,-8.57986,-436968.7,0,0,0,-0.621759,-7874.121
7.47,-0.07484719,-8.587469,-437356.2,0,0,0,-0.6237266,-7881.104
7.486,-0.07484719,-8.597727,-437878.7,0,0,0,-0.6237266,-7890.518
7.494,-0.0750833,-8.603902,-438193.1,0,0,0,-0.6256942,-7896.184
7.504,-0.0750833,-8.614928,-438754.7,0,0,0,-0.6256942,-7906.303
7.516,-0.07531942,-8.625041,-439269.7,0,0,0,-0.6276618,-7915.584
7.538,-0.07555552,-8.627175,-439378.4,0,0,0,-0.6296294,-7917.543
7.562,-0.07579163,-8.630205,-439532.8,0,0,0,-0.6315969,-7920.324
7.57,-0.07579163,-8.642396,-440153.6,0,0,0,-0.6315969,-7931.512
7.578,-0.07579163,-8.653191,-440703.4,0,0,0,-0.6315969,-7941.419
7.584,-0.07602775,-8.657818,-440939,0,0,0,-0.6335645,-7945.666
7.608,-0.07626386,-8.64873,-440476.2,0,0,0,-0.6355321,-7937.325
7.628,-0.07626386,-8.658921,-440995.3,0,0,0,-0.6355321,-7946.678
7.63,-0.07649997,-8.660904,-441096.2,0,0,0,-0.6374997,-7948.498
7.644,-0.07649997,-8.670935,-441607.1,0,0,0,-0.6374997,-7957.704
7.654,-0.07673609,-8.673345,-441729.8,0,0,0,-0.6394674,-7959.915
7.676,-0.07697219,-8.680492,-442093.8,0,0,0,-0.6414349,-7966.474
7.7,-0.0772083,-8.683474,-442245.7,0,0,0,-0.6434025,-7969.211
7.722,-0.07744441,-8.689997,-442577.9,0,0,0,-0.6453701,-7975.198
7.738,-0.07744441,-8.700059,-443090.4,0,0,0,-0.6453701,-7984.432
7.746,-0.07768052,-8.703429,-443262,0,0,0,-0.6473377,-7987.525
7.766,-0.07768052,-8.714143,-443807.7,0,0,0,-0.6473377,-7997.358
7.77,-0.07791664,-8.717069,-443956.7,0,0,0,-0.6493053,-8000.043
7.786,-0.07791664,-8.727347,-444480.1,0,0,0,-0.6493053,-8009.475
7.792,-0.07815275,-8.729827,-444606.4,0,0,0,-0.651273,-8011.751
7.806,-0.07815275,-8.74073,-445161.7,0,0,0,-0.651273,-8021.757
7.812,-0.07838886,-8.747232,-445492.9,0,0,0,-0.6532405,-8027.725
7.834,-0.07862496,-8.7568,-445980.2,0,0,0,-0.655208,-8036.505
7.858,-0.07886108,-8.750833,-445676.3,0,0,0,-0.6571757,-8031.029
7.868,-0.07886108,-8.761144,-446201.4,0,0,0,-0.6571757,-8040.493
7.878,-0.07886108,-8.772257,-446767.4,0,0,0,-0.6571757,-8050.691
7.882,-0.07909719,-8.774956,-446904.8,0,0,0,-0.6591433,-8053.168
7.906,-0.0793333,-8.773248,-446817.8,0,0,0,-0.6611109,-8051.601
7.924,-0.0793333,-8.783338,-447331.7,0,0,0,-0.6611109,-8060.861
7.928,-0.07956942,-8.786497,-447492.6,0,0,0,-0.6630785,-8063.76
7.954,-0.07980552,-8.793669,-447857.9,0,0,0,-0.665046,-8070.342
7.978,-0.08004164,-8.797826,-448069.6,0,0,0,-0.6670136,-8074.157
7.992,-0.08004164,-8.808669,-448621.8,0,0,0,-0.6670136,-8084.108
8.002,-0.08027774,-8.817629,-449078.2,0,0,0,-0.6689812,-8092.331
8.014,-0.08027774,-8.828542,-449634,0,0,0,-0.6689812,-8102.347
8.026,-0.08051386,-8.836477,-450038.1,0,0,0,-0.6709488,-8109.629
8.052,-0.08074997,-8.841829,-450310.7,0,0,0,-0.6729164,-8114.541
8.078,-0.08098608,-8.846804,-450564.1,0,0,0,-0.674884,-8119.107
8.1,-0.08122219,-8.85464,-450963.1,0,0,0,-0.6768516,-8126.298
8.124,-0.0814583,-8.860171,-451244.8,0,0,0,-0.6788192,-8131.374
8.142,-0.0814583,-8.870982,-451795.4,0,0,0,-0.6788192,-8141.295
8.148,-0.08169441,-8.872842,-451890.2,0,0,0,-0.6807867,-8143.003
8.17,-0.08193052,-8.880855,-452298.2,0,0,0,-0.6827543,-8150.356
8.194,-0.08216663,-8.889731,-452750.3,0,0,0,-0.6847219,-8158.502
8.208,-0.08216663,-8.899833,-453264.8,0,0,0,-0.6847219,-8167.773
8.216,-0.08240275,-8.909712,-453767.9,0,0,0,-0.6866896,-8176.84
8.228,-0.08240275,-8.920168,-454300.4,0,0,0,-0.6866896,-8186.436
8.24,-0.08263885,-8.930579,-454830.7,0,0,0,-0.6886571,-8195.99
8.26,-0.08263885,-8.940704,-455346.3,0,0,0,-0.6886571,-8205.283
8.264,-0.08287497,-8.942288,-455427,0,0,0,-0.6906247,-8206.736
8.286,-0.08287497,-8.952379,-455940.9,0,0,0,-0.6906247,-8215.998
8.288,-0.08311108,-8.952694,-455957,0,0,0,-0.6925923,-8216.286
8.31,-0.08334719,-8.955763,-456113.3,0,0,0,-0.6945599,-8219.103
8.332,-0.0835833,-8.958774,-456266.6,0,0,0,-0.6965275,-8221.866
8.356,-0.08381941,-8.960024,-456330.3,0,0,0,-0.6984951,-8223.013
8.378,-0.08405552,-8.967453,-456708.6,0,0,0,-0.7004626,-8229.831
8.404,-0.08429163,-8.97785,-457238.2,0,0,0,-0.7024302,-8239.373
8.412,-0.08429163,-8.988046,-457757.4,0,0,0,-0.7024302,-8248.73
8.426,-0.08452775,-8.997729,-458250.6,0,0,0,-0.7043979,-8257.617
8.452,-0.08476386,-9.00562,-458652.5,0,0,0,-0.7063655,-8264.859
8.474,-0.08499997,-9.007935,-458770.4,0,0,0,-0.708333,-8266.984
8.488,-0.08499997,-9.019024,-459335.1,0,0,0,-0.708333,-8277.16
8.496,-0.08523608,-9.023122,-459543.9,0,0,0,-0.7103007,-8280.922
8.52,-0.08547218,-9.030889,-459939.4,0,0,0,-0.7122682,-8288.05
8.544,-0.0857083,-9.041419,-460475.7,0,0,0,-0.7142358,-8297.714
8.566,-0.08594441,-9.0478,-460800.7,0,0,0,-0.7162035,-8303.569
8.59,-0.08618053,-9.051229,-460975.3,0,0,0,-0.7181711,-8306.717
8.61,-0.08618053,-9.062333,-461540.8,0,0,0,-0.7181711,-8316.907
8.616,-0.08641663,-9.068372,-461848.4,0,0,0,-0.7201386,-8322.449
8.634,-0.08641663,-9.078625,-462370.6,0,0,0,-0.7201386,-8331.858
8.642,-0.08665274,-9.077077,-462291.7,0,0,0,-0.7221062,-8330.438
8.666,-0.08688885,-9.086174,-462755.1,0,0,0,-0.7240738,-8338.787
8.678,-0.08688885,-9.096366,-463274.2,0,0,0,-0.7240738,-8348.141
8.692,-0.08712496,-9.101585,-463539.9,0,0,0,-0.7260414,-8352.93
8.716,-0.08736108,-9.106908,-463811,0,0,0,-0.728009,-8357.815
8.738,-0.08759719,-9.113206,-464131.8,0,0,0,-0.7299766,-8363.595
8.758,-0.0878333,-9.115092,-464227.8,0,0,0,-0.7319442,-8365.326
8.77,-0.0878333,-9.126543,-464811,0,0,0,-0.7319442,-8375.836
8.778,-0.08806941,-9.137576,-465372.9,0,0,0,-0.7339118,-8385.961
8.786,-0.08806941,-9.149116,-465960.6,0,0,0,-0.7339118,-8396.552
8.796,-0.08830551,-9.155308,-466276,0,0,0,-0.7358793,-8402.234
8.818,-0.08854163,-9.160122,-466521.2,0,0,0,-0.7378469,-8406.652
8.836,-0.08854163,-9.171261,-467088.5,0,0,0,-0.7378469,-8416.876
8.84,-0.08877774,-9.173653,-467210.3,0,0,0,-0.7398145,-8419.07
8.864,-0.08901386,-9.171435,-467097.3,0,0,0,-0.7417821,-8417.034
8.878,-0.08901386,-9.183417,-467707.6,0,0,0,-0.7417821,-8428.031
8.888,-0.08924997,-9.194668,-468280.6,0,0,0,-0.7437497,-8438.357
8.902,-0.08924997,-9.205276,-468820.9,0,0,0,-0.7437497,-8448.093
8.914,-0.08948608,-9.210468,-469085.3,0,0,0,-0.7457173,-8452.857
8.938,-0.08972218,-9.214604,-469295.9,0,0,0,-0.7476848,-8456.653
8.954,-0.08972218,-9.203729,-468742.1,0,0,0,-0.7476848,-8446.673
8.964,-0.08995829,-9.206363,-468876.2,0,0,0,-0.7496524,-8449.09
8.974,-0.08995829,-9.216859,-469410.8,0,0,0,-0.7496524,-8458.723
8.99,-0.09019441,-9.225289,-469840.1,0,0,0,-0.7516201,-8466.459
9.014,-0.09019441,-9.235517,-470361,0,0,0,-0.7516201,-8475.846
9.016,-0.09043052,-9.23657,-470414.6,0,0,0,-0.7535877,-8476.812
9.032,-0.09043052,-9.246921,-470941.8,0,0,0,-0.7535877,-8486.312
9.042,-0.09066664,-9.251259,-471162.8,0,0,0,-0.7555553,-8490.293
9.06,-0.09066664,-9.261734,-471696.3,0,0,0,-0.7555553,-8499.906
9.07,-0.09090274,-9.267255,-471977.4,0,0,0,-0.7575228,-8504.973
9.094,-0.09113885,-9.275489,-472396.8,0,0,0,-0.7594904,-8512.529
9.114,-0.09113885,-9.286072,-472935.8,0,0,0,-0.7594904,-8522.242
9.12,-0.09137496,-9.292866,-473281.8,0,0,0,-0.761458,-8528.478
9.142,-0.09137496,-9.282709,-472764.5,0,0,0,-0.761458,-8519.156
9.144,-0.09161107,-9.280582,-472656.2,0,0,0,-0.7634256,-8517.204
9.17,-0.09184719,-9.286345,-472949.7,0,0,0,-0.7653932,-8522.493
9.184,-0.09184719,-9.298332,-473560.2,0,0,0,-0.7653932,-8533.494
9.196,-0.09208329,-9.309544,-474131.2,0,0,0,-0.7673607,-8543.784
9.206,-0.09208329,-9.319691,-474648,0,0,0,-0.7673607,-8553.096
9.222,-0.09231941,-9.321191,-474724.4,0,0,0,-0.7693284,-8554.473
9.242,-0.09231941,-9.331577,-475253.3,0,0,0,-0.7693284,-8564.004
9.244,-0.09255552,-9.333612,-475357,0,0,0,-0.771296,-8565.872
9.264,-0.09279162,-9.341737,-475770.8,0,0,0,-0.7732635,-8573.329
9.278,-0.09279162,-9.353492,-476369.5,0,0,0,-0.7732635,-8584.117
9.286,-0.09302774,-9.360082,-476705,0,0,0,-0.7752311,-8590.164
9.308,-0.09326385,-9.365627,-476987.5,0,0,0,-0.7771988,-8595.253
9.332,-0.09349996,-9.376296,-477530.8,0,0,0,-0.7791663,-8605.045
9.356,-0.09373607,-9.382289,-477836.1,0,0,0,-0.7811339,-8610.545
9.382,-0.09397218,-9.391895,-478325.3,0,0,0,-0.7831016,-8619.361
9.402,-0.09397218,-9.401986,-478839.3,0,0,0,-0.7831016,-8628.622
9.408,-0.09420829,-9.40566,-479026.4,0,0,0,-0.7850691,-8631.994
9.436,-0.0944444,-9.400512,-478764.2,0,0,0,-0.7870367,-8627.27
9.464,-0.09468052,-9.399509,-478713.1,0,0,0,-0.7890043,-8626.349
9.492,-0.09491662,-9.402561,-478868.5,0,0,0,-0.7909719,-8629.149
9.522,-0.09515274,-9.391407,-478300.5,0,0,0,-0.7929395,-8618.913
9.548,-0.09538885,-9.39207,-478334.2,0,0,0,-0.7949071,-8619.521
9.568,-0.09538885,-9.402608,-478870.9,0,0,0,-0.7949071,-8629.192
9.576,-0.09562496,-9.405167,-479001.2,0,0,0,-0.7968747,-8631.541
9.6,-0.09586107,-9.404061,-478944.9,0,0,0,-0.7988423,-8630.526
9.622,-0.09609718,-9.409769,-479235.6,0,0,0,-0.8008099,-8635.764
9.644,-0.09633329,-9.404349,-478959.6,0,0,0,-0.8027774,-8630.791
9.664,-0.0965694,-9.403117,-478896.8,0,0,0,-0.804745,-8629.66
9.676,-0.0965694,-9.413659,-479433.7,0,0,0,-0.804745,-8639.334
9.686,-0.09680552,-9.423261,-479922.7,0,0,0,-0.8067126,-8648.146
9.696,-0.09680552,-9.433548,-480446.7,0,0,0,-0.8067126,-8657.588
9.71,-0.09704163,-9.44523,-481041.6,0,0,0,-0.8086802,-8668.309
9.726,-0.09704163,-9.455704,-481575.1,0,0,0,-0.8086802,-8677.921
9.732,-0.09727774,-9.456967,-481639.4,0,0,0,-0.8106478,-8679.08
9.756,-0.09751385,-9.465449,-482071.4,0,0,0,-0.8126154,-8686.865
9.77,-0.09751385,-9.475873,-482602.3,0,0,0,-0.8126154,-8696.431
9.776,-0.09774995,-9.479649,-482794.6,0,0,0,-0.8145829,-8699.896
9.8,-0.09798607,-9.485686,-483102,0,0,0,-0.8165506,-8705.438
9.822,-0.09822218,-9.487205,-483179.4,0,0,0,-0.8185182,-8706.831
9.844,-0.09845829,-9.490447,-483344.5,0,0,0,-0.8204858,-8709.807
9.854,-0.09845829,-9.502565,-483961.7,0,0,0,-0.8204858,-8720.928
9.862,-0.09845829,-9.514717,-484580.6,0,0,0,-0.8204858,-8732.08
9.868,-0.09869441,-9.523905,-485048.5,0,0,0,-0.8224534,-8740.512
9.878,-0.09869441,-9.534363,-485581.1,0,0,0,-0.8224534,-8750.109
9.89,-0.09893051,-9.536359,-485682.8,0,0,0,-0.8244209,-8751.942
9.912,-0.09916662,-9.53941,-485838.2,0,0,0,-0.8263885,-8754.742
9.934,-0.09940273,-9.547519,-486251.1,0,0,0,-0.8283561,-8762.184
9.956,-0.09963885,-9.549654,-486359.9,0,0,0,-0.8303237,-8764.144
9.972,-0.09963885,-9.560233,-486898.7,0,0,0,-0.8303237,-8773.853
9.98,-0.09987496,-9.568426,-487315.9,0,0,0,-0.8322913,-8781.371
10.002,-0.1001111,-9.576138,-487708.7,0,0,0,-0.834259,-8788.449